Workbook

Sheet bus
A1: name | B1: description | C1: baseKV | D1: type | E1: zone
A2: AA_I_Z_110 | B2: Ardnacrusha_110kV | C2: 110 | D2: 1 | E2: ROI
A3: AA1_I_Z_110 | B3: Ardnacrusha_110kV | C3: 110 | D3: 1 | E3: ROI
A4: AD_I_Z_110 | B4: Aghada_110kV | C4: 110 | D4: 1 | E4: ROI
A5: AD_I_Z_220 | B5: Aghada_220kV | C5: 220 | D5: 1 | E5: ROI
A6: ADM_I_Z_110 | B6: Adamstown_110kV | C6: 110 | D6: 1 | E6: ROI
A7: AGH_N_Z_110 | B7: Aghyoule_110kV | C7: 110 | D7: 1 | E7: NI
A8: AGH_N_Z_33 | B8: Aghyoule_33kV | C8: 33 | D8: 1 | E8: NI
A9: AGL_I_Z_110 | B9: Agannygal_110kV | C9: 110 | D9: 1 | E9: ROI
A10: AGN_I_Z_110 | B10: Aungierstown_110kV | C10: 110 | D10: 1 | E10: ROI
A11: AHA_I_Z_110 | B11: Ahane_110kV | C11: 110 | D11: 1 | E11: ROI
A12: AIR_N_Z_110 | B12: Airport Road_110kV | C12: 110 | D12: 1 | E12: NI
A13: AIR_N_Z_33 | B13: Airport Road_33kV | C13: 33 | D13: 1 | E13: NI
A14: ANR_I_Z_110 | B14: Anner_110kV | C14: 110 | D14: 1 | E14: ROI
A15: ANT_N_Z_110 | B15: Antrim_110kV | C15: 110 | D15: 1 | E15: NI
A16: ANT_N_Z_33 | B16: Antrim_33kV | C16: 33 | D16: 1 | E16: NI
A17: ARD_I_Z_110 | B17: Ardnagappary_110kV | C17: 110 | D17: 1 | E17: ROI
A18: ARI_I_T_110 | B18: Arigna_110kV_Tee | C18: 110 | D18: 1 | E18: ROI
A19: ARI_I_Z_110 | B19: Arigna_110kV | C19: 110 | D19: 1 | E19: ROI
A20: ARK_I_Z_110 | B20: Arklow_110kV | C20: 110 | D20: 1 | E20: ROI
A21: ARK_I_Z_220 | B21: Arklow_220kV | C21: 220 | D21: 1 | E21: ROI
A22: ART_I_Z_110 | B22: Artane_110kV | C22: 110 | D22: 1 | E22: ROI
A23: ARV_I_Z_110 | B23: Arva_110kV | C23: 110 | D23: 1 | E23: ROI
A24: ATE_I_Z_110 | B24: Athea_110kV | C24: 110 | D24: 1 | E24: ROI
... A119: CLW_I_Z_110 | B119: Carlow_110kV | C119: 110 | D119: 1 | E119: ROI
A120: CNB_I_Z_380 | B120: Coolnabacky_380kV | C120: 330 | D120: 1 | E120: ROI
A121: CNB_I_Z_110 | B121: Coolnabacky_110kV | C121: 110 | D121: 1 | E121: ROI
A122: CNG_I_Z_110 | B122: Coolnanoonag_110kV | C122: 110 | D122: 1 | E122: ROI
A123: COL_I_Z_110 | B123: College Park_110kV | C123: 110 | D123: 1 | E123: ROI
A124: COL_N_Z_110 | B124: Coleraine_110kV | C124: 110 | D124: 1 | E124: NI
A125: COL_N_Z_33 | B125: Coleraine_33kV | C125: 33 | D125: 1 | E125: NI
A126: COO_I_Z_110 | B126: Cookstown_110kV | C126: 110 | D126: 1 | E126: ROI
A127: COR_I_Z_110 | B127: Corraclassy_110kV | C127: 110 | D127: 1 | E127: ROI
A128: COS_I_Z_110 | B128: Carrick-on-Shannon_110kV | C128: 110 | D128: 1 | E128: ROI
A129: COW_I_Z_110 | B129: Cow Cross_110kV | C129: 110 | D129: 1 | E129: ROI
A130: CPK_I_Z_110 | B130: Central Park_110kV | C130: 110 | D130: 1 | E130: ROI
A131: CPS_N_Z_110 | B131: Coolkeeragh Power Station_110kV | C131: 110 | D131: 1 | E131: NI
A132: CPS_N_Z_275 | B132: Coolkeeragh Power Station_275kV | C132: 275 | D132: 1 | E132: NI
... A231: HN_I_Z_220 | B231: Huntstown_220kV | C231: 220 | D231: 1 | E231: ROI
A232: HWN_I_Z_110 | B232: Harristown_110kV | C232: 110 | D232: 1 | E232: ROI
...

Sheet demand
A1: name | B1: busname | C1: real | D1: stat | E1: VOLL
A2: AA_I_Z_110_PF0.993 | B2: AA_I_Z_110 | C2: 51.4 | D2: 1 | E2: 20000
A3: AGH_N_Z_110_PF0.99 | B3: AGH_N_Z_110 | C3: 16.2 | D3: 1 | E3: 20000
A4: AGN_I_Z_110_PF0.95 | B4: AGN_I_Z_110 | C4: 25.2 | D4: 1 | E4: 20000
A5: AHA_I_Z_110_PF0.998 | B5: AHA_I_Z_110 | C5: 4.1 | D5: 1 | E5: 20000
A6: AIR_N_Z_110_PF0.99 | B6: AIR_N_Z_110 | C6: 16.5 | D6: 1 | E6: 20000
A7: ANR_I_Z_110_PF0.95 | B7: ANR_I_Z_110 | C7: 14 | D7: 1 | E7: 20000
A8: ANT_N_Z_110_PF0.98 | B8: ANT_N_Z_110 | C8: 34.2 | D8: 1 | E8: 20000
A9: ARD_I_Z_110_PF0.99 | B9: ARD_I_Z_110 | C9: 13 | D9: 1 | E9: 20000
A10: ARI_I_T_110_PF0.998 | B10: ARI_I_T_110 | C10: 4.5 | D10: 1 | E10: 20000
A11: ARK_I_Z_110_PF0.997 | B11: ARK_I_Z_110 | C11: 33.9 | D11: 1 | E11: 20000
A12: ATH_I_Z_110_PF0.998 | B12: ATH_I_Z_110 | C12: 66.8 | D12: 1 | E12: 20000
A13: ATY_I_Z_110_PF0.968 | B13: ATY_I_Z_110 | C13: 15.8 | D13: 1 | E13: 20000
... A165: WHI_I_Z_110_PF0.95 | B165: WHI_I_Z_110 | C165: 9 | D165: 1 | E165: 20000

Sheet ts_PD
A1: timestep | B1: AA_I_Z_110_PF0.993 | C1: AGN_I_Z_110_PF0.95 | D1: AHA_I_Z_110_PF0.998 | E1: ANR_I_Z_110_PF0.95 | F1: ARD_I_Z_110_PF0.99 | G1: ARI_I_T_110_PF0.998 | H1: ARK_I_Z_110_PF0.997 | I1: ATH_I_Z_110_PF0.998 | J1: ATY_I_Z_110_PF0.968 | K1: BAL_I_Z_110_PF1 | L1: BAN_I_Z_110_PF0.987 | M1: BAR_I_T_110_PF1 | N1: BDA_I_Z_110_PF0.95 | O1: BDN_I_Z_110_PF0.96 | P1: BDN_I_Z_110_PF0.95 | Q1: BEG_I_Z_110_PF1 | R1: BIN_I_Z_110_PF0.99 | S1: BIN_I_Z_110_PF0.999 | T1: BK_I_Z_110_PF0.996 | U1: BLC_I_Z_110_PF0.95 | V1: BLI_I_Z_110_PF0.991 | W1: BLK_I_Z_110_PF0.99 | X1: BOG_I_Z_110_PF0.97 | Y1: BRI_I_Z_110_PF0.95 | Z1: BRY_I_Z_110_PF0.976 | AA1: BUT_I_Z_110_PF0.989 | AB1: CAH_I_Z_110_PF0.981 | AC1: CBG_I_Z_110_PF0.984 | AD1: CBR_I_Z_110_PF0.988 | AE1: CF_I_Z_110_PF0.964 | AF1: CFM_I_Z_110_PF0.95 | AG1: CHA_I_Z_110_PF0.96 | AH1: CKM_I_Z_110_PF0.998 | AI1: CLE_I_Z_220_PF0.95 | AJ1: CLG_I_Z_110_PF0.95 | AK1: CLN_I_Z_110_PF0.925 | AL1: CLU_I_Z_110_PF0.95 | AM1: CLW_I_Z_110_PF0.991 | AN1: COL_I_Z_110_PF0.986 | AO1: COS_I_Z_110_PF0.989 | AP1: COW_I_Z_110_PF0.997 | AQ1: CRA_I_Z_110_PF0.979 | AR1: CRO_I_Z_110_PF1 | AS1: CVW_I_Z_110_PF0.982 | AT1: DAL_I_T_110_PF0.987 | AU1: DDK_I_Z_110_PF0.986 | AV1: DFR_I_T_110_PF0.991 | AW1: DGN_I_Z_110_PF0.984 | AX1: DLT_I_Z_110_PF0.981 | AY1: DMY_I_Z_110_PF0.976 | AZ1: DOO_I_Z_110_PF0.984 | BA1: DRU_I_Z_110_PF0.945 | BB1: DRY_I_Z_110_PF0.985 | BC1: ENN_I_Z_110_PF0.981 | BD1: FIN_I_Z_110_PF0.994 | BE1: FTT_I_Z_110_PF0.997 | BF1: GAL_I_Z_110_PF0.988 | BG1: GI_I_Z_110_PF0.952 | BH1: GIL_I_Z_110_PF0.95 | BI1: GLE_I_Z_110_PF0.998 | BJ1: GRI_I_T_110_PF0.997 | BK1: GWE_I_Z_110_PF0.98 | BL1: GWE_I_Z_110_PF0.95 | BM1: HN_I_Z_220_PF0.95 | BN1: IKE_I_T_110_PF0.967 | BO1: INC_I_Z_110_PF0.995 | BP1: KBY_I_Z_110_PF0.993 | BQ1: KCY_I_Z_110_PF0.95 | BR1: KER_I_Z_110_PF0.971 | BS1: KSE_I_Z_110_PF0.95 | BT1: KTL_I_Z_110_PF0.988 | BU1: KIN_I_Z_110_PF0.95 | BV1: KKY_I_Z_110_PF0.978 | BW1: KLM_I_Z_110_PF0.989 | BX1: KTN_I_Z_110_PF0.976 | BY1: KUR_I_Z_110_PF0.95 | BZ1: KYT_I_Z_220_PF0.95 | CA1: LA_I_Z_110_PF0.984 | CB1: LET_I_Z_110_PF0.987 | CC1: LIB_I_Z_110_PF0.986 | CD1: LIM_I_Z_110_PF0.993 | CE1: LIS_I_Z_110_PF0.952 | CF1: MAC_I_Z_110_PF0.973 | CG1: MAL_I_Z_110_PF0.981 | CH1: MCE_I_Z_110_PF0.995 | CI1: MCE_I_Z_110_PF0.95 | CJ1: MID_I_Z_110_PF0.98 | CK1: MLN_I_Z_110_PF0.95 | CL1: MON_I_Z_110_PF0.975 | CM1: MOY_I_Z_110_PF0.989 | CN1: MR_I_Z_110_PF0.992 | CO1: MTA_I_Z_110_PF0.95 | CP1: MTH_I_Z_110_PF0.938 | CQ1: MTN_I_Z_110_PF0.95 | CR1: MUL_I_Z_110_PF0.985 | CS1: MUN_I_Z_110_PF0.95 | CT1: NAV_I_Z_110_PF0.98 | CU1: NEW_I_Z_110_PF0.981 | CV1: NEN_I_Z_110_PF0.954 | CW1: OBE_I_Z_110_PF0.95 | CX1: OLD_I_Z_110_PF0.95 | CY1: OUG_I_T_110_PF0.992 | CZ1: PB_I_Z_110_PF0.989 | DA1: PLA_I_Z_110_PF0.95 | DB1: PLS_I_Z_110_PF0.979 | DC1: RAT_I_Z_110_PF0.993 | DD1: RIC_I_Z_110_PF0.972 | DE1: RNW_I_Z_110_PF0.95 | DF1: RYB_I_Z_110_PF0.95 | DG1: SCR_I_Z_110_PF0.999 | DH1: SHE_I_Z_110_PF0.95 | DI1: SHL_I_Z_220_PF0.997 | DJ1: SKL_I_Z_110_PF0.993 | DK1: SLI_I_Z_110_PF0.996 | DL1: SNG_I_Z_110_PF0.992 | DM1: SBH_I_Z_110_PF0.95 | DN1: SOM_I_T_110_PF0.974 | DO1: STR_I_T_110_PF0.958 | DP1: TBG_I_Z_110_PF0.994 | DQ1: TBK_I_T_110_PF0.931 | DR1: THU_I_Z_110_PF0.983 | DS1: TIP_I_Z_110_PF0.986 | DT1: TLK_I_Z_110_PF0.968 | DU1: TON_I_Z_110_PF0.925 | DV1: TRI_I_Z_110_PF1 | DW1: TRL_I_Z_110_PF0.99 | DX1: TSB_I_Z_110_PF0.977 | DY1: WAT_I_Z_110_PF0.986 | DZ1: WEX_I_Z_110_PF0.979 | EA1: WHI_I_Z_110_PF0.95 | EB1: AGH_N_Z_110_PF0.99 | EC1: AIR_N_Z_110_PF0.99 | ED1: ANT_N_Z_110_PF0.98 | EE1: BAN_N_Z_33_PF0.99 | EF1: BMA_N_Z_110_PF0.95 | EG1: BNH_N_Z_110_PF0.99 | EH1: BNM_N_Z_110_PF0.99 | EI1: CAR_N_Z_110_PF0.99 | EJ1: CEN_N_Z_110_PF0.99 | EK1: COL_N_Z_33_PF0.99 | EL1: CPS_N_Z_110_PF0.99 | EM1: CRE_N_Z_110_PF0.99 | EN1: CRG_N_Z_110_PF0.99 | EO1: DON_N_Z_110_PF0.99 | EP1: DRU_N_Z_33_PF0.99 | EQ1: DUN_N_Z_110_PF0.99 | ER1: EDE_N_Z_110_PF0.99 | ES1: ENN_N_Z_33_PF0.99 | ET1: FIN_N_Z_33_PF0.99 | EU1: GLE_N_Z_33_PF0.99 | EV1: KNO_N_Z_110_PF0.99 | EW1: LAR_N_Z_110_PF0.99 | EX1: LIM_N_Z_33_PF0.99 | EY1: LIS_N_Z_33_PF0.99 | EZ1: LMR_N_Z_110_PF0.98 | FA1: LOG_N_Z_110_PF0.98 | FB1: NAR_N_Z_110_PF0.99 | FC1: NEW_N_Z_33_PF0.99 | FD1: OMA_N_Z_110_PF0.99 | FE1: RAT_N_Z_33_PF0.99 | FF1: ROS_N_Z_110_PF0.99 | FG1: SPR_N_Z_110_PF0.99 | FH1: STR_N_Z_33_PF0.99 | FI1: WAR_N_Z_110_PF0.99
A2: 05/07/25 00:00 | B2: 35.099265 | C2: 17.2082 | D2: 2.7997468 | E2: 9.5601111 | F2: 8.877246 | G2: 3.0728928 | H2: 23.149126 | I2: 45.615387 | J2: 10.789268 | K2: 9.150392 | L2: 27.109744 | M2: 17.549632 | N2: 3.6191849 | O2: 8.467527 | P2: 4.0971905 | Q2: 8.6041 | R2: 8.6041 | S2: 2.5948873 | T2: 3.3460389 | U2: 73.954288 | V2: 7.8529484 | W2: 15.501037 | X2: 4.7800555 | Y2: 2.7314603 | Z2: 19.598228 | AA2: 23.149126 | AB2: 15.159605 | AC2: 10.311263 | AD2: 19.051936 | AE2: 11.881852 | AF2: 34.689546 | AG2: 11.54042 | AH2: 197.62115 | AI2: 92.459931 | AJ2: 49.985724 | AK2: 15.227891 | AL2: 9.7649706 | AM2: 39.742748 | AN2: 19.051936 | AO2: 16.525335 | AP2: 9.6283976 | AQ2: 18.095925 | AR2: 6.0774992 | AS2: 18.642217 | AT2: 10.652695 | AU2: 37.830725 | AV2: 6.1457857 | AW2: 28.065755 | AX2: 16.252189 | AY2: 19.803087 | AZ2: 15.774183 | BA2: 17.549632 | BB2: 51.351454 | BC2: 35.304125 | BD2: 269.86828 | BE2: 7.9895214 | BF2: 54.35606 | BG2: 9.150392 | BH2: 7.7846619 | BI2: 9.8332571 | BJ2: 37.079574 | BK2: 6.1457857 | BL2: 15.569324 | BM2: 10.379549 | BN2: 17.617919 | BO2: 370.79574 | BP2: 48.89314 | BQ2: 5.1897746 | BR2: 22.944267 | BS2: 6.4872182 | BT2: 20.14452 | BU2: 6.9652238 | BV2: 34.279827 | BW2: 11.130701 | BX2: 8.0578079 | BY2: 16.183902 | BZ2: 79.826928 | CA2: 9.4918246 | CB2: 39.333028 | CC2: 14.27188 | CD2: 48.073701 | CE2: 17.822779 | CF2: 9.9698301 | CG2: 13.725588 | CH2: 17.413059 | CI2: 3.1411794 | CJ2: 24.788002 | CK2: 3.0728928 | CL2: 7.9895214 | CM2: 17.413059 | CN2: 9.6966841 | CO2: 0 | CP2: 32.504378 | CQ2: 0 | CR2: 25.675727 | CS2: 14.681599 | CT2: 35.713844 | CU2: 24.105137 | CV2: 12.769577 | CW2: 9.7649706 | CX2: 0.20485952 | CY2: 15.296178 | CZ2: 103.45406 | DA2: 12.291571 | DB2: 31.070361 | DC2: 24.036851 | DD2: 20.963958 | DE2: 6.2140722 | DF2: 71.359401 | DG2: 9.6283976 | DH2: 1.5705897 | DI2: 25.197721 | DJ2: 32.982383 | DK2: 31.548367 | DL2: 10.106403 | DM2: 14.954745 | DN2: 13.179296 | DO2: 13.452442 | DP2: 40.971905 | DQ2: 7.1700833 | DR2: 16.866767 | DS2: 11.950139 | DT2: 12.70129 | DU2: 8.5358135 | DV2: 10.17469 | DW2: 32.367805 | DX2: 20.076233 | DY2: 31.138648 | DZ2: 33.938394 | EA2: 6.1457857 | EB2: 6.2555713 | EC2: 6.3714152 | ED2: 13.206206 | EE2: 11.275474 | EF2: 18.419182 | EG2: 17.878577 | EH2: 14.90525 | EI2: 10.310108 | EJ2: 16.025075 | EK2: 12.74283 | EL2: 10.889328 | EM2: 16.681523 | EN2: 15.098323 | EO2: 26.103495 | EP2: 26.257954 | EQ2: 27.995612 | ER2: 10.039806 | ES2: 18.728099 | ET2: 10.07842 | EU2: 8.8813667 | EV2: 14.364645 | EW2: 13.437894 | EX2: 6.6417177 | EY2: 24.443066 | EZ2: 12.318069 | FA2: 11.584391 | FB2: 12.124996 | FC2: 23.014324 | FD2: 18.457797 | FE2: 16.140919 | FF2: 9.9625765 | FG2: 10.117035 | FH2: 14.40326 | FI2: 17.917192
A3: 05/07/25 00:30 | B3: 34.16336 | C3: 16.749352 | D3: 2.7250929 | E3: 9.3051954 | F3: 8.6405386 | G3: 2.9909557 | H3: 22.531866 | I3: 44.399075 | J3: 10.501578 | K3: 8.9064013 | L3: 26.386876 | M3: 17.08168 | N3: 3.5226811 | O3: 8.2417445 | P3: 3.9879409 | Q3: 8.3746759 | R3: 8.3746759 | S3: 2.5256959 | T3: 3.2568184 | U3: 71.982333 | V3: 7.6435534 | W3: 15.08771 | X3: 4.6525977 | Y3: 2.6586273 | Z3: 19.075651 | AA3: 22.531866 | AB3: 14.755381 | AC3: 10.036318 | AD3: 18.543925 | AE3: 11.565029 | AF3: 33.764566 | AG3: 11.2327 | AH3: 192.35168 | AI3: 89.994533 | AJ3: 48.652879 | AK3: 14.821847 | AL3: 9.5045925 | AM3: 38.683027 | AN3: 18.543925 | AO3: 16.084695 | AP3: 9.3716611 | AQ3: 17.613406 | AR3: 5.9154457 | AS3: 18.145131 | AT3: 10.368646 | AU3: 36.821988 | AV3: 5.9819113 | AW3: 27.317395 | AX3: 15.818832 | AY3: 19.275048 | AZ3: 15.353572 | BA3: 17.08168 | BB3: 49.982192 | BC3: 34.362757 | BD3: 262.67237 | BE3: 7.7764847 | BF3: 52.906682 | BG3: 8.9064013 | BH3: 7.5770877 | BI3: 9.5710581 | BJ3: 36.090865 | BK3: 5.9819113 | BL3: 15.154175 | BM3: 10.102784 | BN3: 17.148146 | BO3: 360.90865 | BP3: 47.589428 | BQ3: 5.0513918 | BR3: 22.332469 | BS3: 6.3142397 | BT3: 19.607376 | BU3: 6.7794995 | BV3: 33.365772 | BW3: 10.833906 | BX3: 7.8429504 | BY3: 15.752367 | BZ3: 77.698382 | CA3: 9.2387297 | CB3: 38.284233 | CC3: 13.891327 | CD3: 46.79184 | CE3: 17.347543 | CF3: 9.7039895 | CG3: 13.359602 | CH3: 16.948749 | CI3: 3.0574213 | CJ3: 24.127042 | CK3: 2.9909557 | CL3: 7.7764847 | CM3: 16.948749 | CN3: 9.4381268 | CO3: 0 | CP3: 31.637664 | CQ3: 0 | CR3: 24.991096 | CS3: 14.290122 | CT3: 34.761551 | CU3: 23.462386 | CV3: 12.429082 | CW3: 9.5045925 | CX3: 0.19939704 | CY3: 14.888313 | CZ3: 100.69551 | DA3: 11.963823 | DB3: 30.241885 | DC3: 23.39592 | DD3: 20.404964 | DE3: 6.048377 | DF3: 69.456637 | DG3: 9.3716611 | DH3: 1.5287107 | DI3: 24.525836 | DJ3: 32.102924 | DK3: 30.707145 | DL3: 9.8369209 | DM3: 14.555984 | DN3: 12.827877 | DO3: 13.093739 | DP3: 39.879409 | DQ3: 6.9788966 | DR3: 16.417023 | DS3: 11.631494 | DT3: 12.362617 | DU3: 8.3082102 | DV3: 9.9033865 | DW3: 31.504733 | DX3: 19.54091 | DY3: 30.308351 | DZ3: 33.033444 | EA3: 5.9819113 | EB3: 5.9497758 | EC3: 6.0599568 | ED3: 12.560638 | EE3: 10.724287 | EF3: 17.518784 | EG3: 17.004606 | EH3: 14.176626 | EI3: 9.806112 | EJ3: 15.24171 | EK3: 12.119914 | EL3: 10.357017 | EM3: 15.866069 | EN3: 14.360261 | EO3: 24.827459 | EP3: 24.974368 | EQ3: 26.627083 | ER3: 9.5490229 | ES3: 17.8126 | ET3: 9.5857499 | EU3: 8.4472125 | EV3: 13.662448 | EW3: 12.781 | EX3: 6.3170459 | EY3: 23.248198 | EZ3: 11.715917 | FA3: 11.018103 | FB3: 11.532281 | FC3: 21.889299 | FD3: 17.555511 | FE3: 15.351891 | FF3: 9.4755689 | FG3: 9.6224769 | FH3: 13.699175 | FI3: 17.041333
A4: 05/07/25 01:00 | B4: 33.623802 | C4: 16.484821 | D4: 2.6820542 | E4: 9.158234 | F4: 8.5040744 | G4: 2.9437181 | H4: 22.176009 | I4: 43.697859 | J4: 10.335721 | K4: 8.7657383 | L4: 25.970135 | M4: 16.811901 | N4: 3.4670457 | O4: 8.1115787 | P4: 3.9249574 | Q4: 8.2424106 | R4: 8.2424106 | S4: 2.4858064 | T4: 3.2053819 | U4: 70.845482 | V4: 7.5228351 | W4: 14.849422 | X4: 4.579117 | Y4: 2.6166383 | Z4: 18.77438 | AA4: 22.176009 | AB4: 14.522342 | AC4: 9.8778095 | AD4: 18.251052 | AE4: 11.382377 | AF4: 33.231306 | AG4: 11.055297 | AH4: 189.31378 | AI4: 88.573206 | AJ4: 47.884481 | AK4: 14.587758 | AL4: 9.3544819 | AM4: 38.072087 | AN4: 18.251052 | AO4: 15.830662 | AP4: 9.22365 | AQ4: 17.335229 | AR4: 5.8220202 | AS4: 17.858556 | AT4: 10.204889 | AU4: 36.24044 | AV4: 5.8874361 | AW4: 26.885958 | AX4: 15.568998 | AY4: 18.970628 | AZ4: 15.111086 | BA4: 16.811901 | BB4: 49.1928 | BC4: 33.82005 | BD4: 258.52386 | BE4: 7.653667 | BF4: 52.071102 | BG4: 8.7657383 | BH4: 7.4574191 | BI4: 9.4198978 | BJ4: 35.520865 | BK4: 5.8874361 | BL4: 14.914838 | BM4: 9.9432255 | BN4: 16.877317 | BO4: 355.20865 | BP4: 46.837825 | BQ4: 4.9716127 | BR4: 21.979762 | BS4: 6.2145159 | BT4: 19.297707 | BU4: 6.6724276 | BV4: 32.838811 | BW4: 10.662801 | BX4: 7.7190829 | BY4: 15.503582 | BZ4: 76.471254 | CA4: 9.092818 | CB4: 37.679591 | CC4: 13.671935 | CD4: 46.052834 | CE4: 17.073565 | CF4: 9.5507297 | CG4: 13.148607 | CH4: 16.681069 | CI4: 3.009134 | CJ4: 23.745992 | CK4: 2.9437181 | CL4: 7.653667 | CM4: 16.681069 | CN4: 9.2890659 | CO4: 0 | CP4: 31.137996 | CQ4: 0 | CR4: 24.5964 | CS4: 14.064431 | CT4: 34.212546 | CU4: 23.091833 | CV4: 12.232784 | CW4: 9.3544819 | CX4: 0.19624787 | CY4: 14.653174 | CZ4: 99.105175 | DA4: 11.774872 | DB4: 29.764261 | DC4: 23.026417 | DD4: 20.082699 | DE4: 5.9528521 | DF4: 68.359675 | DG4: 9.22365 | DH4: 1.504567 | DI4: 24.138488 | DJ4: 31.595907 | DK4: 30.222172 | DL4: 9.6815617 | DM4: 14.326095 | DN4: 12.62528 | DO4: 12.886944 | DP4: 39.249574 | DQ4: 6.8686755 | DR4: 16.157741 | DS4: 11.447793 | DT4: 12.167368 | DU4: 8.1769946 | DV4: 9.7469776 | DW4: 31.007164 | DX4: 19.232291 | DY4: 29.829676 | DZ4: 32.511731 | EA4: 5.8874361 | EB4: 5.7792082 | EC4: 5.8862306 | ED4: 12.200551 | EE4: 10.416844 | EF4: 17.016558 | EG4: 16.51712 | EH4: 13.770212 | EI4: 9.5249914 | EJ4: 14.804762 | EK4: 11.772461 | EL4: 10.060103 | EM4: 15.411222 | EN4: 13.948583 | EO4: 24.115708 | EP4: 24.258405 | EQ4: 25.863741 | ER4: 9.2752725 | ES4: 17.301951 | ET4: 9.3109466 | EU4: 8.2050487 | EV4: 13.270774 | EW4: 12.414595 | EX4: 6.1359495 | EY4: 22.581721 | EZ4: 11.380046 | FA4: 10.702237 | FB4: 11.201675 | FC4: 21.261778 | FD4: 17.052232 | FE4: 14.911784 | FF4: 9.2039242 | FG4: 9.3466207 | FH4: 13.306449 | FI4: 16.552794
A5: 05/07/25 01:30 | B5: 32.759321 | C5: 16.06099 | D5: 2.6130976 | E5: 8.9227722 | F5: 8.2854314 | G5: 2.8680339 | H5: 21.605856 | I5: 42.57437 | J5: 10.069986 | K5: 8.5403677 | L5: 25.302433 | M5: 16.37966 | N5: 3.3779066 | O5: 7.9030268 | P5: 3.8240452 | Q5: 8.030495 | R5: 8.030495 | S5: 2.4218953 | T5: 3.1229703 | U5: 69.024017 | V5: 7.3294201 | W5: 14.467638 | X5: 4.4613861 | Y5: 2.5493635 | Z5: 18.291683 | AA5: 21.605856 | AB5: 14.148967 | AC5: 9.6238472 | AD5: 17.78181 | AE5: 11.089731 | AF5: 32.376916 | AG5: 10.771061 | AH5: 184.44645 | AI5: 86.295954 | AJ5: 46.653352 | AK5: 14.212701 | AL5: 9.1139745 | AM5: 37.093239 | AN5: 17.78181 | AO5: 15.423649 | AP5: 8.9865063 | AQ5: 16.889533 | AR5: 5.6723338 | AS5: 17.399406 | AT5: 9.9425176 | AU5: 35.308684 | AV5: 5.7360679 | AW5: 26.19471 | AX5: 15.168713 | AY5: 18.482885 | AZ5: 14.722574 | BA5: 16.37966 | BB5: 47.928034 | BC5: 32.950523 | BD5: 251.87711 | BE5: 7.4568882 | BF5: 50.732334 | BG5: 8.5403677 | BH5: 7.265686 | BI5: 9.1777086 | BJ5: 34.607609 | BK5: 5.7360679 | BL5: 14.531372 | BM5: 9.6875813 | BN5: 16.443395 | BO5: 346.07609 | BP5: 45.633607 | BQ5: 4.8437906 | BR5: 21.414653 | BS5: 6.0547383 | BT5: 18.801556 | BU5: 6.5008769 | BV5: 31.994512 | BW5: 10.388656 | BX5: 7.5206223 | BY5: 15.104979 | BZ5: 74.505148 | CA5: 8.8590381 | CB5: 36.710834 | CC5: 13.320424 | CD5: 44.868798 | CE5: 16.634597 | CF5: 9.3051768 | CG5: 12.810552 | CH5: 16.252192 | CI5: 2.931768 | CJ5: 23.135474 | CK5: 2.8680339 | CL5: 7.4568882 | CM5: 16.252192 | CN5: 9.0502404 | CO5: 0 | CP5: 30.337426 | CQ5: 0 | CR5: 23.964017 | CS5: 13.702829 | CT5: 33.332928 | CU5: 22.498133 | CV5: 11.918274 | CW5: 9.1139745 | CX5: 0.19120226 | CY5: 14.276436 | CZ5: 96.557142 | DA5: 11.472136 | DB5: 28.99901 | DC5: 22.434399 | DD5: 19.566365 | DE5: 5.799802 | DF5: 66.602121 | DG5: 8.9865063 | DH5: 1.465884 | DI5: 23.517878 | DJ5: 30.783564 | DK5: 29.445148 | DL5: 9.4326449 | DM5: 13.957765 | DN5: 12.300679 | DO5: 12.555615 | DP5: 38.240452 | DQ5: 6.6920792 | DR5: 15.74232 | DS5: 11.153465 | DT5: 11.85454 | DU5: 7.9667609 | DV5: 9.496379 | DW5: 30.209957 | DX5: 18.737822 | DY5: 29.062744 | DZ5: 31.675841 | EA5: 5.7360679 | EB5: 5.5642424 | EC5: 5.6672839 | ED5: 11.746734 | EE5: 10.029375 | EF5: 16.383603 | EG5: 15.902742 | EH5: 13.25801 | EI5: 9.1706958 | EJ5: 14.254078 | EK5: 11.334568 | EL5: 9.6859034 | EM5: 14.83798 | EN5: 13.429746 | EO5: 23.218691 | EP5: 23.356079 | EQ5: 24.901702 | ER5: 8.9302656 | ES5: 16.65838 | ET5: 8.9646128 | EU5: 7.8998503 | EV5: 12.777149 | EW5: 11.952817 | EX5: 5.9077142 | EY5: 21.741762 | EZ5: 10.956749 | FA5: 10.304153 | FB5: 10.785013 | FC5: 20.470916 | FD5: 16.41795 | FE5: 14.357119 | FF5: 8.8615712 | FG5: 8.9989599 | FH5: 12.811496 | FI5: 15.937089
A6: 05/07/25 02:00 | B6: 33.396611 | C6: 16.373436 | D6: 2.663932 | E6: 9.0963533 | F6: 8.4466138 | G6: 2.9238278 | H6: 22.02617 | I6: 43.4026 | J6: 10.265884 | K6: 8.7065096 | L6: 25.794659 | M6: 16.698306 | N6: 3.4436195 | O6: 8.05677 | P6: 3.8984371 | Q6: 8.186718 | R6: 8.186718 | S6: 2.4690102 | T6: 3.1837236 | U6: 70.36679 | V6: 7.4720045 | W6: 14.749087 | X6: 4.5481766 | Y6: 2.5989581 | Z6: 18.647524 | AA6: 22.02617 | AB6: 14.424217 | AC6: 9.8110668 | AD6: 18.127733 | AE6: 11.305468 | AF6: 33.006768 | AG6: 10.980598 | AH6: 188.03462 | AI6: 87.974731 | AJ6: 47.560933 | AK6: 14.489191 | AL6: 9.2912751 | AM6: 37.81484 | AN6: 18.127733 | AO6: 15.723696 | AP6: 9.1613272 | AQ6: 17.218097 | AR6: 5.7826817 | AS6: 17.737889 | AT6: 10.135937 | AU6: 35.995569 | AV6: 5.8476557 | AW6: 26.704294 | AX6: 15.463801 | AY6: 18.842446 | AZ6: 15.008983 | BA6: 16.698306 | BB6: 48.860412 | BC6: 33.591533 | BD6: 256.77706 | BE6: 7.6019524 | BF6: 51.719266 | BG6: 8.7065096 | BH6: 7.4070305 | BI6: 9.3562491 | BJ6: 35.280856 | BK6: 5.8476557 | BL6: 14.814061 | BM6: 9.8760407 | BN6: 16.76328 | BO6: 352.80856 | BP6: 46.52135 | BQ6: 4.9380204 | BR6: 21.831248 | BS6: 6.1725254 | BT6: 19.167316 | BU6: 6.6273431 | BV6: 32.616924 | BW6: 10.590754 | BX6: 7.6669263 | BY6: 15.398827 | BZ6: 75.95455 | CA6: 9.0313793 | CB6: 37.424996 | CC6: 13.579556 | CD6: 45.741662 | CE6: 16.958201 | CF6: 9.486197 | CG6: 13.059764 | CH6: 16.568358 | CI6: 2.9888018 | CJ6: 23.585545 | CK6: 2.9238278 | CL6: 7.6019524 | CM6: 16.568358 | CN6: 9.2263012 | CO6: 0 | CP6: 30.927601 | CQ6: 0 | CR6: 24.430206 | CS6: 13.9694 | CT6: 33.981377 | CU6: 22.935805 | CV6: 12.150129 | CW6: 9.2912751 | CX6: 0.19492186 | CY6: 14.554165 | CZ6: 98.435537 | DA6: 11.695311 | DB6: 29.563148 | DC6: 22.870831 | DD6: 19.947003 | DE6: 5.9126296 | DF6: 67.89778 | DG6: 9.1613272 | DH6: 1.4944009 | DI6: 23.975388 | DJ6: 31.382419 | DK6: 30.017966 | DL6: 9.6161449 | DM6: 14.229295 | DN6: 12.539973 | DO6: 12.799869 | DP6: 38.984371 | DQ6: 6.822265 | DR6: 16.048566 | DS6: 11.370442 | DT6: 12.085155 | DU6: 8.121744 | DV6: 9.6811188 | DW6: 30.797653 | DX6: 19.102342 | DY6: 29.628122 | DZ6: 32.292054 | EA6: 5.8476557 | EB6: 5.6955534 | EC6: 5.8010266 | ED6: 12.023946 | EE6: 10.266059 | EF6: 16.770241 | EG6: 16.278032 | EH6: 13.570887 | EI6: 9.3871158 | EJ6: 14.590461 | EK6: 11.602053 | EL6: 9.9144819 | EM6: 15.188142 | EN6: 13.746675 | EO6: 23.76663 | EP6: 23.907261 | EQ6: 25.489359 | ER6: 9.1410117 | ES6: 17.051503 | ET6: 9.1761694 | EU6: 8.0862796 | EV6: 13.078678 | EW6: 12.234893 | EX6: 6.0471308 | EY6: 22.254848 | EZ6: 11.215318 | FA6: 10.547321 | FB6: 11.039529 | FC6: 20.954011 | FD6: 16.805398 | FE6: 14.695934 | FF6: 9.0706962 | FG6: 9.2113271 | FH6: 13.113836 | FI6: 16.31319
A7: 05/07/25 02:30 | B7: 32.820898 | C7: 16.09118 | D7: 2.6180094 | E7: 8.9395443 | F7: 8.3010054 | G7: 2.873425 | H7: 21.646468 | I7: 42.654397 | J7: 10.088914 | K7: 8.556421 | L7: 25.349994 | M7: 16.410449 | N7: 3.3842561 | O7: 7.9178821 | P7: 3.8312333 | Q7: 8.0455899 | R7: 8.0455899 | S7: 2.4264477 | T7: 3.1288405 | U7: 69.153761 | V7: 7.3431971 | W7: 14.494833 | X7: 4.4697722 | Y7: 2.5541555 | Z7: 18.326066 | AA7: 21.646468 | AB7: 14.175563 | AC7: 9.6419371 | AD7: 17.815235 | AE7: 11.110577 | AF7: 32.437775 | AG7: 10.791307 | AH7: 184.79315 | AI7: 86.458164 | AJ7: 46.741046 | AK7: 14.239417 | AL7: 9.131106 | AM7: 37.162963 | AN7: 17.815235 | AO7: 15.452641 | AP7: 9.0033982 | AQ7: 16.92128 | AR7: 5.682996 | AS7: 17.432111 | AT7: 9.9612065 | AU7: 35.375054 | AV7: 5.7468499 | AW7: 26.243948 | AX7: 15.197225 | AY7: 18.517628 | AZ7: 14.750248 | BA7: 16.410449 | BB7: 48.018124 | BC7: 33.01246 | BD7: 252.35057 | BE7: 7.4709049 | BF7: 50.827695 | BG7: 8.556421 | BH7: 7.2793432 | BI7: 9.1949599 | BJ7: 34.672661 | BK7: 5.7468499 | BL7: 14.558686 | BM7: 9.705791 | BN7: 16.474303 | BO7: 346.72661 | BP7: 45.719384 | BQ7: 4.8528955 | BR7: 21.454906 | BS7: 6.0661194 | BT7: 18.836897 | BU7: 6.5130966 | BV7: 32.054652 | BW7: 10.408184 | BX7: 7.5347588 | BY7: 15.133371 | BZ7: 74.645195 | CA7: 8.8756904 | CB7: 36.779839 | CC7: 13.345463 | CD7: 44.953137 | CE7: 16.665865 | CF7: 9.3226676 | CG7: 12.834631 | CH7: 16.282741 | CI7: 2.9372788 | CJ7: 23.178961 | CK7: 2.873425 | CL7: 7.4709049 | CM7: 16.282741 | CN7: 9.0672521 | CO7: 0 | CP7: 30.394451 | CQ7: 0 | CR7: 24.009062 | CS7: 13.728586 | CT7: 33.395583 | CU7: 22.540422 | CV7: 11.940677 | CW7: 9.131106 | CX7: 0.19156166 | CY7: 14.303271 | CZ7: 96.73864 | DA7: 11.4937 | DB7: 29.053519 | DC7: 22.476569 | DD7: 19.603144 | DE7: 5.8107038 | DF7: 66.727313 | DG7: 9.0033982 | DH7: 1.4686394 | DI7: 23.562085 | DJ7: 30.841428 | DK7: 29.500496 | DL7: 9.4503754 | DM7: 13.984001 | DN7: 12.3238 | DO7: 12.579216 | DP7: 38.312333 | DQ7: 6.7046582 | DR7: 15.77191 | DS7: 11.17443 | DT7: 11.876823 | DU7: 7.981736 | DV7: 9.5142293 | DW7: 30.266743 | DX7: 18.773043 | DY7: 29.117373 | DZ7: 31.735382 | EA7: 5.7468499 | EB7: 5.591058 | EC7: 5.6945961 | ED7: 11.803345 | EE7: 10.077709 | EF7: 16.46256 | EG7: 15.979382 | EH7: 13.321904 | EI7: 9.2148918 | EJ7: 14.322772 | EK7: 11.389192 | EL7: 9.7325824 | EM7: 14.909488 | EN7: 13.494467 | EO7: 23.330588 | EP7: 23.468638 | EQ7: 25.02171 | ER7: 8.9733029 | ES7: 16.738661 | ET7: 9.0078156 | EU7: 7.9379218 | EV7: 12.838726 | EW7: 12.010421 | EX7: 5.936185 | EY7: 21.846541 | EZ7: 11.009552 | FA7: 10.353811 | FB7: 10.836989 | FC7: 20.569571 | FD7: 16.497072 | FE7: 14.42631 | FF7: 8.9042775 | FG7: 9.0423283 | FH7: 12.873238 | FI7: 16.013894
A8: 05/07/25 03:00 | B8: 32.407881 | C8: 15.888689 | D8: 2.5850645 | E8: 8.8270494 | F8: 8.1965459 | G8: 2.8372659 | H8: 21.37407 | I8: 42.117636 | J8: 9.9619557 | K8: 8.4487473 | L8: 25.03099 | M8: 16.203941 | N8: 3.3416687 | O8: 7.8182437 | P8: 3.7830212 | Q8: 7.9443444 | R8: 7.9443444 | S8: 2.3959134 | T8: 3.0894673 | U8: 68.283532 | V8: 7.2507906 | W8: 14.31243 | X8: 4.4135247 | Y8: 2.5220141 | Z8: 18.095451 | AA8: 21.37407 | AB8: 13.997178 | AC8: 9.5206033 | AD8: 17.591048 | AE8: 10.970761 | AF8: 32.029579 | AG8: 10.65551 | AH8: 182.46772 | AI8: 85.370178 | AJ8: 46.152858 | AK8: 14.060229 | AL8: 9.0162004 | AM8: 36.695305 | AN8: 17.591048 | AO8: 15.258185 | AP8: 8.8900997 | AQ8: 16.708343 | AR8: 5.6114814 | AS8: 17.212746 | AT8: 9.835855 | AU8: 34.929895 | AV8: 5.6745317 | AW8: 25.913695 | AX8: 15.005984 | AY8: 18.284602 | AZ8: 14.564631 | BA8: 16.203941 | BB8: 47.413865 | BC8: 32.597032 | BD8: 249.17499 | BE8: 7.3768913 | BF8: 50.188081 | BG8: 8.4487473 | BH8: 7.1877402 | BI8: 9.0792508 | BJ8: 34.236342 | BK8: 5.6745317 | BL8: 14.37548 | BM8: 9.5836536 | BN8: 16.266991 | BO8: 342.36342 | BP8: 45.144053 | BQ8: 4.7918268 | BR8: 21.184919 | BS8: 5.9897835 | BT8: 18.599854 | BU8: 6.431136 | BV8: 31.651277 | BW8: 10.277207 | BX8: 7.4399416 | BY8: 14.942934 | BZ8: 73.705862 | CA8: 8.763999 | CB8: 36.317003 | CC8: 13.177524 | CD8: 44.387448 | CE8: 16.456142 | CF8: 9.2053515 | CG8: 12.673121 | CH8: 16.07784 | CI8: 2.9003162 | CJ8: 22.887278 | CK8: 2.8372659 | CL8: 7.3768913 | CM8: 16.07784 | CN8: 8.9531501 | CO8: 0 | CP8: 30.011968 | CQ8: 0 | CR8: 23.706933 | CS8: 13.555826 | CT8: 32.975334 | CU8: 22.256775 | CV8: 11.790416 | CW8: 9.0162004 | CX8: 0.18915106 | CY8: 14.123279 | CZ8: 95.521284 | DA8: 11.349063 | DB8: 28.68791 | DC8: 22.193724 | DD8: 19.356458 | DE8: 5.7375821 | DF8: 65.887619 | DG8: 8.8900997 | DH8: 1.4501581 | DI8: 23.26558 | DJ8: 30.45332 | DK8: 29.129263 | DL8: 9.3314522 | DM8: 13.808027 | DN8: 12.168718 | DO8: 12.420919 | DP8: 37.830212 | DQ8: 6.620287 | DR8: 15.573437 | DS8: 11.033812 | DT8: 11.727366 | DU8: 7.8812941 | DV8: 9.3945026 | DW8: 29.885867 | DX8: 18.536804 | DY8: 28.750961 | DZ8: 31.336025 | EA8: 5.6745317 | EB8: 5.4934824 | EC8: 5.5952136 | ED8: 11.597352 | EE8: 9.9018325 | EF8: 16.175254 | EG8: 15.700508 | EH8: 13.089409 | EI8: 9.0540729 | EJ8: 14.07281 | EK8: 11.190427 | EL8: 9.5627287 | EM8: 14.649286 | EN8: 13.258961 | EO8: 22.92342 | EP8: 23.059062 | EQ8: 24.585029 | ER8: 8.8167002 | ES8: 16.446537 | ET8: 8.8506106 | EU8: 7.7993886 | EV8: 12.614663 | EW8: 11.800814 | EX8: 5.8325863 | EY8: 21.465274 | EZ8: 10.817413 | FA8: 10.173116 | FB8: 10.647861 | FC8: 20.21059 | FD8: 16.209164 | FE8: 14.174541 | FF8: 8.7488794 | FG8: 8.884521 | FH8: 12.648574 | FI8: 15.734419
A9: 05/07/25 03:30 | B9: 31.947769 | C9: 15.663109 | D9: 2.5483629 | E9: 8.7017271 | F9: 8.0801751 | G9: 2.7969837 | H9: 21.070611 | I9: 41.519669 | J9: 9.8205206 | K9: 8.3287959 | L9: 24.675612 | M9: 15.973885 | N9: 3.2942252 | O9: 7.707244 | P9: 3.7293116 | Q9: 7.8315544 | R9: 7.8315544 | S9: 2.3618973 | T9: 3.0456045 | U9: 67.314074 | V9: 7.1478472 | W9: 14.109229 | X9: 4.3508635 | Y9: 2.4862077 | Z9: 17.838541 | AA9: 21.070611 | AB9: 13.798453 | AC9: 9.3854342 | AD9: 17.341299 | AE9: 10.815004 | AF9: 31.574838 | AG9: 10.504228 | AH9: 179.87713 | AI9: 84.158132 | AJ9: 45.497602 | AK9: 13.860608 | AL9: 8.8881927 | AM9: 36.174323 | AN9: 17.341299 | AO9: 15.041557 | AP9: 8.7638823 | AQ9: 16.471126 | AR9: 5.5318122 | AS9: 16.968368 | AT9: 9.6962102 | AU9: 34.433977 | AV9: 5.5939674 | AW9: 25.545784 | AX9: 14.792936 | AY9: 18.025006 | AZ9: 14.35785 | BA9: 15.973885 | BB9: 46.740705 | BC9: 32.134235 | BD9: 245.63732 | BE9: 7.2721576 | BF9: 49.475534 | BG9: 8.3287959 | BH9: 7.085692 | BI9: 8.9503478 | BJ9: 33.75027 | BK9: 5.5939674 | BL9: 14.171384 | BM9: 9.4475894 | BN9: 16.03604 | BO9: 337.5027 | BP9: 44.503118 | BQ9: 4.7237947 | BR9: 20.884145 | BS9: 5.9047434 | BT9: 18.335782 | BU9: 6.3398297 | BV9: 31.201907 | BW9: 10.131297 | BX9: 7.3343128 | BY9: 14.730781 | BZ9: 72.659421 | CA9: 8.6395719 | CB9: 35.801391 | CC9: 12.990435 | CD9: 43.757256 | CE9: 16.222505 | CF9: 9.0746582 | CG9: 12.493194 | CH9: 15.849574 | CI9: 2.8591389 | CJ9: 22.562335 | CK9: 2.7969837 | CL9: 7.2721576 | CM9: 15.849574 | CN9: 8.8260375 | CO9: 0 | CP9: 29.585872 | CQ9: 0 | CR9: 23.370353 | CS9: 13.363367 | CT9: 32.507166 | CU9: 21.940783 | CV9: 11.623021 | CW9: 8.8881927 | CX9: 0.18646558 | CY9: 13.922763 | CZ9: 94.165118 | DA9: 11.187935 | DB9: 28.280613 | DC9: 21.878628 | DD9: 19.081644 | DE9: 5.6561226 | DF9: 64.952177 | DG9: 8.7638823 | DH9: 1.4295694 | DI9: 22.935266 | DJ9: 30.020958 | DK9: 28.715699 | DL9: 9.1989686 | DM9: 13.611987 | DN9: 11.995952 | DO9: 12.244573 | DP9: 37.293116 | DQ9: 6.5262953 | DR9: 15.352333 | DS9: 10.877159 | DT9: 11.560866 | DU9: 7.7693992 | DV9: 9.2611238 | DW9: 29.461562 | DX9: 18.273627 | DY9: 28.342768 | DZ9: 30.891131 | EA9: 5.5939674 | EB9: 5.3827944 | EC9: 5.4824758 | ED9: 11.363677 | EE9: 9.7023208 | EF9: 15.849339 | EG9: 15.384159 | EH9: 12.825671 | EI9: 8.8716427 | EJ9: 13.789257 | EK9: 10.964952 | EL9: 9.3700496 | EM9: 14.354119 | EN9: 12.991806 | EO9: 22.461537 | EP9: 22.594446 | EQ9: 24.089666 | ER9: 8.6390528 | ES9: 16.115156 | ET9: 8.6722799 | EU9: 7.642239 | EV9: 12.360491 | EW9: 11.56304 | EX9: 5.7150657 | EY9: 21.032771 | EZ9: 10.599453 | FA9: 9.9681379 | FB9: 10.433318 | FC9: 19.803367 | FD9: 15.882566 | FE9: 13.888939 | FF9: 8.5725986 | FG9: 8.7055071 | FH9: 12.393718 | FI9: 15.417387
A10: 05/07/25 04:00 | B10: 32.058838 | C10: 15.717563 | D10: 2.5572225 | E10: 8.7319792 | F10: 8.1082664 | G10: 2.8067076 | H10: 21.143864 | I10: 41.664015 | J10: 9.8546623 | K10: 8.3577516 | L10: 24.761398 | M10: 16.029419 | N10: 3.3056779 | O10: 7.7340388 | P10: 3.7422768 | Q10: 7.8587813 | R10: 7.8587813 | S10: 2.3701087 | T10: 3.0561927 | U10: 67.548097 | V10: 7.1726972 | W10: 14.158281 | X10: 4.3659896 | Y10: 2.4948512 | Z10: 17.900557 | AA10: 21.143864 | AB10: 13.846424 | AC10: 9.4180633 | AD10: 17.401587 | AE10: 10.852603 | AF10: 31.68461 | AG10: 10.540746 | AH10: 180.50249 | AI10: 84.450714 | AJ10: 45.655777 | AK10: 13.908796 | AL10: 8.9190931 | AM10: 36.300085 | AN10: 17.401587 | AO10: 15.09385 | AP10: 8.7943505 | AQ10: 16.528389 | AR10: 5.5510439 | AS10: 17.02736 | AT10: 9.7299197 | AU10: 34.553689 | AV10: 5.6134152 | AW10: 25.634596 | AX10: 14.844365 | AY10: 18.087671 | AZ10: 14.407766 | BA10: 16.029419 | BB10: 46.903203 | BC10: 32.245952 | BD10: 246.4913 | BE10: 7.2974398 | BF10: 49.647539 | BG10: 8.3577516 | BH10: 7.110326 | BI10: 8.9814644 | BJ10: 33.867605 | BK10: 5.6134152 | BL10: 14.220652 | BM10: 9.4804346 | BN10: 16.09179 | BO10: 338.67605 | BP10: 44.657837 | BQ10: 4.7402173 | BR10: 20.95675 | BS10: 5.9252716 | BT10: 18.399528 | BU10: 6.3618706 | BV10: 31.310383 | BW10: 10.166519 | BX10: 7.3598111 | BY10: 14.781993 | BZ10: 72.912027 | CA10: 8.669608 | CB10: 35.925857 | CC10: 13.035598 | CD10: 43.909381 | CE10: 16.278904 | CF10: 9.1062069 | CG10: 12.536627 | CH10: 15.904676 | CI10: 2.8690789 | CJ10: 22.640775 | CK10: 2.8067076 | CL10: 7.2974398 | CM10: 15.904676 | CN10: 8.8567218 | CO10: 0 | CP10: 29.688729 | CQ10: 0 | CR10: 23.451601 | CS10: 13.409825 | CT10: 32.62018 | CU10: 22.017062 | CV10: 11.663429 | CW10: 8.9190931 | CX10: 0.18711384 | CY10: 13.971167 | CZ10: 94.49249 | DA10: 11.22683 | DB10: 28.378933 | DC10: 21.954691 | DD10: 19.147983 | DE10: 5.6757865 | DF10: 65.177988 | DG10: 8.7943505 | DH10: 1.4345394 | DI10: 23.015002 | DJ10: 30.125328 | DK10: 28.815532 | DL10: 9.2309495 | DM10: 13.65931 | DN10: 12.037657 | DO10: 12.287142 | DP10: 37.422768 | DQ10: 6.5489844 | DR10: 15.405706 | DS10: 10.914974 | DT10: 11.601058 | DU10: 7.79641 | DV10: 9.2933208 | DW10: 29.563987 | DX10: 18.337156 | DY10: 28.441304 | DZ10: 30.998526 | EA10: 5.6134152 | EB10: 5.4031004 | EC10: 5.5031578 | ED10: 11.406545 | EE10: 9.7389217 | EF10: 15.909129 | EG10: 15.442194 | EH10: 12.874054 | EI10: 8.9051099 | EJ10: 13.841276 | EK10: 11.006316 | EL10: 9.405397 | EM10: 14.408268 | EN10: 13.040816 | EO10: 22.546271 | EP10: 22.679681 | EQ10: 24.180542 | ER10: 8.6716426 | ES10: 16.175949 | ET10: 8.7049951 | EU10: 7.6710685 | EV10: 12.407119 | EW10: 11.60666 | EX10: 5.7366251 | EY10: 21.112115 | EZ10: 10.639438 | FA10: 10.005741 | FB10: 10.472676 | FC10: 19.878073 | FD10: 15.942481 | FE10: 13.941333 | FF10: 8.6049377 | FG10: 8.7383476 | FH10: 12.440472 | FI10: 15.475547
A11: 05/07/25 04:30 | B11: 31.838368 | C11: 15.609472 | D11: 2.5396363 | E11: 8.671929 | F11: 8.0525055 | G11: 2.7874057 | H11: 20.998457 | I11: 41.37749 | J11: 9.7868913 | K11: 8.3002749 | L11: 24.591113 | M11: 15.919184 | N11: 3.2829445 | O11: 7.6808514 | P11: 3.716541 | Q11: 7.8047361 | R11: 7.8047361 | S11: 2.3538093 | T11: 3.0351751 | U11: 67.083565 | V11: 7.1233702 | W11: 14.060913 | X11: 4.3359645 | Y11: 2.477694 | Z11: 17.777454 | AA11: 20.998457 | AB11: 13.751202 | AC11: 9.3532948 | AD11: 17.281916 | AE11: 10.777969 | AF11: 31.466714 | AG11: 10.468257 | AH11: 179.26116 | AI11: 83.869942 | AJ11: 45.3418 | AK11: 13.813144 | AL11: 8.857756 | AM11: 36.050448 | AN11: 17.281916 | AO11: 14.990049 | AP11: 8.7338713 | AQ11: 16.414723 | AR11: 5.5128691 | AS11: 16.910261 | AT11: 9.6630066 | AU11: 34.316062 | AV11: 5.5748115 | AW11: 25.458306 | AX11: 14.742279 | AY11: 17.963281 | AZ11: 14.308683 | BA11: 15.919184 | BB11: 46.580647 | BC11: 32.024195 | BD11: 244.79617 | BE11: 7.2472549 | BF11: 49.30611 | BG11: 8.3002749 | BH11: 7.0614279 | BI11: 8.9196984 | BJ11: 33.634696 | BK11: 5.5748115 | BL11: 14.122856 | BM11: 9.4152372 | BN11: 15.981126 | BO11: 336.34696 | BP11: 44.350722 | BQ11: 4.7076186 | BR11: 20.81263 | BS11: 5.8845232 | BT11: 18.272993 | BU11: 6.3181197 | BV11: 31.09506 | BW11: 10.096603 | BX11: 7.3091973 | BY11: 14.680337 | BZ11: 72.410607 | CA11: 8.6099866 | CB11: 35.678793 | CC11: 12.945951 | CD11: 43.607414 | CE11: 16.166953 | CF11: 9.0435831 | CG11: 12.450412 | CH11: 15.795299 | CI11: 2.8493481 | CJ11: 22.485073 | CK11: 2.7874057 | CL11: 7.2472549 | CM11: 15.795299 | CN11: 8.7958137 | CO11: 0 | CP11: 29.484559 | CQ11: 0 | CR11: 23.290324 | CS11: 13.317605 | CT11: 32.395849 | CU11: 21.865649 | CV11: 11.583219 | CW11: 8.857756 | CX11: 0.18582705 | CY11: 13.875086 | CZ11: 93.84266 | DA11: 11.149623 | DB11: 28.183769 | DC11: 21.803707 | DD11: 19.016301 | DE11: 5.6367538 | DF11: 64.729756 | DG11: 8.7338713 | DH11: 1.424674 | DI11: 22.856727 | DJ11: 29.918155 | DK11: 28.617366 | DL11: 9.1674678 | DM11: 13.565375 | DN11: 11.954874 | DO11: 12.202643 | DP11: 37.16541 | DQ11: 6.5039467 | DR11: 15.29976 | DS11: 10.839911 | DT11: 11.521277 | DU11: 7.7427937 | DV11: 9.2294101 | DW11: 29.360674 | DX11: 18.211051 | DY11: 28.245712 | DZ11: 30.785348 | EA11: 5.5748115 | EB11: 5.3472932 | EC11: 5.4463172 | ED11: 11.28873 | EE11: 9.638331 | EF11: 15.744808 | EG11: 15.282696 | EH11: 12.741081 | EI11: 8.8131314 | EJ11: 13.698313 | EK11: 10.892634 | EL11: 9.3082512 | EM11: 14.259449 | EN11: 12.906121 | EO11: 22.313396 | EP11: 22.445428 | EQ11: 23.930788 | ER11: 8.5820755 | ES11: 16.008872 | ET11: 8.6150835 | EU11: 7.591836 | EV11: 12.27897 | EW11: 11.486778 | EX11: 5.677373 | EY11: 20.894053 | EZ11: 10.529547 | FA11: 9.9023948 | FB11: 10.364507 | FC11: 19.672758 | FD11: 15.777816 | FE11: 13.797337 | FF11: 8.5160596 | FG11: 8.6480915 | FH11: 12.311978 | FI11: 15.315704
A12: 05/07/25 05:00 | B12: 31.569917 | C12: 15.477858 | D12: 2.518223 | E12: 8.5988101 | F12: 7.9846094 | G12: 2.7639032 | H12: 20.821404 | I12: 41.028608 | J12: 9.7043714 | K12: 8.2302897 | L12: 24.383769 | M12: 15.784959 | N12: 3.2552638 | O12: 7.6160889 | P12: 3.6852043 | Q12: 7.7389291 | R12: 7.7389291 | S12: 2.3339627 | T12: 3.0095835 | U12: 66.517938 | V12: 7.0633083 | W12: 13.942356 | X12: 4.2994051 | Y12: 2.4568029 | Z12: 17.627561 | AA12: 20.821404 | AB12: 13.635256 | AC12: 9.2744309 | AD12: 17.1362 | AE12: 10.687093 | AF12: 31.201397 | AG12: 10.379992 | AH12: 177.74969 | AI12: 83.162778 | AJ12: 44.959493 | AK12: 13.696676 | AL12: 8.7830703 | AM12: 35.746482 | AN12: 17.1362 | AO12: 14.863657 | AP12: 8.6602302 | AQ12: 16.276319 | AR12: 5.4663864 | AS12: 16.76768 | AT12: 9.5815313 | AU12: 34.02672 | AV12: 5.5278065 | AW12: 25.24365 | AX12: 14.617977 | AY12: 17.811821 | AZ12: 14.188037 | BA12: 15.784959 | BB12: 46.187894 | BC12: 31.754177 | BD12: 242.73213 | BE12: 7.1861484 | BF12: 48.890377 | BG12: 8.2302897 | BH12: 7.0018882 | BI12: 8.8444904 | BJ12: 33.351099 | BK12: 5.5278065 | BL12: 14.003776 | BM12: 9.335851 | BN12: 15.846379 | BO12: 333.51099 | BP12: 43.976772 | BQ12: 4.6679255 | BR12: 20.637144 | BS12: 5.8349069 | BT12: 18.118921 | BU12: 6.2648474 | BV12: 30.832876 | BW12: 10.011472 | BX12: 7.2475685 | BY12: 14.556557 | BZ12: 71.800064 | CA12: 8.53739 | CB12: 35.377962 | CC12: 12.836795 | CD12: 43.239731 | CE12: 16.030639 | CF12: 8.9673305 | CG12: 12.345435 | CH12: 15.662118 | CI12: 2.8253233 | CJ12: 22.295486 | CK12: 2.7639032 | CL12: 7.1861484 | CM12: 15.662118 | CN12: 8.7216502 | CO12: 0 | CP12: 29.235954 | CQ12: 0 | CR12: 23.093947 | CS12: 13.205316 | CT12: 32.122698 | CU12: 21.681285 | CV12: 11.485553 | CW12: 8.7830703 | CX12: 0.18426022 | CY12: 13.758096 | CZ12: 93.051409 | DA12: 11.055613 | DB12: 27.946133 | DC12: 21.619865 | DD12: 18.855962 | DE12: 5.5892266 | DF12: 64.183975 | DG12: 8.6602302 | DH12: 1.4126617 | DI12: 22.664007 | DJ12: 29.665895 | DK12: 28.376073 | DL12: 9.0901707 | DM12: 13.450996 | DN12: 11.854074 | DO12: 12.099754 | DP12: 36.852043 | DQ12: 6.4491076 | DR12: 15.170758 | DS12: 10.748513 | DT12: 11.424133 | DU12: 7.677509 | DV12: 9.1515908 | DW12: 29.113114 | DX12: 18.057501 | DY12: 28.007553 | DZ12: 30.525776 | EA12: 5.5278065 | EB12: 5.3676489 | EC12: 5.4670498 | ED12: 11.331703 | EE12: 9.6750215 | EF12: 15.804744 | EG12: 15.340873 | EH12: 12.789583 | EI12: 8.8466806 | EJ12: 13.750459 | EK12: 10.9341 | EL12: 9.3436851 | EM12: 14.31373 | EN12: 12.955251 | EO12: 22.398337 | EP12: 22.530872 | EQ12: 24.021886 | ER12: 8.6147452 | ES12: 16.069813 | ET12: 8.6478788 | EU12: 7.6207361 | EV12: 12.325712 | EW12: 11.530505 | EX12: 5.6989853 | EY12: 20.973591 | EZ12: 10.56963 | FA12: 9.9400906 | FB12: 10.403961 | FC12: 19.747647 | FD12: 15.837878 | FE12: 13.84986 | FF12: 8.5484779 | FG12: 8.6810124 | FH12: 12.358846 | FI12: 15.374007
A13: 05/07/25 05:30 | B13: 31.573355 | C13: 15.479544 | D13: 2.5184972 | E13: 8.5997466 | F13: 7.985479 | G13: 2.7642043 | H13: 20.823672 | I13: 41.033077 | J13: 9.7054283 | K13: 8.231186 | L13: 24.386424 | M13: 15.786678 | N13: 3.2556184 | O13: 7.6169184 | P13: 3.6856057 | Q13: 7.739772 | R13: 7.739772 | S13: 2.3342169 | T13: 3.0099113 | U13: 66.525183 | V13: 7.0640776 | W13: 13.943875 | X13: 4.2998733 | Y13: 2.4570705 | Z13: 17.629481 | AA13: 20.823672 | AB13: 13.636741 | AC13: 9.275441 | AD13: 17.138066 | AE13: 10.688257 | AF13: 31.204795 | AG13: 10.381123 | AH13: 177.76905 | AI13: 83.171835 | AJ13: 44.964389 | AK13: 13.698168 | AL13: 8.7840269 | AM13: 35.750375 | AN13: 17.138066 | AO13: 14.865276 | AP13: 8.6611734 | AQ13: 16.278092 | AR13: 5.4669818 | AS13: 16.769506 | AT13: 9.5825748 | AU13: 34.030426 | AV13: 5.5284085 | AW13: 25.246399 | AX13: 14.619569 | AY13: 17.813761 | AZ13: 14.189582 | BA13: 15.786678 | BB13: 46.192925 | BC13: 31.757636 | BD13: 242.75856 | BE13: 7.1869311 | BF13: 48.895702 | BG13: 8.231186 | BH13: 7.0026508 | BI13: 8.8454537 | BJ13: 33.354732 | BK13: 5.5284085 | BL13: 14.005302 | BM13: 9.3368678 | BN13: 15.848104 | BO13: 333.54732 | BP13: 43.981561 | BQ13: 4.6684339 | BR13: 20.639392 | BS13: 5.8355423 | BT13: 18.120895 | BU13: 6.2655297 | BV13: 30.836234 | BW13: 10.012562 | BX13: 7.2483579 | BY13: 14.558142 | BZ13: 71.807884 | CA13: 8.5383199 | CB13: 35.381815 | CC13: 12.838193 | CD13: 43.24444 | CE13: 16.032385 | CF13: 8.9683072 | CG13: 12.346779 | CH13: 15.663824 | CI13: 2.825631 | CJ13: 22.297914 | CK13: 2.7642043 | CL13: 7.1869311 | CM13: 15.663824 | CN13: 8.7226001 | CO13: 0 | CP13: 29.239138 | CQ13: 0 | CR13: 23.096462 | CS13: 13.206754 | CT13: 32.126196 | CU13: 21.683647 | CV13: 11.486804 | CW13: 8.7840269 | CX13: 0.18428028 | CY13: 13.759595 | CZ13: 93.061544 | DA13: 11.056817 | DB13: 27.949176 | DC13: 21.62222 | DD13: 18.858016 | DE13: 5.5898353 | DF13: 64.190966 | DG13: 8.6611734 | DH13: 1.4128155 | DI13: 22.666475 | DJ13: 29.669126 | DK13: 28.379164 | DL13: 9.0911607 | DM13: 13.452461 | DN13: 11.855365 | DO13: 12.101072 | DP13: 36.856057 | DQ13: 6.44981 | DR13: 15.17241 | DS13: 10.749683 | DT13: 11.425378 | DU13: 7.6783452 | DV13: 9.1525875 | DW13: 29.116285 | DX13: 18.059468 | DY13: 28.010603 | DZ13: 30.5291 | EA13: 5.5284085 | EB13: 5.493041 | EC13: 5.594764 | ED13: 11.59642 | EE13: 9.9010368 | EF13: 16.173954 | EG13: 15.699247 | EH13: 13.088357 | EI13: 9.0533453 | EJ13: 14.071679 | EK13: 11.189528 | EL13: 9.5619602 | EM13: 14.648109 | EN13: 13.257895 | EO13: 22.921578 | EP13: 23.057209 | EQ13: 24.583054 | ER13: 8.8159917 | ES13: 16.445215 | ET13: 8.8498994 | EU13: 7.7987619 | EV13: 12.61365 | EW13: 11.799866 | EX13: 5.8321176 | EY13: 21.463549 | EZ13: 10.816544 | FA13: 10.172298 | FB13: 10.647005 | FC13: 20.208966 | FD13: 16.207862 | FE13: 14.173402 | FF13: 8.7481764 | FG13: 8.883807 | FH13: 12.647557 | FI13: 15.733154
... A49: 05/07/25 23:30 | B49: 33.988214 | C49: 16.663482 | D49: 2.7111221 | E49: 9.2574901 | F49: 8.5962408 | G49: 2.9756218 | H49: 22.416351 | I49: 44.171453 | J49: 10.447739 | K49: 8.8607405 | L49: 26.251597 | M49: 16.994107 | N49: 3.5046212 | O49: 8.1994912 | P49: 3.9674957 | Q49: 8.3317411 | R49: 8.3317411 | S49: 2.5127473 | T49: 3.2401215 | U49: 71.613298 | V49: 7.6043668 | W49: 15.010359 | X49: 4.628745 | Y49: 2.6449972 | Z49: 18.977855 | AA49: 22.416351 | AB49: 14.679734 | AC49: 9.9848643 | AD49: 18.448855 | AE49: 11.505738 | AF49: 33.591464 | AG49: 11.175113 | AH49: 191.36554 | AI49: 89.533154 | AJ49: 48.403448 | AK49: 14.745859 | AL49: 9.4558649 | AM49: 38.484709 | AN49: 18.448855 | AO49: 16.002233 | AP49: 9.323615 | AQ49: 17.523106 | AR49: 5.8851187 | AS49: 18.052106 | AT49: 10.315489 | AU49: 36.633211 | AV49: 5.9512436 | AW49: 27.177346 | AX49: 15.737733 | AY49: 19.176229 | AZ49: 15.274859 | BA49: 16.994107 | BB49: 49.725947 | BC49: 34.186588 | BD49: 261.32572 | BE49: 7.7366167 | BF49: 52.635444 | BG49: 8.8607405 | BH49: 7.5382419 | BI49: 9.5219898 | BJ49: 35.905836 | BK49: 5.9512436 | BL49: 15.076484 | BM49: 10.050989 | BN49: 17.060232 | BO49: 359.05836 | BP49: 47.345449 | BQ49: 5.0254946 | BR49: 22.217976 | BS49: 6.2818683 | BT49: 19.506854 | BU49: 6.7447428 | BV49: 33.194714 | BW49: 10.778363 | BX49: 7.8027416 | BY49: 15.671608 | BZ49: 77.300042 | CA49: 9.1913651 | CB49: 38.087959 | CC49: 13.82011 | CD49: 46.55195 | CE49: 17.258606 | CF49: 9.6542396 | CG49: 13.291111 | CH49: 16.861857 | CI49: 3.0417467 | CJ49: 24.003349 | CK49: 2.9756218 | CL49: 7.7366167 | CM49: 16.861857 | CN49: 9.3897399 | CO49: 0 | CP49: 31.475466 | CQ49: 0 | CR49: 24.862973 | CS49: 14.21686 | CT49: 34.583338 | CU49: 23.3421 | CV49: 12.365362 | CW49: 9.4558649 | CX49: 0.19837479 | CY49: 14.811984 | CZ49: 100.17927 | DA49: 11.902487 | DB49: 30.086843 | DC49: 23.275975 | DD49: 20.300353 | DE49: 6.0173685 | DF49: 69.100551 | DG49: 9.323615 | DH49: 1.5208734 | DI49: 24.400099 | DJ49: 31.938341 | DK49: 30.549717 | DL49: 9.7864895 | DM49: 14.481359 | DN49: 12.762111 | DO49: 13.026611 | DP49: 39.674957 | DQ49: 6.9431176 | DR49: 16.332857 | DS49: 11.571863 | DT49: 12.299237 | DU49: 8.2656161 | DV49: 9.8526144 | DW49: 31.343216 | DX49: 19.440729 | DY49: 30.152968 | DZ49: 32.86409 | EA49: 5.9512436 | EB49: 7.3233314 | EC49: 7.4589486 | ED49: 15.460366 | EE49: 13.200079 | EF49: 21.563142 | EG49: 20.930262 | EH49: 17.449419 | EI49: 12.069935 | EJ49: 18.760386 | EK49: 14.917897 | EL49: 12.748021 | EM49: 19.528884 | EN49: 17.675448 | EO49: 30.559086 | EP49: 30.739909 | EQ49: 32.774168 | ER49: 11.753495 | ES49: 21.924788 | ET49: 11.798701 | EU49: 10.397322 | EV49: 16.816539 | EW49: 15.731601 | EX49: 7.7753889 | EY49: 28.615239 | EZ49: 14.420634 | FA49: 13.561725 | FB49: 14.194605 | FC49: 26.942626 | FD49: 21.608348 | FE49: 18.896003 | FF49: 11.663083 | FG49: 11.843906 | FH49: 16.861744 | FI49: 20.975468

Sheet ts_VOLL
A1: timestep | B1: AA_I_Z_110_PF0.993 | C1: AGN_I_Z_110_PF0.95 | D1: AHA_I_Z_110_PF0.998 | E1: ANR_I_Z_110_PF0.95 | F1: ARD_I_Z_110_PF0.99 | G1: ARI_I_T_110_PF0.998 | H1: ARK_I_Z_110_PF0.997 | I1: ATH_I_Z_110_PF0.998 | J1: ATY_I_Z_110_PF0.968 | K1: BAL_I_Z_110_PF1 | L1: BAN_I_Z_110_PF0.987 | M1: BAR_I_T_110_PF1 | N1: BDA_I_Z_110_PF0.95 | O1: BDN_I_Z_110_PF0.96 | P1: BDN_I_Z_110_PF0.95 | Q1: BEG_I_Z_110_PF1 | R1: BIN_I_Z_110_PF0.99 | S1: BIN_I_Z_110_PF0.999 | T1: BK_I_Z_110_PF0.996 | U1: BLC_I_Z_110_PF0.95 | V1: BLI_I_Z_110_PF0.991 | W1: BLK_I_Z_110_PF0.99 | X1: BOG_I_Z_110_PF0.97 | Y1: BRI_I_Z_110_PF0.95 | Z1: BRY_I_Z_110_PF0.976 | AA1: BUT_I_Z_110_PF0.989 | AB1: CAH_I_Z_110_PF0.981 | AC1: CBG_I_Z_110_PF0.984 | AD1: CBR_I_Z_110_PF0.988 | AE1: CF_I_Z_110_PF0.964 | AF1: CFM_I_Z_110_PF0.95 | AG1: CHA_I_Z_110_PF0.96 | AH1: CKM_I_Z_110_PF0.998 | AI1: CLE_I_Z_220_PF0.95 | AJ1: CLG_I_Z_110_PF0.95 | AK1: CLN_I_Z_110_PF0.925 | AL1: CLU_I_Z_110_PF0.95 | AM1: CLW_I_Z_110_PF0.991 | AN1: COL_I_Z_110_PF0.986 | AO1: COS_I_Z_110_PF0.989 | AP1: COW_I_Z_110_PF0.997 | AQ1: CRA_I_Z_110_PF0.979 | AR1: CRO_I_Z_110_PF1 | AS1: CVW_I_Z_110_PF0.982 | AT1: DAL_I_T_110_PF0.987 | AU1: DDK_I_Z_110_PF0.986 | AV1: DFR_I_T_110_PF0.991 | AW1: DGN_I_Z_110_PF0.984 | AX1: DLT_I_Z_110_PF0.981 | AY1: DMY_I_Z_110_PF0.976 | AZ1: DOO_I_Z_110_PF0.984 | BA1: DRU_I_Z_110_PF0.945 | BB1: DRY_I_Z_110_PF0.985 | BC1: ENN_I_Z_110_PF0.981 | BD1: FIN_I_Z_110_PF0.994 | BE1: FTT_I_Z_110_PF0.997 | BF1: GAL_I_Z_110_PF0.988 | BG1: GI_I_Z_110_PF0.952 | BH1: GIL_I_Z_110_PF0.95 | BI1: GLE_I_Z_110_PF0.998 | BJ1: GRI_I_T_110_PF0.997 | BK1: GWE_I_Z_110_PF0.98 | BL1: GWE_I_Z_110_PF0.95 | BM1: HN_I_Z_220_PF0.95 | BN1: IKE_I_T_110_PF0.967 | BO1: INC_I_Z_110_PF0.995 | BP1: KBY_I_Z_110_PF0.993 | BQ1: KCY_I_Z_110_PF0.95 | BR1: KER_I_Z_110_PF0.971 | BS1: KSE_I_Z_110_PF0.95 | BT1: KTL_I_Z_110_PF0.988 | BU1: KIN_I_Z_110_PF0.95 | BV1: KKY_I_Z_110_PF0.978 | BW1: KLM_I_Z_110_PF0.989 | BX1: KTN_I_Z_110_PF0.976 | BY1: KUR_I_Z_110_PF0.95 | BZ1: KYT_I_Z_220_PF0.95 | CA1: LA_I_Z_110_PF0.984 | CB1: LET_I_Z_110_PF0.987 | CC1: LIB_I_Z_110_PF0.986 | CD1: LIM_I_Z_110_PF0.993 | CE1: LIS_I_Z_110_PF0.952 | CF1: MAC_I_Z_110_PF0.973 | CG1: MAL_I_Z_110_PF0.981 | CH1: MCE_I_Z_110_PF0.995 | CI1: MCE_I_Z_110_PF0.95 | CJ1: MID_I_Z_110_PF0.98 | CK1: MLN_I_Z_110_PF0.95 | CL1: MON_I_Z_110_PF0.975 | CM1: MOY_I_Z_110_PF0.989 | CN1: MR_I_Z_110_PF0.992 | CO1: MTA_I_Z_110_PF0.95 | CP1: MTH_I_Z_110_PF0.938 | CQ1: MTN_I_Z_110_PF0.95 | CR1: MUL_I_Z_110_PF0.985 | CS1: MUN_I_Z_110_PF0.95 | CT1: NAV_I_Z_110_PF0.98 | CU1: NEW_I_Z_110_PF0.981 | CV1: NEN_I_Z_110_PF0.954 | CW1: OBE_I_Z_110_PF0.95 | CX1: OLD_I_Z_110_PF0.95 | CY1: OUG_I_T_110_PF0.992 | CZ1: PB_I_Z_110_PF0.989 | DA1: PLA_I_Z_110_PF0.95 | DB1: PLS_I_Z_110_PF0.979 | DC1: RAT_I_Z_110_PF0.993 | DD1: RIC_I_Z_110_PF0.972 | DE1: RNW_I_Z_110_PF0.95 | DF1: RYB_I_Z_110_PF0.95 | DG1: SCR_I_Z_110_PF0.999 | DH1: SHE_I_Z_110_PF0.95 | DI1: SHL_I_Z_220_PF0.997 | DJ1: SKL_I_Z_110_PF0.993 | DK1: SLI_I_Z_110_PF0.996 | DL1: SNG_I_Z_110_PF0.992 | DM1: SBH_I_Z_110_PF0.95 | DN1: SOM_I_T_110_PF0.974 | DO1: STR_I_T_110_PF0.958 | DP1: TBG_I_Z_110_PF0.994 | DQ1: TBK_I_T_110_PF0.931 | DR1: THU_I_Z_110_PF0.983 | DS1: TIP_I_Z_110_PF0.986 | DT1: TLK_I_Z_110_PF0.968 | DU1: TON_I_Z_110_PF0.925 | DV1: TRI_I_Z_110_PF1 | DW1: TRL_I_Z_110_PF0.99 | DX1: TSB_I_Z_110_PF0.977 | DY1: WAT_I_Z_110_PF0.986 | DZ1: WEX_I_Z_110_PF0.979 | EA1: WHI_I_Z_110_PF0.95 | EB1: AGH_N_Z_110_PF0.99 | EC1: AIR_N_Z_110_PF0.99 | ED1: ANT_N_Z_110_PF0.98 | EE1: BAN_N_Z_33_PF0.99 | EF1: BMA_N_Z_110_PF0.95 | EG1: BNH_N_Z_110_PF0.99 | EH1: BNM_N_Z_110_PF0.99 | EI1: CAR_N_Z_110_PF0.99 | EJ1: CEN_N_Z_110_PF0.99 | EK1: COL_N_Z_33_PF0.99 | EL1: CPS_N_Z_110_PF0.99 | EM1: CRE_N_Z_110_PF0.99 | EN1: CRG_N_Z_110_PF0.99 | EO1: DON_N_Z_110_PF0.99 | EP1: DRU_N_Z_33_PF0.99 | EQ1: DUN_N_Z_110_PF0.99 | ER1: EDE_N_Z_110_PF0.99 | ES1: ENN_N_Z_33_PF0.99 | ET1: FIN_N_Z_33_PF0.99 | EU1: GLE_N_Z_33_PF0.99 | EV1: KNO_N_Z_110_PF0.99 | EW1: LAR_N_Z_110_PF0.99 | EX1: LIM_N_Z_33_PF0.99 | EY1: LIS_N_Z_33_PF0.99 | EZ1: LMR_N_Z_110_PF0.98 | FA1: LOG_N_Z_110_PF0.98 | FB1: NAR_N_Z_110_PF0.99 | FC1: NEW_N_Z_33_PF0.99 | FD1: OMA_N_Z_110_PF0.99 | FE1: RAT_N_Z_33_PF0.99 | FF1: ROS_N_Z_110_PF0.99 | FG1: SPR_N_Z_110_PF0.99 | FH1: STR_N_Z_33_PF0.99 | FI1: WAR_N_Z_110_PF0.99
A2: 05/07/25 00:00 | B2: 20000 | C2: 20000 | D2: 20000 | E2: 20000 | F2: 20000 | G2: 20000 | H2: 20000 | I2: 20000 | J2: 20000 | K2: 20000 | L2: 20000 | M2: 20000 | N2: 20000 | O2: 20000 | P2: 20000 | Q2: 20000 | R2: 20000 | S2: 20000 | T2: 20000 | U2: 20000 | V2: 20000 | W2: 20000 | X2: 20000 | Y2: 20000 | Z2: 20000 | AA2: 20000 | AB2: 20000 | AC2: 20000 | AD2: 20000 | AE2: 20000 | AF2: 20000 | AG2: 20000 | AH2: 20000 | AI2: 20000 | AJ2: 20000 | AK2: 20000 | AL2: 20000 | AM2: 20000 | AN2: 20000 | AO2: 20000 | AP2: 20000 | AQ2: 20000 | AR2: 20000 | AS2: 20000 | AT2: 20000 | AU2: 20000 | AV2: 20000 | AW2: 20000 | AX2: 20000 | AY2: 20000 | AZ2: 20000 | BA2: 20000 | BB2: 20000 | BC2: 20000 | BD2: 20000 | BE2: 20000 | BF2: 20000 | BG2: 20000 | BH2: 20000 | BI2: 20000 | BJ2: 20000 | BK2: 20000 | BL2: 20000 | BM2: 20000 | BN2: 20000 | BO2: 20000 | BP2: 20000 | BQ2: 20000 | BR2: 20000 | BS2: 20000 | BT2: 20000 | BU2: 20000 | BV2: 20000 | BW2: 20000 | BX2: 20000 | BY2: 20000 | BZ2: 20000 | CA2: 20000 | CB2: 20000 | CC2: 20000 | CD2: 20000 | CE2: 20000 | CF2: 20000 | CG2: 20000 | CH2: 20000 | CI2: 20000 | CJ2: 20000 | CK2: 20000 | CL2: 20000 | CM2: 20000 | CN2: 20000 | CO2: 20000 | CP2: 20000 | CQ2: 20000 | CR2: 20000 | CS2: 20000 | CT2: 20000 | CU2: 20000 | CV2: 20000 | CW2: 20000 | CX2: 20000 | CY2: 20000 | CZ2: 20000 | DA2: 20000 | DB2: 20000 | DC2: 20000 | DD2: 20000 | DE2: 20000 | DF2: 20000 | DG2: 20000 | DH2: 20000 | DI2: 20000 | DJ2: 20000 | DK2: 20000 | DL2: 20000 | DM2: 20000 | DN2: 20000 | DO2: 20000 | DP2: 20000 | DQ2: 20000 | DR2: 20000 | DS2: 20000 | DT2: 20000 | DU2: 20000 | DV2: 20000 | DW2: 20000 | DX2: 20000 | DY2: 20000 | DZ2: 20000 | EA2: 20000 | EB2: 20000 | EC2: 20000 | ED2: 20000 | EE2: 20000 | EF2: 20000 | EG2: 20000 | EH2: 20000 | EI2: 20000 | EJ2: 20000 | EK2: 20000 | EL2: 20000 | EM2: 20000 | EN2: 20000 | EO2: 20000 | EP2: 20000 | EQ2: 20000 | ER2: 20000 | ES2: 20000 | ET2: 20000 | EU2: 20000 | EV2: 20000 | EW2: 20000 | EX2: 20000 | EY2: 20000 | EZ2: 20000 | FA2: 20000 | FB2: 20000 | FC2: 20000 | FD2: 20000 | FE2: 20000 | FF2: 20000 | FG2: 20000 | FH2: 20000 | FI2: 20000
A3: 05/07/25 00:30 | B3: 20000 | C3: 20000 | D3: 20000 | E3: 20000 | F3: 20000 | G3: 20000 | H3: 20000 | I3: 20000 | J3: 20000 | K3: 20000 | L3: 20000 | M3: 20000 | N3: 20000 | O3: 20000 | P3: 20000 | Q3: 20000 | R3: 20000 | S3: 20000 | T3: 20000 | U3: 20000 | V3: 20000 | W3: 20000 | X3: 20000 | Y3: 20000 | Z3: 20000 | AA3: 20000 | AB3: 20000 | AC3: 20000 | AD3: 20000 | AE3: 20000 | AF3: 20000 | AG3: 20000 | AH3: 20000 | AI3: 20000 | AJ3: 20000 | AK3: 20000 | AL3: 20000 | AM3: 20000 | AN3: 20000 | AO3: 20000 | AP3: 20000 | AQ3: 20000 | AR3: 20000 | AS3: 20000 | AT3: 20000 | AU3: 20000 | AV3: 20000 | AW3: 20000 | AX3: 20000 | AY3: 20000 | AZ3: 20000 | BA3: 20000 | BB3: 20000 | BC3: 20000 | BD3: 20000 | BE3: 20000 | BF3: 20000 | BG3: 20000 | BH3: 20000 | BI3: 20000 | BJ3: 20000 | BK3: 20000 | BL3: 20000 | BM3: 20000 | BN3: 20000 | BO3: 20000 | BP3: 20000 | BQ3: 20000 | BR3: 20000 | BS3: 20000 | BT3: 20000 | BU3: 20000 | BV3: 20000 | BW3: 20000 | BX3: 20000 | BY3: 20000 | BZ3: 20000 | CA3: 20000 | CB3: 20000 | CC3: 20000 | CD3: 20000 | CE3: 20000 | CF3: 20000 | CG3: 20000 | CH3: 20000 | CI3: 20000 | CJ3: 20000 | CK3: 20000 | CL3: 20000 | CM3: 20000 | CN3: 20000 | CO3: 20000 | CP3: 20000 | CQ3: 20000 | CR3: 20000 | CS3: 20000 | CT3: 20000 | CU3: 20000 | CV3: 20000 | CW3: 20000 | CX3: 20000 | CY3: 20000 | CZ3: 20000 | DA3: 20000 | DB3: 20000 | DC3: 20000 | DD3: 20000 | DE3: 20000 | DF3: 20000 | DG3: 20000 | DH3: 20000 | DI3: 20000 | DJ3: 20000 | DK3: 20000 | DL3: 20000 | DM3: 20000 | DN3: 20000 | DO3: 20000 | DP3: 20000 | DQ3: 20000 | DR3: 20000 | DS3: 20000 | DT3: 20000 | DU3: 20000 | DV3: 20000 | DW3: 20000 | DX3: 20000 | DY3: 20000 | DZ3: 20000 | EA3: 20000 | EB3: 20000 | EC3: 20000 | ED3: 20000 | EE3: 20000 | EF3: 20000 | EG3: 20000 | EH3: 20000 | EI3: 20000 | EJ3: 20000 | EK3: 20000 | EL3: 20000 | EM3: 20000 | EN3: 20000 | EO3: 20000 | EP3: 20000 | EQ3: 20000 | ER3: 20000 | ES3: 20000 | ET3: 20000 | EU3: 20000 | EV3: 20000 | EW3: 20000 | EX3: 20000 | EY3: 20000 | EZ3: 20000 | FA3: 20000 | FB3: 20000 | FC3: 20000 | FD3: 20000 | FE3: 20000 | FF3: 20000 | FG3: 20000 | FH3: 20000 | FI3: 20000
A4: 05/07/25 01:00 | B4: 20000 | C4: 20000 | D4: 20000 | E4: 20000 | F4: 20000 | G4: 20000 | H4: 20000 | I4: 20000 | J4: 20000 | K4: 20000 | L4: 20000 | M4: 20000 | N4: 20000 | O4: 20000 | P4: 20000 | Q4: 20000 | R4: 20000 | S4: 20000 | T4: 20000 | U4: 20000 | V4: 20000 | W4: 20000 | X4: 20000 | Y4: 20000 | Z4: 20000 | AA4: 20000 | AB4: 20000 | AC4: 20000 | AD4: 20000 | AE4: 20000 | AF4: 20000 | AG4: 20000 | AH4: 20000 | AI4: 20000 | AJ4: 20000 | AK4: 20000 | AL4: 20000 | AM4: 20000 | AN4: 20000 | AO4: 20000 | AP4: 20000 | AQ4: 20000 | AR4: 20000 | AS4: 20000 | AT4: 20000 | AU4: 20000 | AV4: 20000 | AW4: 20000 | AX4: 20000 | AY4: 20000 | AZ4: 20000 | BA4: 20000 | BB4: 20000 | BC4: 20000 | BD4: 20000 | BE4: 20000 | BF4: 20000 | BG4: 20000 | BH4: 20000 | BI4: 20000 | BJ4: 20000 | BK4: 20000 | BL4: 20000 | BM4: 20000 | BN4: 20000 | BO4: 20000 | BP4: 20000 | BQ4: 20000 | BR4: 20000 | BS4: 20000 | BT4: 20000 | BU4: 20000 | BV4: 20000 | BW4: 20000 | BX4: 20000 | BY4: 20000 | BZ4: 20000 | CA4: 20000 | CB4: 20000 | CC4: 20000 | CD4: 20000 | CE4: 20000 | CF4: 20000 | CG4: 20000 | CH4: 20000 | CI4: 20000 | CJ4: 20000 | CK4: 20000 | CL4: 20000 | CM4: 20000 | CN4: 20000 | CO4: 20000 | CP4: 20000 | CQ4: 20000 | CR4: 20000 | CS4: 20000 | CT4: 20000 | CU4: 20000 | CV4: 20000 | CW4: 20000 | CX4: 20000 | CY4: 20000 | CZ4: 20000 | DA4: 20000 | DB4: 20000 | DC4: 20000 | DD4: 20000 | DE4: 20000 | DF4: 20000 | DG4: 20000 | DH4: 20000 | DI4: 20000 | DJ4: 20000 | DK4: 20000 | DL4: 20000 | DM4: 20000 | DN4: 20000 | DO4: 20000 | DP4: 20000 | DQ4: 20000 | DR4: 20000 | DS4: 20000 | DT4: 20000 | DU4: 20000 | DV4: 20000 | DW4: 20000 | DX4: 20000 | DY4: 20000 | DZ4: 20000 | EA4: 20000 | EB4: 20000 | EC4: 20000 | ED4: 20000 | EE4: 20000 | EF4: 20000 | EG4: 20000 | EH4: 20000 | EI4: 20000 | EJ4: 20000 | EK4: 20000 | EL4: 20000 | EM4: 20000 | EN4: 20000 | EO4: 20000 | EP4: 20000 | EQ4: 20000 | ER4: 20000 | ES4: 20000 | ET4: 20000 | EU4: 20000 | EV4: 20000 | EW4: 20000 | EX4: 20000 | EY4: 20000 | EZ4: 20000 | FA4: 20000 | FB4: 20000 | FC4: 20000 | FD4: 20000 | FE4: 20000 | FF4: 20000 | FG4: 20000 | FH4: 20000 | FI4: 20000
A5: 05/07/25 01:30 | B5: 20000 | C5: 20000 | D5: 20000 | E5: 20000 | F5: 20000 | G5: 20000 | H5: 20000 | I5: 20000 | J5: 20000 | K5: 20000 | L5: 20000 | M5: 20000 | N5: 20000 | O5: 20000 | P5: 20000 | Q5: 20000 | R5: 20000 | S5: 20000 | T5: 20000 | U5: 20000 | V5: 20000 | W5: 20000 | X5: 20000 | Y5: 20000 | Z5: 20000 | AA5: 20000 | AB5: 20000 | AC5: 20000 | AD5: 20000 | AE5: 20000 | AF5: 20000 | AG5: 20000 | AH5: 20000 | AI5: 20000 | AJ5: 20000 | AK5: 20000 | AL5: 20000 | AM5: 20000 | AN5: 20000 | AO5: 20000 | AP5: 20000 | AQ5: 20000 | AR5: 20000 | AS5: 20000 | AT5: 20000 | AU5: 20000 | AV5: 20000 | AW5: 20000 | AX5: 20000 | AY5: 20000 | AZ5: 20000 | BA5: 20000 | BB5: 20000 | BC5: 20000 | BD5: 20000 | BE5: 20000 | BF5: 20000 | BG5: 20000 | BH5: 20000 | BI5: 20000 | BJ5: 20000 | BK5: 20000 | BL5: 20000 | BM5: 20000 | BN5: 20000 | BO5: 20000 | BP5: 20000 | BQ5: 20000 | BR5: 20000 | BS5: 20000 | BT5: 20000 | BU5: 20000 | BV5: 20000 | BW5: 20000 | BX5: 20000 | BY5: 20000 | BZ5: 20000 | CA5: 20000 | CB5: 20000 | CC5: 20000 | CD5: 20000 | CE5: 20000 | CF5: 20000 | CG5: 20000 | CH5: 20000 | CI5: 20000 | CJ5: 20000 | CK5: 20000 | CL5: 20000 | CM5: 20000 | CN5: 20000 | CO5: 20000 | CP5: 20000 | CQ5: 20000 | CR5: 20000 | CS5: 20000 | CT5: 20000 | CU5: 20000 | CV5: 20000 | CW5: 20000 | CX5: 20000 | CY5: 20000 | CZ5: 20000 | DA5: 20000 | DB5: 20000 | DC5: 20000 | DD5: 20000 | DE5: 20000 | DF5: 20000 | DG5: 20000 | DH5: 20000 | DI5: 20000 | DJ5: 20000 | DK5: 20000 | DL5: 20000 | DM5: 20000 | DN5: 20000 | DO5: 20000 | DP5: 20000 | DQ5: 20000 | DR5: 20000 | DS5: 20000 | DT5: 20000 | DU5: 20000 | DV5: 20000 | DW5: 20000 | DX5: 20000 | DY5: 20000 | DZ5: 20000 | EA5: 20000 | EB5: 20000 | EC5: 20000 | ED5: 20000 | EE5: 20000 | EF5: 20000 | EG5: 20000 | EH5: 20000 | EI5: 20000 | EJ5: 20000 | EK5: 20000 | EL5: 20000 | EM5: 20000 | EN5: 20000 | EO5: 20000 | EP5: 20000 | EQ5: 20000 | ER5: 20000 | ES5: 20000 | ET5: 20000 | EU5: 20000 | EV5: 20000 | EW5: 20000 | EX5: 20000 | EY5: 20000 | EZ5: 20000 | FA5: 20000 | FB5: 20000 | FC5: 20000 | FD5: 20000 | FE5: 20000 | FF5: 20000 | FG5: 20000 | FH5: 20000 | FI5: 20000
A6: 05/07/25 02:00 | B6: 20000 | C6: 20000 | D6: 20000 | E6: 20000 | F6: 20000 | G6: 20000 | H6: 20000 | I6: 20000 | J6: 20000 | K6: 20000 | L6: 20000 | M6: 20000 | N6: 20000 | O6: 20000 | P6: 20000 | Q6: 20000 | R6: 20000 | S6: 20000 | T6: 20000 | U6: 20000 | V6: 20000 | W6: 20000 | X6: 20000 | Y6: 20000 | Z6: 20000 | AA6: 20000 | AB6: 20000 | AC6: 20000 | AD6: 20000 | AE6: 20000 | AF6: 20000 | AG6: 20000 | AH6: 20000 | AI6: 20000 | AJ6: 20000 | AK6: 20000 | AL6: 20000 | AM6: 20000 | AN6: 20000 | AO6: 20000 | AP6: 20000 | AQ6: 20000 | AR6: 20000 | AS6: 20000 | AT6: 20000 | AU6: 20000 | AV6: 20000 | AW6: 20000 | AX6: 20000 | AY6: 20000 | AZ6: 20000 | BA6: 20000 | BB6: 20000 | BC6: 20000 | BD6: 20000 | BE6: 20000 | BF6: 20000 | BG6: 20000 | BH6: 20000 | BI6: 20000 | BJ6: 20000 | BK6: 20000 | BL6: 20000 | BM6: 20000 | BN6: 20000 | BO6: 20000 | BP6: 20000 | BQ6: 20000 | BR6: 20000 | BS6: 20000 | BT6: 20000 | BU6: 20000 | BV6: 20000 | BW6: 20000 | BX6: 20000 | BY6: 20000 | BZ6: 20000 | CA6: 20000 | CB6: 20000 | CC6: 20000 | CD6: 20000 | CE6: 20000 | CF6: 20000 | CG6: 20000 | CH6: 20000 | CI6: 20000 | CJ6: 20000 | CK6: 20000 | CL6: 20000 | CM6: 20000 | CN6: 20000 | CO6: 20000 | CP6: 20000 | CQ6: 20000 | CR6: 20000 | CS6: 20000 | CT6: 20000 | CU6: 20000 | CV6: 20000 | CW6: 20000 | CX6: 20000 | CY6: 20000 | CZ6: 20000 | DA6: 20000 | DB6: 20000 | DC6: 20000 | DD6: 20000 | DE6: 20000 | DF6: 20000 | DG6: 20000 | DH6: 20000 | DI6: 20000 | DJ6: 20000 | DK6: 20000 | DL6: 20000 | DM6: 20000 | DN6: 20000 | DO6: 20000 | DP6: 20000 | DQ6: 20000 | DR6: 20000 | DS6: 20000 | DT6: 20000 | DU6: 20000 | DV6: 20000 | DW6: 20000 | DX6: 20000 | DY6: 20000 | DZ6: 20000 | EA6: 20000 | EB6: 20000 | EC6: 20000 | ED6: 20000 | EE6: 20000 | EF6: 20000 | EG6: 20000 | EH6: 20000 | EI6: 20000 | EJ6: 20000 | EK6: 20000 | EL6: 20000 | EM6: 20000 | EN6: 20000 | EO6: 20000 | EP6: 20000 | EQ6: 20000 | ER6: 20000 | ES6: 20000 | ET6: 20000 | EU6: 20000 | EV6: 20000 | EW6: 20000 | EX6: 20000 | EY6: 20000 | EZ6: 20000 | FA6: 20000 | FB6: 20000 | FC6: 20000 | FD6: 20000 | FE6: 20000 | FF6: 20000 | FG6: 20000 | FH6: 20000 | FI6: 20000
