Workbook

Sheet bus
A1: name | B1: description | C1: baseKV | D1: type | E1: zone
A2: AA_I_Z_110 | B2: Ardnacrusha_110kV | C2: 110 | D2: 1 | E2: I
A3: AA1_I_Z_110 | B3: Ardnacrusha_110kV | C3: 110 | D3: 1 | E3: I
A4: AD_I_Z_110 | B4: Aghada_110kV | C4: 110 | D4: 1 | E4: I
A5: AD_I_Z_220 | B5: Aghada_220kV | C5: 220 | D5: 1 | E5: I
A6: ADM_I_Z_110 | B6: Adamstown_110kV | C6: 110 | D6: 1 | E6: I
A7: AGH_N_Z_110 | B7: Aghyoule_110kV | C7: 110 | D7: 1 | E7: N
A8: AGH_N_Z_33 | B8: Aghyoule_33kV | C8: 33 | D8: 1 | E8: N
A9: AGL_I_Z_110 | B9: Agannygal_110kV | C9: 110 | D9: 1 | E9: I
A10: AGN_I_Z_110 | B10: Aungierstown_110kV | C10: 110 | D10: 1 | E10: I
A11: AHA_I_Z_110 | B11: Ahane_110kV | C11: 110 | D11: 1 | E11: I
A12: AIR_N_Z_110 | B12: Airport Road_110kV | C12: 110 | D12: 1 | E12: N
A13: AIR_N_Z_33 | B13: Airport Road_33kV | C13: 33 | D13: 1 | E13: N
A14: ANR_I_Z_110 | B14: Anner_110kV | C14: 110 | D14: 1 | E14: I
A15: ANT_N_Z_110 | B15: Antrim_110kV | C15: 110 | D15: 1 | E15: N
A16: ANT_N_Z_33 | B16: Antrim_33kV | C16: 33 | D16: 1 | E16: N
A17: ARD_I_Z_110 | B17: Ardnagappary_110kV | C17: 110 | D17: 1 | E17: I
A18: ARI_I_T_110 | B18: Arigna_110kV_Tee | C18: 110 | D18: 1 | E18: I
A19: ARI_I_Z_110 | B19: Arigna_110kV | C19: 110 | D19: 1 | E19: I
A20: ARK_I_Z_110 | B20: Arklow_110kV | C20: 110 | D20: 1 | E20: I
A21: ARK_I_Z_220 | B21: Arklow_220kV | C21: 220 | D21: 1 | E21: I
A22: ART_I_Z_110 | B22: Artane_110kV | C22: 110 | D22: 1 | E22: I
A23: ARV_I_Z_110 | B23: Arva_110kV | C23: 110 | D23: 1 | E23: I
A24: ATE_I_Z_110 | B24: Athea_110kV | C24: 110 | D24: 1 | E24: I
... A119: CLW_I_Z_110 | B119: Carlow_110kV | C119: 110 | D119: 1 | E119: I
A120: CNB_I_Z_380 | B120: Coolnabacky_380kV | C120: 330 | D120: 1 | E120: I
A121: CNB_I_Z_110 | B121: Coolnabacky_110kV | C121: 110 | D121: 1 | E121: I
A122: CNG_I_Z_110 | B122: Coolnanoonag_110kV | C122: 110 | D122: 1 | E122: I
A123: COL_I_Z_110 | B123: College Park_110kV | C123: 110 | D123: 1 | E123: I
A124: COL_N_Z_110 | B124: Coleraine_110kV | C124: 110 | D124: 1 | E124: N
A125: COL_N_Z_33 | B125: Coleraine_33kV | C125: 33 | D125: 1 | E125: N
A126: COO_I_Z_110 | B126: Cookstown_110kV | C126: 110 | D126: 1 | E126: I
A127: COR_I_Z_110 | B127: Corraclassy_110kV | C127: 110 | D127: 1 | E127: I
A128: COS_I_Z_110 | B128: Carrick-on-Shannon_110kV | C128: 110 | D128: 1 | E128: I
A129: COW_I_Z_110 | B129: Cow Cross_110kV | C129: 110 | D129: 1 | E129: I
A130: CPK_I_Z_110 | B130: Central Park_110kV | C130: 110 | D130: 1 | E130: I
A131: CPS_N_Z_110 | B131: Coolkeeragh Power Station_110kV | C131: 110 | D131: 1 | E131: N
A132: CPS_N_Z_275 | B132: Coolkeeragh Power Station_275kV | C132: 275 | D132: 1 | E132: N
... A231: HN_I_Z_220 | B231: Huntstown_220kV | C231: 220 | D231: 1 | E231: I
A232: HWN_I_Z_110 | B232: Harristown_110kV | C232: 110 | D232: 1 | E232: I
...

Sheet demand
A1: name | B1: busname | C1: real | D1: stat | E1: VOLL
A2: AA(I)(Z)PF1 | B2: AA_I_Z_110 | C2: 28.6 | D2: 1 | E2: 7000
A3: AGH(N)(Z)PF0.99 | B3: AGH_N_Z_33 | C3: 6 | D3: 1 | E3: 7000
A4: AGN(I)(Z)PF0.95 | B4: AGN_I_Z_110 | C4: 0 | D4: 1 | E4: 7000
A5: AHA(I)(Z)PF0.965 | B5: AHA_I_Z_110 | C5: 1.2 | D5: 1 | E5: 7000
A6: AIR(N)(Z)PF0.99 | B6: AIR_N_Z_33 | C6: 0 | D6: 1 | E6: 7000
A7: ANR(I)(Z)PF0.95 | B7: ANR_I_Z_110 | C7: 14 | D7: 1 | E7: 7000
A8: ANT(N)(Z)PF0.98 | B8: ANT_N_Z_33 | C8: 12.4 | D8: 1 | E8: 7000
A9: ARD(I)(Z)PF0.99 | B9: ARD_I_Z_110 | C9: 4.7 | D9: 1 | E9: 7000
A10: ARI(I)(T)PF0.911 | B10: ARI_I_T_110 | C10: 0.9 | D10: 1 | E10: 7000
A11: ARK(I)(Z)PF0.967 | B11: ARK_I_Z_110 | C11: 15.4 | D11: 1 | E11: 7000
A12: ATH(I)(Z)PF0.995 | B12: ATH_I_Z_110 | C12: 26.7 | D12: 1 | E12: 7000
A13: ATY(I)(Z)PF0.971 | B13: ATY_I_Z_110 | C13: 6.1 | D13: 1 | E13: 7000
... A167: WHI(I)(Z)PF0.95 | B167: WHI_I_Z_110 | C167: 9 | D167: 1 | E167: 7000

Sheet ts_PD
A1: timestep | B1: {=TRANSPOSE(_xlfn._xlws.FILTER(demand!$A$2:$A$167,demand!$D$2:$D$167=1))} -> AA(I)(Z)PF1 | C1: AGH(N)(Z)PF0.99 | D1: AGN(I)(Z)PF0.95 | E1: AHA(I)(Z)PF0.965 | F1: AIR(N)(Z)PF0.99 | G1: ANR(I)(Z)PF0.95 | H1: ANT(N)(Z)PF0.98 | I1: ARD(I)(Z)PF0.99 | J1: ARI(I)(T)PF0.911 | K1: ARK(I)(Z)PF0.967 | L1: ATH(I)(Z)PF0.995 | M1: ATY(I)(Z)PF0.971 | N1: BAG(I)PF0.95 | O1: BAL(I)(Z)PF0.998 | P1: BAN(I)(Z)PF0.993 | Q1: BAN(I)(Z)PF0.99 | R1: BAN(N)(Z)PF0.958 | S1: BAR(I)(T)PF0.95 | T1: BDA(I)(Z)PF0.982 | U1: BDN(I)(Z)PF0.95 | V1: BDN(I)(Z)PF0.992 | W1: BEG(I)(Z)PF0.992 | X1: BIN(I)(Z)PF0.992 | Y1: BK(I)(Z)PF0.998 | Z1: BLC(I)(Z)PF0.951 | AA1: BLI(I)(Z)PF0.925 | AB1: BLK(I)(Z)PF0.999 | AC1: BMA(N)(Z)PF0.95 | AD1: BNH(N)(Z)PF0.99 | AE1: BNM(N)(Z)PF0.99 | AF1: BOG(I)(Z)PF0.989 | AG1: BRI(I)(Z)PF0.95 | AH1: BRY(I)(Z)PF0.982 | AI1: BUT(I)(Z)PF0.999 | AJ1: CAH(I)(Z)PF1 | AK1: CAR(N)(Z)PF0.99 | AL1: CBG(I)(Z)PF0.996 | AM1: CBR(I)(Z)PF0.984 | AN1: CEN(N)(Z)PF0.99 | AO1: CF(I)(Z)PF0.999 | AP1: CFM(I)(Z)PF0.95 | AQ1: CHA(I)(Z)PF0.999 | AR1: CKM(I)(Z)PF0.998 | AS1: CLE(I)(Z)PF0.95 | AT1: CLG(I)(Z)PF0.95 | AU1: CLN(I)(Z)PF1 | AV1: CLU(I)(Z)PF0.95 | AW1: CLW(I)(Z)PF0.982 | AX1: COL(I)(Z)PF0.993 | AY1: COL(N)(Z)PF0.99 | AZ1: COS(I)(Z)PF1 | BA1: COW(I)(Z)PF1 | BB1: CPS(N)(Z)PF0.99 | BC1: CRA(I)(Z)PF0.999 | BD1: CRE(N)(Z)PF0.99 | BE1: CRG(N)(Z)PF0.99 | BF1: CRO(I)(Z)PF1 | BG1: CVW(I)(Z)PF0.95 | BH1: CVW(I)(Z)PF0.992 | BI1: DAL(I)(T)PF0.993 | BJ1: DDK(I)(Z)PF1 | BK1: DFR(I)(T)PF1 | BL1: DGN(I)(Z)PF1 | BM1: DLT(I)(Z)PF0.999 | BN1: DMY(I)(Z)PF0.983 | BO1: DON(N)(Z)PF0.99 | BP1: DOO(I)(Z)PF1 | BQ1: DRU(I)(Z)PF0.873 | BR1: DRU(N)(Z)PF0.99 | BS1: DRY(I)(Z)PF1 | BT1: DUN(N)(Z)PF0.99 | BU1: EDE(N)(Z)PF0.99 | BV1: ENN(I)(Z)PF0.996 | BW1: ENN(N)(Z)PF0.99 | BX1: FIN(N)(Z)PF0.99 | BY1: FIN(I)(Z)PF0.984 | BZ1: FTT(I)(Z)PF1 | CA1: GAL(I)(Z)PF1 | CB1: GI(I)(Z)PF0.979 | CC1: GIL(I)(Z)PF0.95 | CD1: GLE(I)(Z)PF0.956 | CE1: GLE(N)(Z)PF0.99 | CF1: GRI(I)(T)PF1 | CG1: GWE(I)(Z)PF0.981 | CH1: GWE(I)(Z)PF0.95 | CI1: HN(I)(Z)PF0.95 | CJ1: IKE(I)(T)PF0.996 | CK1: INC(I)(Z)PF0.999 | CL1: KBY(I)(Z)PF1 | CM1: KCY(I)(Z)PF0.95 | CN1: KER(I)(Z)PF0.99 | CO1: KSE(I)(Z)PF0.95 | CP1: KTL(I)(Z)PF0.998 | CQ1: KIN(I)(Z)PF0.95 | CR1: KKY(I)(Z)PF1 | CS1: KLM(I)(Z)PF0.992 | CT1: KNO(N)(Z)PF0.99 | CU1: KTN(I)(Z)PF0.993 | CV1: KUR(I)(Z)PF0.95 | CW1: KYT(I)(Z)PF0.95 | CX1: LA(I)(Z)PF1 | CY1: LAR(N)(Z)PF0.99 | CZ1: LET(I)(Z)PF0.996 | DA1: LIB(I)(Z)PF0.989 | DB1: LIM(I)(Z)PF1 | DC1: LIM(N)(Z)PF0.99 | DD1: LIS(I)(Z)PF0.992 | DE1: LIS(N)(Z)PF0.99 | DF1: LMR(N)(Z)PF0.98 | DG1: LOG(N)(Z)PF0.98 | DH1: MAC(I)(Z)PF0.96 | DI1: MAL(I)(Z)PF0.988 | DJ1: MCE(I)(Z)PF0.95 | DK1: MHL(I)(Z)PF1 | DL1: MID(I)(Z)PF0.99 | DM1: MLN(I)(Z)PF0.95 | DN1: MON(I)(Z)PF0.999 | DO1: MOY(I)(Z)PF1 | DP1: MR(I)(Z)PF0.999 | DQ1: MTA(I)(Z)PF0.95 | DR1: MTH(I)(Z)PF0.984 | DS1: MNH(I)(Z)PF0.95 | DT1: MUL(I)(Z)PF0.998 | DU1: MUN(I)(Z)PF0.95 | DV1: NAR(N)(Z)PF0.99 | DW1: NAV(I)(Z)PF0.969 | DX1: NEW(I)(Z)PF1 | DY1: NEW(N)(Z)PF0.99 | DZ1: NEN(I)(Z)PF0.977 | EA1: OBE(I)(Z)PF0.95 | EB1: OLD(I)(Z)PF0.95 | EC1: OMA(N)(Z)PF0.99 | ED1: OUG(I)(T)PF0.989 | EE1: PLA(I)(Z)PF0.95 | EF1: PB(I)(Z)PF0.989 | EG1: PLS(I)(Z)PF0.996 | EH1: RAT(I)(Z)PF0.997 | EI1: RAT(N)(Z)PF0.99 | EJ1: RIC(I)(Z)PF0.997 | EK1: RNW(I)(Z)PF0.95 | EL1: ROS(N)(Z)PF0.99 | EM1: RYB(I)(Z)PF0.95 | EN1: SCR(I)(Z)PF0.976 | EO1: SHE(I)(Z)PF0.95 | EP1: SAL(I)(Z)PF0.997 | EQ1: SKL(I)(Z)PF0.997 | ER1: SLI(I)(Z)PF1 | ES1: SNG(I)(Z)PF1 | ET1: SBH(I)(Z)PF0.95 | EU1: SOM(I)(T)PF0.998 | EV1: SPR(N)(Z)PF0.99 | EW1: STR(I)(T)PF1 | EX1: STR(N)(Z)PF0.99 | EY1: TBG(I)(Z)PF1 | EZ1: TBK(I)(T)PF0.992 | FA1: THU(I)(Z)PF0.99 | FB1: TIP(I)(Z)PF0.992 | FC1: TLK(I)(Z)PF0.994 | FD1: TON(I)(Z)PF0.987 | FE1: TRI(I)(Z)PF0.962 | FF1: TRL(I)(Z)PF0.997 | FG1: TSB(I)(Z)PF0.996 | FH1: WAR(N)(Z)PF0.99 | FI1: WAT(I)(Z)PF1 | FJ1: WEX(I)(Z)PF1 | FK1: WHI(I)(Z)PF0.95
A2: t-1 | B2: {=TRANSPOSE(_xlfn._xlws.FILTER(demand!$C$2:$C$167,demand!$D$2:$D$167=1))} -> 28.6 | C2: 6 | D2: 0 | E2: 1.2 | F2: 0 | G2: 14 | H2: 12.4 | I2: 4.7 | J2: 0.9 | K2: 15.4 | L2: 26.7 | M2: 6.1 | N2: 0 | O2: 4.5 | P2: 2 | Q2: 16.6 | R2: 10.4 | S2: 11.5 | T2: 5.3 | U2: 3.8 | V2: 6 | W2: 4.2 | X2: 6.2 | Y2: 1.7 | Z2: 91.2 | AA2: 6 | AB2: 8.3 | AC2: 17.1 | AD2: 16.5 | AE2: 13.8 | AF2: 1.9 | AG2: 4 | AH2: 26.6 | AI2: 12.9 | AJ2: 8.3 | AK2: 9.6 | AL2: 8.4 | AM2: 10.7 | AN2: 15.2 | AO2: 6.4 | AP2: 50.8 | AQ2: 6.6 | AR2: 128.9 | AS2: 90.3 | AT2: 73.2 | AU2: 7.1 | AV2: 0 | AW2: 18.2 | AX2: 15.9 | AY2: 11.8 | AZ2: 8 | BA2: 8.2 | BB2: 10.4 | BC2: 12 | BD2: 19.4 | BE2: 14.1 | BF2: 4.7 | BG2: 0 | BH2: 14.9 | BI2: 4.8 | BJ2: 18.3 | BK2: 3.3 | BL2: 15.1 | BM2: 10.7 | BN2: 10.1 | BO2: 23.9 | BP2: 8.9 | BQ2: 12.9 | BR2: 24.4 | BS2: 24.3 | BT2: 26.4 | BU2: 9.3 | BV2: 22 | BW2: 17.4 | BX2: 9.4 | BY2: 181.2 | BZ2: 5.1 | CA2: 34.1 | CB2: 5.5 | CC2: 11.4 | CD2: 5 | CE2: 8.4 | CF2: 22.5 | CG2: 6.5 | CH2: 22.8 | CI2: 0 | CJ2: 9.7 | CK2: 342.7 | CL2: 20.3 | CM2: 0 | CN2: 15.3 | CO2: 0 | CP2: 9.8 | CQ2: 10.2 | CR2: 18.9 | CS2: 9.4 | CT2: 14.7 | CU2: 5 | CV2: 23.7 | CW2: 0 | CX2: 4.6 | CY2: 12.4 | CZ2: 17.9 | DA2: 7.9 | DB2: 30.1 | DC2: 6.1 | DD2: 9.7 | DE2: 22.9 | DF2: 11.4 | DG2: 10.7 | DH2: 7.1 | DI2: 12.9 | DJ2: 4.6 | DK2: 9.8 | DL2: 21.1 | DM2: 4.5 | DN2: 4.8 | DO2: 10.1 | DP2: 4.7 | DQ2: 0 | DR2: 13.5 | DS2: 0 | DT2: 13.1 | DU2: 21.5 | DV2: 11.1 | DW2: 17.7 | DX2: 13.2 | DY2: 21.4 | DZ2: 8.2 | EA2: 0 | EB2: 0.3 | EC2: 17.3 | ED2: 10.6 | EE2: 18 | EF2: 74 | EG2: 17.6 | EH2: 9.7 | EI2: 14.7 | EJ2: 11.9 | EK2: 9.1 | EL2: 9.6 | EM2: 104.5 | EN2: 7.7 | EO2: 2.3 | EP2: 14 | EQ2: 11.5 | ER2: 16.6 | ES2: 5.5 | ET2: 14.3 | EU2: 3.1 | EV2: 9.5 | EW2: 5.1 | EX2: 13.5 | EY2: 26.9 | EZ2: 1.9 | FA2: 10.6 | FB2: 7.2 | FC2: 5.9 | FD2: 6.1 | FE2: 9.2 | FF2: 15.1 | FG2: 10.9 | FH2: 16.7 | FI2: 28.9 | FJ2: 20.8 | FK2: 9

Sheet ts_VOLL
A1: timestep | B1: AA(I)(Z)PF1 | C1: AGH(N)(Z)PF0.99 | D1: AGN(I)(Z)PF0.95 | E1: AHA(I)(Z)PF0.965 | F1: AIR(N)(Z)PF0.99 | G1: ANR(I)(Z)PF0.95 | H1: ANT(N)(Z)PF0.98 | I1: ARD(I)(Z)PF0.99 | J1: ARI(I)(T)PF0.911 | K1: ARK(I)(Z)PF0.967 | L1: ATH(I)(Z)PF0.995 | M1: ATY(I)(Z)PF0.971 | N1: BAG(I)PF0.95 | O1: BAL(I)(Z)PF0.998 | P1: BAN(I)(Z)PF0.993 | Q1: BAN(I)(Z)PF0.99 | R1: BAN(N)(Z)PF0.958 | S1: BAR(I)(T)PF0.95 | T1: BDA(I)(Z)PF0.982 | U1: BDN(I)(Z)PF0.95 | V1: BDN(I)(Z)PF0.992 | W1: BEG(I)(Z)PF0.992 | X1: BIN(I)(Z)PF0.992 | Y1: BK(I)(Z)PF0.998 | Z1: BLC(I)(Z)PF0.951 | AA1: BLI(I)(Z)PF0.925 | AB1: BLK(I)(Z)PF0.999 | AC1: BMA(N)(Z)PF0.95 | AD1: BNH(N)(Z)PF0.99 | AE1: BNM(N)(Z)PF0.99 | AF1: BOG(I)(Z)PF0.989 | AG1: BRI(I)(Z)PF0.95 | AH1: BRY(I)(Z)PF0.982 | AI1: BUT(I)(Z)PF0.999 | AJ1: CAH(I)(Z)PF1 | AK1: CAR(N)(Z)PF0.99 | AL1: CBG(I)(Z)PF0.996 | AM1: CBR(I)(Z)PF0.984 | AN1: CEN(N)(Z)PF0.99 | AO1: CF(I)(Z)PF0.999 | AP1: CFM(I)(Z)PF0.95 | AQ1: CHA(I)(Z)PF0.999 | AR1: CKM(I)(Z)PF0.998 | AS1: CLE(I)(Z)PF0.95 | AT1: CLG(I)(Z)PF0.95 | AU1: CLN(I)(Z)PF1 | AV1: CLU(I)(Z)PF0.95 | AW1: CLW(I)(Z)PF0.982 | AX1: COL(I)(Z)PF0.993 | AY1: COL(N)(Z)PF0.99 | AZ1: COS(I)(Z)PF1 | BA1: COW(I)(Z)PF1 | BB1: CPS(N)(Z)PF0.99 | BC1: CRA(I)(Z)PF0.999 | BD1: CRE(N)(Z)PF0.99 | BE1: CRG(N)(Z)PF0.99 | BF1: CRO(I)(Z)PF1 | BG1: CVW(I)(Z)PF0.95 | BH1: CVW(I)(Z)PF0.992 | BI1: DAL(I)(T)PF0.993 | BJ1: DDK(I)(Z)PF1 | BK1: DFR(I)(T)PF1 | BL1: DGN(I)(Z)PF1 | BM1: DLT(I)(Z)PF0.999 | BN1: DMY(I)(Z)PF0.983 | BO1: DON(N)(Z)PF0.99 | BP1: DOO(I)(Z)PF1 | BQ1: DRU(I)(Z)PF0.873 | BR1: DRU(N)(Z)PF0.99 | BS1: DRY(I)(Z)PF1 | BT1: DUN(N)(Z)PF0.99 | BU1: EDE(N)(Z)PF0.99 | BV1: ENN(I)(Z)PF0.996 | BW1: ENN(N)(Z)PF0.99 | BX1: FIN(N)(Z)PF0.99 | BY1: FIN(I)(Z)PF0.984 | BZ1: FTT(I)(Z)PF1 | CA1: GAL(I)(Z)PF1 | CB1: GI(I)(Z)PF0.979 | CC1: GIL(I)(Z)PF0.95 | CD1: GLE(I)(Z)PF0.956 | CE1: GLE(N)(Z)PF0.99 | CF1: GRI(I)(T)PF1 | CG1: GWE(I)(Z)PF0.981 | CH1: GWE(I)(Z)PF0.95 | CI1: HN(I)(Z)PF0.95 | CJ1: IKE(I)(T)PF0.996 | CK1: INC(I)(Z)PF0.999 | CL1: KBY(I)(Z)PF1 | CM1: KCY(I)(Z)PF0.95 | CN1: KER(I)(Z)PF0.99 | CO1: KSE(I)(Z)PF0.95 | CP1: KTL(I)(Z)PF0.998 | CQ1: KIN(I)(Z)PF0.95 | CR1: KKY(I)(Z)PF1 | CS1: KLM(I)(Z)PF0.992 | CT1: KNO(N)(Z)PF0.99 | CU1: KTN(I)(Z)PF0.993 | CV1: KUR(I)(Z)PF0.95 | CW1: KYT(I)(Z)PF0.95 | CX1: LA(I)(Z)PF1 | CY1: LAR(N)(Z)PF0.99 | CZ1: LET(I)(Z)PF0.996 | DA1: LIB(I)(Z)PF0.989 | DB1: LIM(I)(Z)PF1 | DC1: LIM(N)(Z)PF0.99 | DD1: LIS(I)(Z)PF0.992 | DE1: LIS(N)(Z)PF0.99 | DF1: LMR(N)(Z)PF0.98 | DG1: LOG(N)(Z)PF0.98 | DH1: MAC(I)(Z)PF0.96 | DI1: MAL(I)(Z)PF0.988 | DJ1: MCE(I)(Z)PF0.95 | DK1: MHL(I)(Z)PF1 | DL1: MID(I)(Z)PF0.99 | DM1: MLN(I)(Z)PF0.95 | DN1: MON(I)(Z)PF0.999 | DO1: MOY(I)(Z)PF1 | DP1: MR(I)(Z)PF0.999 | DQ1: MTA(I)(Z)PF0.95 | DR1: MTH(I)(Z)PF0.984 | DS1: MNH(I)(Z)PF0.95 | DT1: MUL(I)(Z)PF0.998 | DU1: MUN(I)(Z)PF0.95 | DV1: NAR(N)(Z)PF0.99 | DW1: NAV(I)(Z)PF0.969 | DX1: NEW(I)(Z)PF1 | DY1: NEW(N)(Z)PF0.99 | DZ1: NEN(I)(Z)PF0.977 | EA1: OBE(I)(Z)PF0.95 | EB1: OLD(I)(Z)PF0.95 | EC1: OMA(N)(Z)PF0.99 | ED1: OUG(I)(T)PF0.989 | EE1: PLA(I)(Z)PF0.95 | EF1: PB(I)(Z)PF0.989 | EG1: PLS(I)(Z)PF0.996 | EH1: RAT(I)(Z)PF0.997 | EI1: RAT(N)(Z)PF0.99 | EJ1: RIC(I)(Z)PF0.997 | EK1: RNW(I)(Z)PF0.95 | EL1: ROS(N)(Z)PF0.99 | EM1: RYB(I)(Z)PF0.95 | EN1: SCR(I)(Z)PF0.976 | EO1: SHE(I)(Z)PF0.95 | EP1: SAL(I)(Z)PF0.997 | EQ1: SKL(I)(Z)PF0.997 | ER1: SLI(I)(Z)PF1 | ES1: SNG(I)(Z)PF1 | ET1: SBH(I)(Z)PF0.95 | EU1: SOM(I)(T)PF0.998 | EV1: SPR(N)(Z)PF0.99 | EW1: STR(I)(T)PF1 | EX1: STR(N)(Z)PF0.99 | EY1: TBG(I)(Z)PF1 | EZ1: TBK(I)(T)PF0.992 | FA1: THU(I)(Z)PF0.99 | FB1: TIP(I)(Z)PF0.992 | FC1: TLK(I)(Z)PF0.994 | FD1: TON(I)(Z)PF0.987 | FE1: TRI(I)(Z)PF0.962 | FF1: TRL(I)(Z)PF0.997 | FG1: TSB(I)(Z)PF0.996 | FH1: WAR(N)(Z)PF0.99 | FI1: WAT(I)(Z)PF1 | FJ1: WEX(I)(Z)PF1 | FK1: WHI(I)(Z)PF0.95
A2: t-1 | B2: 7000 | C2: 7000 | D2: 7000 | E2: 7000 | F2: 7000 | G2: 7000 | H2: 7000 | I2: 7000 | J2: 7000 | K2: 7000 | L2: 7000 | M2: 7000 | N2: 7000 | O2: 7000 | P2: 7000 | Q2: 7000 | R2: 7000 | S2: 7000 | T2: 7000 | U2: 7000 | V2: 7000 | W2: 7000 | X2: 7000 | Y2: 7000 | Z2: 7000 | AA2: 7000 | AB2: 7000 | AC2: 7000 | AD2: 7000 | AE2: 7000 | AF2: 7000 | AG2: 7000 | AH2: 7000 | AI2: 7000 | AJ2: 7000 | AK2: 7000 | AL2: 7000 | AM2: 7000 | AN2: 7000 | AO2: 7000 | AP2: 7000 | AQ2: 7000 | AR2: 7000 | AS2: 7000 | AT2: 7000 | AU2: 7000 | AV2: 7000 | AW2: 7000 | AX2: 7000 | AY2: 7000 | AZ2: 7000 | BA2: 7000 | BB2: 7000 | BC2: 7000 | BD2: 7000 | BE2: 7000 | BF2: 7000 | BG2: 7000 | BH2: 7000 | BI2: 7000 | BJ2: 7000 | BK2: 7000 | BL2: 7000 | BM2: 7000 | BN2: 7000 | BO2: 7000 | BP2: 7000 | BQ2: 7000 | BR2: 7000 | BS2: 7000 | BT2: 7000 | BU2: 7000 | BV2: 7000 | BW2: 7000 | BX2: 7000 | BY2: 7000 | BZ2: 7000 | CA2: 7000 | CB2: 7000 | CC2: 7000 | CD2: 7000 | CE2: 7000 | CF2: 7000 | CG2: 7000 | CH2: 7000 | CI2: 7000 | CJ2: 7000 | CK2: 7000 | CL2: 7000 | CM2: 7000 | CN2: 7000 | CO2: 7000 | CP2: 7000 | CQ2: 7000 | CR2: 7000 | CS2: 7000 | CT2: 7000 | CU2: 7000 | CV2: 7000 | CW2: 7000 | CX2: 7000 | CY2: 7000 | CZ2: 7000 | DA2: 7000 | DB2: 7000 | DC2: 7000 | DD2: 7000 | DE2: 7000 | DF2: 7000 | DG2: 7000 | DH2: 7000 | DI2: 7000 | DJ2: 7000 | DK2: 7000 | DL2: 7000 | DM2: 7000 | DN2: 7000 | DO2: 7000 | DP2: 7000 | DQ2: 7000 | DR2: 7000 | DS2: 7000 | DT2: 7000 | DU2: 7000 | DV2: 7000 | DW2: 7000 | DX2: 7000 | DY2: 7000 | DZ2: 7000 | EA2: 7000 | EB2: 7000 | EC2: 7000 | ED2: 7000 | EE2: 7000 | EF2: 7000 | EG2: 7000 | EH2: 7000 | EI2: 7000 | EJ2: 7000 | EK2: 7000 | EL2: 7000 | EM2: 7000 | EN2: 7000 | EO2: 7000 | EP2: 7000 | EQ2: 7000 | ER2: 7000 | ES2: 7000 | ET2: 7000 | EU2: 7000 | EV2: 7000 | EW2: 7000 | EX2: 7000 | EY2: 7000 | EZ2: 7000 | FA2: 7000 | FB2: 7000 | FC2: 7000 | FD2: 7000 | FE2: 7000 | FF2: 7000 | FG2: 7000 | FH2: 7000 | FI2: 7000 | FJ2: 7000 | FK2: 7000

Sheet branch
A1: name | B1: from_busname | C1: to_busname | D1: stat | E1: r | F1: x | G1: b | H1: ShortTermRating | I1: ContinousRating
A2: AA(I)(Z)>DRU(I)(Z)_110L1 | B2: AA_I_Z_110 | C2: DRU_I_Z_110 | D2: 1 | E2: 0.027 | F2: 0.063 | G2: 0.006 | H2: =I2*1.25 -> 123.75 | I2: 99
A3: AA(I)(Z)>ENN(I)(Z)_110L1 | B3: AA_I_Z_110 | C3: ENN_I_Z_110 | D3: 1 | E3: 0.048 | F3: 0.111 | G3: 0.012 | H3: =I3*1.25 -> 123.75 | I3: 99
A4: AA(I)(Z)>LIM(I)(Z)_110L1 | B4: AA_I_Z_110 | C4: LIM_I_Z_110 | D4: 1 | E4: 0.007 | F4: 0.037 | G4: 0.012 | H4: =I4*1.25 -> 222.5 | I4: 178
A5: AA1(I)(Z)>SNG(I)(Z)_110L1 | B5: AA1_I_Z_110 | C5: SNG_I_Z_110 | D5: 1 | E5: 0.003 | F5: 0.017 | G5: 0.007 | H5: =I5*1.25 -> 181.25 | I5: 145
A6: AD(I)(Z)>AD(I)(Z)_220L1 | B6: AD_I_Z_220 | C6: AD_I_Z_220 | D6: 0 | E6: 0 | F6: 0.001 | G6: 0.038 | H6: =I6*1.25 -> 741.25 | I6: 593
A7: AD(I)(Z)>GGO(I)(Z)_220L1 | B7: AD_I_Z_220 | C7: GGO_I_Z_220 | D7: 1 | E7: 0 | F7: 0.002 | G7: 0.104 | H7: =I7*1.25 -> 670 | I7: 536
A8: AD(I)(Z)>KRA(I)(Z)_220L1 | B8: AD_I_Z_220 | C8: KRA_I_Z_220 | D8: 1 | E8: 0.003 | F8: 0.022 | G8: 0.034 | H8: =I8*1.25 -> 491.25 | I8: 393
A9: AD(I)(Z)>KRA(I)(Z)_220L2 | B9: AD_I_Z_220 | C9: KRA_I_Z_220 | D9: 1 | E9: 0.003 | F9: 0.022 | G9: 0.034 | H9: =I9*1.25 -> 491.25 | I9: 393
A10: AD(I)(Z)>LPT(I)(Z)_220L1 | B10: AD_I_Z_220 | C10: LPT_I_Z_220 | D10: 1 | E10: 0 | F10: 0.001 | G10: 0.0265 | H10: =I10*1.25 -> 741.25 | I10: 593
A11: AD(I)(Z)>RAF(I)(Z)_220L1 | B11: AD_I_Z_220 | C11: RAF_I_Z_220 | D11: 1 | E11: 0.001 | F11: 0.009 | G11: 0.252 | H11: =I11*1.25 -> 542.5 | I11: 434
A12: AD(I)(Z)>WHI(I)(Z)_110L1 | B12: AD_I_Z_110 | C12: WHI_I_Z_110 | D12: 1 | E12: 0.005 | F12: 0.011 | G12: 0.001 | H12: =I12*1.25 -> 123.75 | I12: 99
A13: ADM(I)(Z)>GCA(I)(Z)_110L1 | B13: ADM_I_Z_110 | C13: GCA_I_Z_110 | D13: 1 | E13: 0.002 | F13: 0.004 | G13: 0.025 | H13: =I13*1.25 -> 175 | I13: 140
A14: ADM(I)(Z)>INC(I)(Z)_110L1 | B14: ADM_I_Z_110 | C14: INC_I_Z_110 | D14: 1 | E14: 0.009 | F14: 0.027 | G14: 0.024 | H14: =I14*1.25 -> 128.75 | I14: 103
A15: AGH(N)(Z)>ENN(N)(Z)_110L1 | B15: AGH_N_Z_110 | C15: ENN_N_Z_110 | D15: 1 | E15: 0.039 | F15: 0.095 | G15: 0.019 | H15: =I15*1.25 -> 136.25 | I15: 109
A16: AGL(I)(Z)>DYN(I)(Z)_110L1 | B16: AGL_I_Z_110 | C16: DYN_I_Z_110 | D16: 1 | E16: 0.012 | F16: 0.028 | G16: 0.003 | H16: =I16*1.25 -> 131.25 | I16: 105
A17: AGL(I)(Z)>ENN(I)(Z)_110L1 | B17: AGL_I_Z_110 | C17: ENN_I_Z_110 | D17: 1 | E17: 0.059 | F17: 0.131 | G17: 0.012 | H17: =I17*1.25 -> 123.75 | I17: 99
A18: AGN(I)(Z)>CBT(I)(Z)_110L1 | B18: AGN_I_Z_110 | C18: CBT_I_Z_110 | D18: 1 | E18: 1e-05 | F18: 1e-05 | G18: 0.002 | H18: =I18*1.25 -> 233.75 | I18: 187
A19: AGN(I)(Z)>CBT(I)(Z)_110L2 | B19: AGN_I_Z_110 | C19: CBT_I_Z_110 | D19: 1 | E19: 1e-05 | F19: 1e-05 | G19: 0.002 | H19: =I19*1.25 -> 233.75 | I19: 187
A20: AGN(I)(Z)>KSE(I)(Z)_110L1 | B20: AGN_I_Z_110 | C20: KSE_I_Z_110 | D20: 1 | E20: 1e-05 | F20: 0.002 | G20: 0.019 | H20: =I20*1.25 -> 233.75 | I20: 187
A21: AGL(I)(Z)>SH(I)(Z)_110L1 | B21: AGL_I_Z_110 | C21: SH_I_Z_110 | D21: 1 | E21: 0.068 | F21: 0.157 | G21: 0.017 | H21: =I21*1.25 -> 130 | I21: 104
A22: AHA(I)(Z)>KLN(I)(Z)_110L1 | B22: AHA_I_Z_110 | C22: KLN_I_Z_110 | D22: 1 | E22: 0.004 | F22: 0.012 | G22: 0.004 | H22: =I22*1.25 -> 140 | I22: 112
A23: ANR(I)(Z)>DOO(I)(Z)_110L1 | B23: ANR_I_Z_110 | C23: DOO_I_Z_110 | D23: 1 | E23: 0.003 | F23: 0.007 | G23: 0.001 | H23: =I23*1.25 -> 131.25 | I23: 105
A24: ANT(N)(Z)>KEL(N)(Z)_110L1 | B24: ANT_N_Z_110 | C24: KEL_N_Z_110 | D24: 1 | E24: 0.012 | F24: 0.03 | G24: 0.003 | H24: =I24*1.25 -> 102.5 | I24: 82
A25: ANT(N)(Z)>KEL(N)(Z)_110L2 | B25: ANT_N_Z_110 | C25: KEL_N_Z_110 | D25: 1 | E25: 0.012 | F25: 0.03 | G25: 0.003 | H25: =I25*1.25 -> 102.5 | I25: 82
A26: ARD(I)(Z)>TIV(I)(Z)_110L1 | B26: ARD_I_Z_110 | C26: TIV_I_Z_110 | D26: 1 | E26: 0.054 | F26: 0.12 | G26: 0.011 | H26: =I26*1.25 -> 131.25 | I26: 105
A27: ARI(I)(Z)>ARI(I)(T)_110L1 | B27: ARI_I_Z_110 | C27: ARI_I_T_110 | D27: 1 | E27: 0 | F27: 0.001 | G27: 0 | H27: =I27*1.25 -> 131.25 | I27: 105
A28: ARK(I)(Z)>BEG(I)(Z)_110L1 | B28: ARK_I_Z_110 | C28: BEG_I_Z_110 | D28: 1 | E28: 0.01 | F28: 0.079 | G28: 0.007 | H28: =I28*1.25 -> 123.75 | I28: 99
A29: ARK(I)(Z)>BOG(I)(Z)_110L1 | B29: ARK_I_Z_110 | C29: BOG_I_Z_110 | D29: 1 | E29: 0.021 | F29: 0.095 | G29: 0.01 | H29: =I29*1.25 -> 222.5 | I29: 178
A30: ARK(I)(Z)>CKM(I)(Z)_220L1 | B30: ARK_I_Z_220 | C30: CKM_I_Z_220 | D30: 1 | E30: 0.006 | F30: 0.046 | G30: 0.081 | H30: =I30*1.25 -> 542.5 | I30: 434
A31: ARK(I)(Z)>LOD(I)(Z)_220L1 | B31: ARK_I_Z_220 | C31: LWD_I_Z_220 | D31: 1 | E31: 0.005 | F31: 0.034 | G31: 0.051 | H31: =I31*1.25 -> 542.5 | I31: 434
A32: ARK(I)(Z)>SHE(I)(Z)_110L1 | B32: ARK_I_Z_110 | C32: SHE_I_Z_110 | D32: 1 | E32: 0.004 | F32: 0.008 | G32: 0.001 | H32: =I32*1.25 -> 42.5 | I32: 34
... A46: ATY(I)(Z)>CLW(I)(Z)_110L1 | B46: ATY_I_Z_110 | C46: CLW_I_Z_110 | D46: 1 | E46: 0.036 | F46: 0.083 | G46: 0.008 | H46: =I46*1.25 -> 123.75 | I46: 99
A47: ATY(I)(Z)>CNB(I)(Z)_110L1 | B47: ATY_I_Z_110 | C47: CNB_I_Z_110 | D47: 1 | E47: 0.034 | F47: 0.076 | G47: 0.007 | H47: =I47*1.25 -> 131.25 | I47: 105
A48: ATY(I)(Z)>PLS(I)(Z)_110L1 | B48: ATY_I_Z_110 | C48: PLS_I_Z_110 | D48: 1 | E48: 0.038 | F48: 0.088 | G48: 0.008 | H48: =I48*1.25 -> 123.75 | I48: 99
A49: AUG(I)(Z)>CFM(I)(Z)_110L1 | B49: AUG_I_Z_110 | C49: CFM_I_Z_110 | D49: 1 | E49: 0.001 | F49: 0.002 | G49: 0.001 | H49: =I49*1.25 -> 120 | I49: 96
A50: AUG(I)(Z)>CFM(I)(Z)_110L2 | B50: AUG_I_Z_110 | C50: CFM_I_Z_110 | D50: 1 | E50: 0.001 | F50: 0.002 | G50: 0.001 | H50: =I50*1.25 -> 120 | I50: 96
A51: AUG(I)(Z)>KPG(I)(Z)_110L1 | B51: AUG_I_Z_110 | C51: KPG_I_Z_110 | D51: 1 | E51: 0.021 | F51: 0.107 | G51: 0.012 | H51: =I51*1.25 -> 222.5 | I51: 178
A52: AUG(I)(Z)>MTN(I)(Z)_110L1 | B52: AUG_I_Z_110 | C52: MTN_I_Z_110 | D52: 1 | E52: 0.017 | F52: 0.089 | G52: 0.01 | H52: =I52*1.25 -> 222.5 | I52: 178
A53: AUG(I)(Z)>SK(I)(Z)_110L1 | B53: AUG_I_Z_110 | C53: SK_I_Z_110 | D53: 1 | E53: 0.001 | F53: 0.001 | G53: 0.006 | H53: =I53*1.25 -> 150 | I53: 120
...

Sheet ts_Lmax
A1: timestep | B1: {=TRANSPOSE(_xlfn._xlws.FILTER(branch!$A$2:$A$591,branch!$D$2:$D$591<>0))} -> AA(I)(Z)>DRU(I)(Z)_110L1 | C1: AA(I)(Z)>ENN(I)(Z)_110L1 | D1: AA(I)(Z)>LIM(I)(Z)_110L1 | E1: AA1(I)(Z)>SNG(I)(Z)_110L1 | F1: AD(I)(Z)>GGO(I)(Z)_220L1 | G1: AD(I)(Z)>KRA(I)(Z)_220L1 | H1: AD(I)(Z)>KRA(I)(Z)_220L2 | I1: AD(I)(Z)>LPT(I)(Z)_220L1 | J1: AD(I)(Z)>RAF(I)(Z)_220L1 | K1: AD(I)(Z)>WHI(I)(Z)_110L1 | L1: ADM(I)(Z)>GCA(I)(Z)_110L1 | M1: ADM(I)(Z)>INC(I)(Z)_110L1 | N1: AGH(N)(Z)>ENN(N)(Z)_110L1 | O1: AGL(I)(Z)>DYN(I)(Z)_110L1 | P1: AGL(I)(Z)>ENN(I)(Z)_110L1 | Q1: AGN(I)(Z)>CBT(I)(Z)_110L1 | R1: AGN(I)(Z)>CBT(I)(Z)_110L2 | S1: AGN(I)(Z)>KSE(I)(Z)_110L1 | T1: AGL(I)(Z)>SH(I)(Z)_110L1 | U1: AHA(I)(Z)>KLN(I)(Z)_110L1 | V1: ANR(I)(Z)>DOO(I)(Z)_110L1 | W1: ANT(N)(Z)>KEL(N)(Z)_110L1 | X1: ANT(N)(Z)>KEL(N)(Z)_110L2 | Y1: ARD(I)(Z)>TIV(I)(Z)_110L1 | Z1: ARI(I)(Z)>ARI(I)(T)_110L1 | AA1: ARK(I)(Z)>BEG(I)(Z)_110L1 | AB1: ARK(I)(Z)>BOG(I)(Z)_110L1 | AC1: ARK(I)(Z)>CKM(I)(Z)_220L1 | AD1: ARK(I)(Z)>LOD(I)(Z)_220L1 | AE1: ARK(I)(Z)>SHE(I)(Z)_110L1 | AF1: ART(I)(Z)>FIN(I)(Z)_110L1 | AG1: ART(I)(Z)>MCD(I)(Z)_110L1 | AH1: ARV(I)(Z)>COS(I)(Z)_110L1 | AI1: ARV(I)(Z)>GWE(I)(Z)_110L1 | AJ1: ARV(I)(Z)>NAV(I)(Z)_110L1 | AK1: ARV(I)(Z)>SKL(I)(Z)_110L1 | AL1: ARV(I)(Z)>SKL(I)(Z)_110L2 | AM1: ATE(I)(Z)>DRO(I)(Z)_110L1 | AN1: ATE(I)(Z)>KNR(I)(Z)_110L1 | AO1: ATH(I)(Z)>LA(I)(Z)_110L1 | AP1: ATH(I)(Z)>SH(I)(Z)_110L1 | AQ1: ATN(I)(Z)>INC(I)(Z)_110L1 | AR1: ATN(I)(Z)>INC(I)(Z)_110L2 | AS1: ATY(I)(Z)>CLW(I)(Z)_110L1 | AT1: ATY(I)(Z)>CNB(I)(Z)_110L1 | AU1: ATY(I)(Z)>PLS(I)(Z)_110L1 | AV1: AUG(I)(Z)>CFM(I)(Z)_110L1 | AW1: AUG(I)(Z)>CFM(I)(Z)_110L2 | AX1: AUG(I)(Z)>KPG(I)(Z)_110L1 | AY1: AUG(I)(Z)>MTN(I)(Z)_110L1 | AZ1: AUG(I)(Z)>SK(I)(Z)_110L1 | BA1: AUG(I)(Z)>SK(I)(Z)_110L2 | BB1: BAL(I)(Z)>CDU(I)(Z)_110L1 | BC1: BAL(I)(Z)>DRY(I)(Z)_110L1 | BD1: BAL(I)(Z)>DEE(I)(Z)_110L1 | BE1: BAN(I)(Z)>BRI(I)(Z)_110L1 | BF1: BAN(I)(Z)>BRI(I)(Z)_110L2 | BG1: BAN(I)(Z)>DMY(I)(Z)_110L1 | BH1: BAN(I)(Z)>RAF(I)(Z)_110L1 | BI1: BAN(N)(Z)>TAN(N)(Z)_110L1 | BJ1: BAN(N)(Z)>TAN(N)(Z)_110L2 | BK1: BAR(I)(Z)>BAR(I)(T)_110L1 | BL1: BCT(I)(Z)>CKM(I)(Z)_110L1 | BM1: BCT(I)(Z)>COO(I)(Z)_110L1 | BN1: BDA(I)(Z)>MON(I)(Z)_110L1 | BO1: BDA(I)(Z)>NEW(I)(Z)_110L1 | BP1: BDN(I)(Z)>CUL(I)(Z)_110L1 | BQ1: BDN(I)(Z)>DOO(I)(Z)_110L1 | BR1: BEG(I)(Z)>CKM(I)(Z)_110L1 | BS1: BGH(I)(Z)>CLA(I)(Z)_110L1 | BT1: BGN(I)(Z)>MLC(I)(Z)_110L1 | BU1: BGT(I)(Z)>CNB(I)(Z)_110L1 | BV1: BGT(I)(Z)>GGT(I)(Z)_110L1 | BW1: BGT(I)(Z)>KKY(I)(Z)_110L1 | BX1: BIN(I)(Z)>CF(I)(Z)_110L1 | BY1: BIN(I)(Z)>TIV(I)(Z)_110L1 | BZ1: BK(I)(Z)>CBR(I)(Z)_110L1 | CA1: BK(I)(Z)>CGW(I)(Z)_110L1 | CB1: BK(I)(Z)>MOY(I)(Z)_110L1 | CC1: BK(I)(Z)>SKY(I)(Z)_110L1 | CD1: BK(I)(Z)>SKY(I)(Z)_110L2 | CE1: BKT(I)(Z)>CUR(I)(Z)_110L1 | CF1: BKY(I)(Z)>CBT(I)(Z)_110L1 | CG1: BKY(I)(Z)>CBT(I)(Z)_110L2 | CH1: BKY(I)(Z)>KCY(I)(Z)_110 | CI1: BLA(I)(Z)>POT(I)(Z)_110L1 | CJ1: BLA(I)(Z)>RE(I)(Z)_110L1 | CK1: BLC(I)(Z)>FIN(I)(Z)_220L1 | CL1: BLC(I)(Z)>SHL(I)(Z)_220L1 | CM1: BLC(I)(Z)>GRA(I)(Z)_110L1 | CN1: BLC(I)(Z)>KLM(I)(Z)_110L1 | CO1: BLC(I)(Z)>MNH(I)(Z)_110L1 | CP1: BLI(I)(Z)>DMY(I)(Z)_110L1 | CQ1: BMA(N)(Z)>KEL(N)(Z)_110L1 | CR1: BMA(N)(Z)>KEL(N)(Z)_110L2 | CS1: BNH(N)(Z)>CAS(N)(Z)_110L1 | CT1: BNH(N)(Z)>CAS(N)(Z)_110L2 | CU1: BNM(N)(Z)>DON(N)(Z)_110L1 | CV1: BNM(N)(Z)>DON(N)(Z)_110L2 | CW1: BOG(I)(Z)>TTU(I)(Z)_110L1 | CX1: TTU(I)(Z)>CRA(I)(Z)_110L1 | CY1: BOL(I)(Z)>ENN(I)(Z)_110L1 | CZ1: BOL(I)(Z)>TBK(I)(T)_110L1 | DA1: BPS(N)(Z)>BVG(N)(Z)_110L1 | DB1: BPS(N)(Z)>BVG(N)(Z)_110L2 | DC1: BPS(N)(Z)>BYC(N)(Z)_275L1 | DD1: BPS(N)(Z)>EDE(N)(Z)_110L1 | DE1: BPS(N)(Z)>EDE(N)(Z)_110L2 | DF1: BPS(N)(Z)>HAN(N)(Z)_275L1 | DG1: BPS(N)(Z)>KEL(N)(Z)_275L1 | DH1: BPS(N)(Z)>MAG(N)(Z)_275L1 | DI1: BRO(N)(Z)>RSK(N)(Z)_110L1 | DJ1: BRY(I)(Z)>RAF(I)(Z)_110L1 | DK1: BRY(I)(Z)>RAF(I)(Z)_110L2 | DL1: BTN(I)(Z)>CLE(I)(Z)_220L1 | DM1: BTN(I)(Z)>CLE(I)(Z)_220L2 | DN1: BUT(I)(Z)>CUL(I)(Z)_110L1 | DO1: BUT(I)(Z)>KTN(I)(Z)_110L1 | DP1: BVG(N)(Z)>KEL(N)(Z)_110L1 | DQ1: BVG(N)(Z)>KEL(N)(Z)_110L2 | DR1: BVG(N)(Z)>LAR(N)(Z)_110L1 | DS1: BVG(N)(Z)>LAR(N)(Z)_110L2 | DT1: BVK(I)(Z)>BYH(I)(Z)_220L1 | DU1: BVK(I)(Z)>CLA(I)(Z)_220L1 | DV1: BVK(I)(Z)>CTG(I)(Z)_110L1 | DW1: BWR(I)(Z)>CRA(I)(Z)_110L1 | DX1: BYH(I)(Z)>CDL(I)(Z)_110L1 | DY1: BYH(I)(Z)>GLE(I)(Z)_110L1 | DZ1: CAB(I)(Z)>PTN(I)(Z)_110L1 | EA1: CAB(I)(Z)>WOL(I)(Z)_110L1 | EB1: CAH(I)(Z)>BAR(I)(T)_110L1 | EC1: CAH(I)(Z)>DOO(I)(Z)_110L1 | ED1: CAH(I)(Z)>KHL(I)(Z)_110L1 | EE1: CAH(I)(Z)>TIP(I)(Z)_110L1 | EF1: CAR(N)(Z)>CAS(N)(Z)_110L1 | EG1: CAR(N)(Z)>CAS(N)(Z)_110L2 | EH1: CAR(N)(Z)>EDE(N)(Z)_110L1 | EI1: CAR(N)(Z)>EDE(N)(Z)_110L2 | EJ1: CAS(N)(Z)>CRE(N)(Z)_110L1 | EK1: CAS(N)(Z)>CRE(N)(Z)_110L2 | EL1: CAS(N)(Z)>HAN(N)(Z)_275L1 | EM1: CAS(N)(Z)>HAN(N)(Z)_275L2 | EN1: CAS(N)(Z)>KNO(N)(Z)_110L1 | EO1: CAS(N)(Z)>KNO(N)(Z)_110L2 | EP1: CAS(N)(Z)>KPS(N)(Z)_275L1 | EQ1: CAS(N)(Z)>NAR(N)(Z)_110L1 | ER1: CAS(N)(Z)>NAR(N)(Z)_110L2 | ES1: CAS(N)(Z)>RAT(N)(Z)_110L1 | ET1: CAS(N)(Z)>RAT(N)(Z)_110L2 | EU1: CAS(N)(Z)>ROS(N)(Z)_110L1 | EV1: CAS(N)(Z)>ROS(N)(Z)_110L2 | EW1: CAS(N)(Z)>TAN(N)(Z)_275L1 | EX1: CTN(I)(Z)>KLN(I)(Z)_110L1 | EY1: CBL(I)(Z)>TRI(I)(Z)_110L1 | EZ1: CBG(I)(Z)>CBR(I)(Z)_110L1 | FA1: CBR(I)(Z)>CLN(I)(Z)_110L1 | FB1: CBR(I)(Z)>DLT(I)(Z)_110L1 | FC1: CBT(I)(Z)>INC(I)(Z)_220L1 | FD1: CBT(I)(Z)>KCY(I)(Z)_110L1 | FE1: CBT(I)(Z)>INC(I)(Z)_220L2 | FF1: CBT(I)(Z)>MAY(I)(Z)_220L1 | FG1: CBT(I)(Z)>MAY(I)(Z)_220L2 | FH1: CD(I)(Z)>KBY(I)(Z)_110L1 | FI1: CD(I)(Z)>MAC(I)(Z)_110L1 | FJ1: CDK(I)(Z)>LWD(I)(Z)_110L1 | FK1: CDU(I)(Z)>FIN(I)(Z)_220L1 | FL1: CDU(I)(Z)>FIN(I)(Z)_220L2 | FM1: CDU(I)(Z)>HN(I)(Z)_220L1 | FN1: CDU(I)(Z)>BLU(I)(Z)_110L1 | FO1: CDU(I)(Z)>GLN(I)(Z)_110L1 | FP1: BLU(I)(Z)>MUL(I)(Z)_110L1 | FQ1: CDU(I)(Z)>PLA(I)(Z)_110L1 | FR1: CDU(I)(Z)>RYB(I)(Z)_110L1 | FS1: CDU(I)(Z)>SBH(I)(Z)_110L1 | FT1: CDU(I)(Z)>WOO(I)(Z)_220L1 | FU1: CDY(I)(Z)>ARI(I)(T)_110L1 | FV1: CDY(I)(Z)>GRV(I)(Z)_110L1 | FW1: CDY(I)(Z)>SRA(I)(Z)_110L1 | FX1: CEN(N)(Z)>CRE(N)(Z)_110L1 | FY1: CEN(N)(Z)>CRE(N)(Z)_110L2 | FZ1: CF(I)(Z)>CAD(Y)(Z)_110L1 | GA1: CF(I)(Z)>CKL(Y)(Z)_110L1 | GB1: CF(I)(Z)>CL(I)(Z)_110L1 | GC1: CF(I)(Z)>CLO(I)(Z)_110L1 | GD1: CF(I)(Z)>CLO(I)(Z)_110L2 | GE1: CF(I)(Z)>COR(I)(Z)_110L1 | GF1: CF(I)(Z)>SRA(I)(Z)_110L1 | GG1: CF(I)(Z)>SRA(I)(Z)_110L2 | GH1: CFD(I)(Z)>MUL(I)(Z)_110L1 | GI1: CFD(I)(Z)>KIN(I)(Z)_110L1 | GJ1: CGL(I)(Z)>GAE(I)(Z)_110L1 | GK1: CHA(I)(Z)>GLE(I)(Z)_110L1 | GL1: CHA(I)(Z)>KLN(I)(Z)_110L1 | GM1: CHA(I)(Z)>MAL(I)(Z)_110L1 | GN1: CHE(I)(Z)>FAS(I)(Z)_110L1 | GO1: CKG(I)(Z)>CBT(I)(Z)_110L1 | GP1: CKG(I)(Z)>CBT(I)(Z)_110L2 | GQ1: CKG(I)(Z)>KUD(I)(Z)_110L1 | GR1: CKM(I)(Z)>CHE(I)(Z)_110L1 | GS1: CKM(I)(Z)>COO(I)(Z)_110L1 | GT1: CKM(I)(Z)>DSN(I)(Z)_220L1 | GU1: CKM(I)(Z)>FAS(I)(Z)_110L1 | GV1: CKM(I)(Z)>FAS(I)(Z)_110L2 | GW1: CKM(I)(Z)>ISH(I)(Z)_220L1 | GX1: CKM(I)(Z)>POT(I)(Z)_110L1 | GY1: CKN(I)(Z)>CGL(I)(Z)_110L1 | GZ1: CKN(I)(Z)>GRO(I)(Z)_110L1 | HA1: CKN(I)(Z)>KER(I)(Z)_110L1 | HB1: CLA(I)(Z)>CKN(I)(Z)_110L1 | HC1: CLA(I)(Z)>DMY(I)(Z)_110L1 | HD1: CLA(I)(Z)>KRA(I)(Z)_220L1 | HE1: CLA(I)(Z)>MAC(I)(Z)_110L1 | HF1: CLA(I)(Z)>MAC(I)(Z)_110L2 | HG1: CLE(I)(Z)>CDU(I)(Z)_220L1 | HH1: CLE(I)(Z)>WOO(I)(Z)_220L1 | HI1: CLG(I)(Z)>CDU(I)(Z)_110L1 | HJ1: CLG(I)(Z)>FIN(I)(Z)_110L1 | HK1: CLH(I)(Z)>TRI(I)(Z)_110L1 | HL1: CLH(I)(Z)>TRL(I)(Z)_110L1 | HM1: CLN(I)(Z)>LA(I)(Z)_110L1 | HN1: CLO(I)(Z)>CF(I)(Z)_110L1 | HO1: CLO(I)(Z)>GOL(I)(T)_110L1 | HP1: CLO(I)(Z)>MRY(I)(Z)_110L1 | HQ1: CLU(I)(Z)>CBT(I)(Z)_110L1 | HR1: CLU(I)(Z)>KUD(I)(Z)_110L1 | HS1: CLW(I)(Z)>KLS(I)(Z)_110L1 | HT1: CLW(I)(Z)>KLS(I)(Z)_110L2 | HU1: CLW(I)(Z)>STR(I)(T)_110L1 | HV1: CNB(I)(Z)>GGT(I)(T)_110L1 | HW1: CNB(I)(Z)>PLS(I)(T)_110L1 | HX1: CNB(I)(Z)>MP(I)(T)_380L1 | HY1: CNB(I)(Z)>DSN(I)(T)_380L1 | HZ1: COL(I)(Z)>CDU(I)(Z)_110L1 | IA1: COL(I)(Z)>FIN(I)(Z)_110L1 | IB1: COL(N)(Z)>CPS(N)(Z)_110L1 | IC1: COL(N)(Z)>LIM(N)(Z)_110L1 | ID1: COL(N)(Z)>LOG(N)(Z)_110L1 | IE1: COL(N)(Z)>LOG(N)(Z)_110L2 | IF1: COL(N)(Z)>RSK(N)(Z)_110L1 | IG1: COO(I)(Z)>FTT(I)(Z)_110L1 | IH1: COO(I)(Z)>INC(I)(Z)_110L1 | II1: COR(I)(Z)>ENN(N)(Z)_110L1 | IJ1: COR(I)(Z)>GWE(I)(Z)_110L1 | IK1: COS(I)(Z)>ARI(I)(T)_110L1 | IL1: COS(I)(Z)>FLA(I)(Z)_110L1 | IM1: COS(I)(Z)>FLA(I)(Z)_110L2 | IN1: COW(I)(Z)>OLD(I)(Z)_110L1 | IO1: COW(I)(Z)>OLD(I)(Z)_110L2 | IP1: COW(I)(Z)>RAF(I)(Z)_110L1 | IQ1: COW(I)(Z)>WHI(I)(Z)_110L1 | IR1: CPK(I)(Z)>CKM(I)(Z)_110L1 | IS1: CPK(I)(Z)>TNY(I)(Z)_110L1 | IT1: CPS(N)(Z)>CRD(N)(Z)_110L1 | IU1: CPS(N)(Z)>KMT(N)(Z)_110L1 | IV1: CPS(N)(Z)>LIM(N)(Z)_110L1 | IW1: CPS(N)(Z)>LMR(N)(Z)_110L1 | IX1: CPS(N)(Z)>LMR(N)(Z)_110L2 | IY1: CPS(N)(Z)>MAG(N)(Z)_275L1 | IZ1: CPS(N)(Z)>MAG(N)(Z)_275L2 | JA1: CPS(N)(Z)>SPR(N)(Z)_110L1 | JB1: CPS(N)(Z)>SPR(N)(Z)_110L2 | JC1: CPS(N)(Z)>STR(N)(Z)_110L1 | JD1: CRA(I)(Z)>LWD(I)(Z)_110L1 | JE1: CRA(I)(Z)>WEX(I)(Z)_110L1 | JF1: CRG(N)(Z)>KEL(N)(Z)_110L1 | JG1: CRG(N)(Z)>TMN(N)(Z)_110L1 | JH1: CRM(I)(Z)>KLM(I)(Z)_110L1 | JI1: CRM(I)(Z)>KLM(I)(Z)_110L2 | JJ1: CRO(I)(Z)>IA(I)(Z)_110L1 | JK1: CRO(I)(Z)>KBY(I)(Z)_110L1 | JL1: CSH(I)(Z)>CLN(I)(Z)_110L1 | JM1: CSH(I)(Z)>DLT(I)(Z)_110L1 | JN1: CSH(I)(Z)>ENN(I)(Z)_110L1 | JO1: CSH(I)(Z)>FLA(I)(Z)_220L1 | JP1: CSH(I)(Z)>GAL(I)(Z)_110L1 | JQ1: CSH(I)(Z)>GAL(I)(Z)_110L2 | JR1: CSH(I)(Z)>GAL(I)(Z)_110L3 | JS1: CSH(I)(Z)>PRO(I)(Z)_220L1 | JT1: CSH(I)(Z)>SAL(I)(Z)_110L1 | JU1: CSH(I)(Z)>SOM(I)(T)_110L1 | JV1: CSH(I)(Z)>TYN(I)(Z)_220L1 | JW1: CTN(I)(Z)>TIP(I)(Z)_110L1 | JX1: CTY(I)(Z)>FTT(I)(Z)_110L1 | JY1: CTY(I)(Z)>INC(I)(Z)_110L1 | JZ1: CUL(I)(Z)>DGN(I)(Z)_110L1 | KA1: CUL(I)(Z)>GI(I)(Z)_220L1 | KB1: CUL(I)(Z)>KRA(I)(Z)_220L1 | KC1: CUL(I)(Z)>WAT(I)(Z)_110L1 | KD1: CUL(I)(Z)>RTO(I)(Z)_110L1 | KE1: CUN(I)(Z)>GLR(I)(Z)_110L1 | KF1: CUN(I)(Z)>SLI(I)(Z)_110L1 | KG1: CUR(I)(Z)>BKM(I)(Z)_110L1 | KH1: CUR(I)(Z)>NEN(I)(Z)_110L1 | KI1: CUS(I)(Z)>MLC(I)(Z)_110L1 | KJ1: CUS(I)(Z)>NEW(I)(Z)_110L1 | KK1: CUS(I)(Z)>PLS(I)(Z)_110L1 | KL1: CUS(I)(Z)>PPT(I)(Z)_110L1 | KM1: CVW(I)(Z)>COW(I)(Z)_110L1 | KN1: CVW(I)(Z)>DKL(I)(Z)_110L1 | KO1: CVW(I)(Z)>KRA(I)(Z)_110L1 | KP1: DAL(I)(Z)>DAL(I)(T)_110L1 | KQ1: DDK(I)(Z)>LOU(I)(Z)_110L1 | KR1: DDK(I)(Z)>MLN(I)(Z)_110L1 | KS1: DER(I)(Z)>KIN(I)(Z)_110L1 | KT1: DER(I)(Z)>TEN(I)(Z)_110L1 | KU1: TEN(I)(Z)>MAY(I)(Z)_110L1 | KV1: DER(I)(Z)>TSB(I)(Z)_110L1 | KW1: DEY(I)(Z)>DAL(I)(T)_110L1 | KX1: DEY(I)(Z)>PLS(I)(Z)_110L1 | KY1: DFR(I)(T)>DFR(I)(Z)_110L1 | KZ1: DFR(I)(Z)>MGT(I)(Z)_110L1 | LA1: DGN(I)(Z)>WHE(I)(Z)_110L1 | LB1: DGN(I)(Z)>RTO(I)(Z)_110L1 | LC1: DMY(I)(Z)>CDN(I)(Z)_110L1 | LD1: DMY(I)(Z)>MAC(I)(Z)_110L1 | LE1: DON(N)(Z)>FIN(N)(Z)_110L1 | LF1: DON(N)(Z)>FIN(N)(Z)_110L2 | LG1: DON(N)(Z)>HAN(N)(Z)_110L1 | LH1: DON(N)(Z)>HAN(N)(Z)_110L2 | LI1: DRM(I)(Z)>CLO(I)(Z)_110L1 | LJ1: DRM(I)(Z)>LET(I)(Z)_110L1 | LK1: DRM(I)(Z)>MEE(I)(Z)_110L1 | LL1: DRO(N)(Z)>ENN(N)(Z)_110L1 | LM1: DRO(N)(Z)>ENN(N)(Z)_110L2 | LN1: DRO(N)(Z)>OMA(N)(Z)_110L1 | LO1: DRO(N)(Z)>OMA(N)(Z)_110L2 | LP1: DRQ(N)(Z)>DRO(N)(Z)_110L1 | LQ1: DRU(I)(Z)>ENN(I)(Z)_110L1 | LR1: DRU(N)(Z)>TAN(N)(Z)_110L1 | LS1: DRU(N)(Z)>TAN(N)(Z)_110L2 | LT1: DRU(N)(Z)>TAN(N)(Z)_110L3 | LU1: DRU(N)(Z)>TMN(N)(Z)_110L1 | LV1: DRU(N)(Z)>TMN(N)(Z)_110L2 | LW1: DRY(I)(Z)>GOR(I)(Z)_110L1 | LX1: DRY(I)(Z)>LOU(I)(Z)_110L1 | LY1: DRY(I)(Z)>PLA(I)(Z)_110L1 | LZ1: DRY(I)(Z)>OBE(I)(Z)_110L1 | MA1: DSN(I)(Z)>KLS(I)(Z)_220L1 | MB1: DSN(I)(Z)>MAY(I)(Z)_220L1 | MC1: DSN(I)(Z)>MAY(I)(Z)_220L2 | MD1: DSN(I)(Z)>MAY(I)(Z)_220L3 | ME1: DSN(I)(Z)>MP(I)(Z)_380L1 | MF1: DSN(I)(Z)>TH(I)(Z)_220L1 | MG1: DTN(I)(Z)>BLC(I)(Z)_110L1 | MH1: DTN(I)(Z)>FIN(I)(Z)_110L1 | MI1: DTN(I)(Z)>KLM(I)(Z)_110L1 | MJ1: DUN(N)(Z)>OMA(N)(Z)_110L1 | MK1: DUN(N)(Z)>TMN(N)(Z)_110L1 | ML1: DUN(N)(Z)>TMN(N)(Z)_110L2 | MM1: DUN(N)(Z)>TMN(N)(Z)_110L3 | MN1: ENN(I)(Z)>SLC(I)(Z)_110L1 | MO1: FIN(I)(Z)>GLA(I)(Z)_110L1 | MP1: FIN(I)(Z)>GRA(I)(Z)_110L1 | MQ1: FIN(I)(Z)>HN(I)(Z)_220L1 | MR1: FIN(I)(Z)>MCD(I)(Z)_110L1 | MS1: FIN(I)(Z)>NW(I)(Z)_220L1 | MT1: FIN(I)(Z)>POP(I)(Z)_110L1 | MU1: FIN(I)(Z)>PTN(I)(Z)_110L1 | MV1: FIN(I)(Z)>SHL(I)(Z)_220L1 | MW1: FIN(I)(Z)>SVN(I)(Z)_110L1 | MX1: FIN(N)(Z)>HAN(N)(Z)_110L1 | MY1: FIN(N)(Z)>HAN(N)(Z)_110L2 | MZ1: FLA(I)(Z)>GIL(I)(Z)_110L1 | NA1: FLA(I)(Z)>LOU(I)(Z)_220L1 | NB1: FLA(I)(Z)>SLB(I)(Z)_110L1 | NC1: FLA(I)(Z)>SLI(I)(Z)_110L1 | ND1: FLA(I)(Z)>SRA(I)(Z)_220L1 | NE1: FLA(I)(Z)>TON(I)(Z)_110L1 | NF1: FRS(I)(Z)>HAR(I)(Z)_110L1 | NG1: FRS(I)(Z)>HEU(I)(Z)_110L1 | NH1: FRS(I)(Z)>INC(I)(Z)_110L1 | NI1: FRS(I)(Z)>TRN(I)(Z)_110L1 | NJ1: GAL(I)(Z)>SAL(I)(Z)_110L1 | NK1: GAL(I)(Z)>SEE(I)(Z)_110L1 | NL1: CDU(I)(Z)>GAN(I)(Z)_110L1 | NM1: GCA(I)(Z)>GRI(I)(T)_110L1 | NN1: GCA(I)(Z)>INC(I)(Z)_110L1 | NO1: GCA(I)(Z)>INC(I)(Z)_110L2 | NP1: GCA(I)(Z)>NAN(I)(Z)_110L1 | NQ1: GCA(I)(Z)>NAN(I)(Z)_110L2 | NR1: GGO(I)(Z)>RAF(I)(Z)_220L1 | NS1: GI(I)(Z)>KKY(I)(Z)_110L1 | NT1: GI(I)(Z)>KLS(I)(Z)_220L1 | NU1: GI(I)(Z)>LWD(I)(Z)_220L1 | NV1: GI(I)(Z)>LWN(I)(Z)_220L1 | NW1: GI(I)(Z)>WAT(I)(Z)_110L1 | NX1: GI(I)(Z)>WAT(I)(Z)_110L2 | NY1: GI(I)(Z)>ROP(I)(Z)_110L1 | NZ1: ROP(I)(Z)>WEX(I)(Z)_110L1 | OA1: GLA(I)(Z)>SVN(I)(Z)_110L1 | OB1: GLE(I)(Z)>KCR(I)(Z)_110L1 | OC1: GLE(N)(Z)>KEL(N)(Z)_110L1 | OD1: GLE(N)(Z)>KEL(N)(Z)_110L2 | OE1: GOL(I)(Z)>GOL(I)(T)_110L1 | OF1: GOR(I)(Z)>LOU(I)(Z)_220L1 | OG1: GOR(I)(Z)>MAY(I)(Z)_220L1 | OH1: GOR(I)(Z)>MTH(I)(Z)_110L1 | OI1: GOR(I)(Z)>NAV(I)(Z)_110L1 | OJ1: GOR(I)(Z)>NAV(I)(Z)_110L2 | OK1: GOR(I)(Z)>NAV(I)(Z)_110L3 | OL1: GOR(I)(Z)>GRH(I)(Z)_110L1 | OM1: GRH(I)(Z)>PLA(I)(Z)_110L1 | ON1: GOR(N)(Z)>OMA(N)(Z)_110L1 | OO1: GOR(N)(Z)>TMN(N)(Z)_110L1 | OP1: GRA(I)(Z)>NBY(I)(Z)_110L1 | OQ1: GRI(I)(T)>MAY(I)(Z)_110L1 | OR1: GRI(I)(Z)>GRI(I)(T)_110L1 | OS1: GRO(I)(Z)>BVK(I)(Z)_110L1 | OT1: HAN(N)(Z)>BYC(N)(Z)_275L1 | OU1: HAN(N)(Z)>LIS(N)(Z)_110L1 | OV1: HAN(N)(Z)>LIS(N)(Z)_110L2 | OW1: HAR(I)(Z)>RE(I)(Z)_110L1 | OX1: HEU(I)(Z)>INC(I)(Z)_110L1 | OY1: HWN(I)(Z)>MGT(I)(Z)_110L1 | OZ1: HWN(I)(Z)>KIN(I)(Z)_110L1 | PA1: HWN(I)(Z)>DFR(I)(T)_110L1 | PB1: IA(I)(Z)>MAC(I)(Z)_110L1 | PC1: IKE(I)(Z)>IKE(I)(T)_110L1 | PD1: INC(I)(Z)>ISH(I)(Z)_220L1 | PE1: INC(I)(Z)>MIL(I)(Z)_110L1 | PF1: INC(I)(Z)>PB(I)(Z)_220L1 | PG1: INC(I)(Z)>PB(I)(Z)_220L2 | PH1: ISH(I)(Z)>SHL(I)(Z)_220L1 | PI1: KBY(I)(Z)>KRA(I)(Z)_110L1 | PJ1: KBY(I)(Z)>KRA(I)(Z)_110L2 | PK1: KBY(I)(Z)>MAL(I)(Z)_110L1 | PL1: KBY(I)(Z)>MR(I)(Z)_110L1 | PM1: KBY(I)(Z)>MR(I)(Z)_110L2 | PN1: KEL(N)(Z)>KPS(N)(Z)_275L1 | PO1: KEL(N)(Z)>KPS(N)(Z)_275L2 | PP1: KEL(N)(Z)>MAG(N)(Z)_275L1 | PQ1: KEL(N)(Z)>RSK(N)(Z)_110L1 | PR1: KER(I)(Z)>OUG(I)(T)_110L1 | PS1: KIN(I)(Z)>DFR(I)(T)_110L1 | PT1: KIN(I)(Z)>MUL(I)(Z)_110L1 | PU1: KLH(I)(Z)>THU(I)(Z)_110L1 | PV1: KLM(I)(Z)>NBY(I)(Z)_110L1 | PW1: KLM(I)(Z)>POP(I)(Z)_110L1 | PX1: KLN(I)(Z)>CUR(I)(Z)_110L1 | PY1: KLN(I)(Z)>KPG(I)(Z)_220L1 | PZ1: KLN(I)(Z)>KRA(I)(Z)_220L1 | QA1: KLN(I)(Z)>LIM(I)(Z)_110L1 | QB1: KLN(I)(Z)>LIM(I)(Z)_110L2 | QC1: KLN(I)(Z)>SH(I)(Z)_220L1 | QD1: KLN(I)(Z)>SNG(I)(Z)_110L1 | QE1: KLP(I)(Z)>CNG(I)(Z)_110L1 | QF1: KLP(I)(Z)>KNR(I)(Z)_110L1 | QG1: KLP(I)(Z)>KNR(I)(Z)_220L1 | QH1: KLP(I)(Z)>KNR(I)(Z)_220L2 | QI1: KLP(I)(Z)>MP(I)(Z)_220L1 | QJ1: KLP(I)(Z)>MP(I)(Z)_220L2 | QK1: KLP(I)(Z)>RAT(I)(Z)_110L1 | QL1: KLP(I)(Z)>TB(I)(Z)_110L1 | QM1: KLP(I)(Z)>TB(I)(Z)_110L2 | QN1: KLP(I)(Z)>TB(I)(Z)_220L1 | QO1: KLP(I)(Z)>TB(I)(Z)_220L2 | QP1: KLP(I)(Z)>TRL(I)(Z)_110L1 | QQ1: KLP(I)(Z)>TRL(I)(Z)_110L2 | QR1: KLS(I)(Z)>KKY(I)(Z)_110L1 | QS1: KMT(N)(Z)>SLK(N)(Z)_110L1 | QT1: KMT(N)(Z)>STR(N)(Z)_110L1 | QU1: KNR(I)(Z)>BYH(I)(Z)_220L1 | QV1: KNR(I)(Z)>TRI(I)(Z)_110L1 | QW1: KNR(I)(Z)>TRI(I)(Z)_110L2 | QX1: KNY(I)(Z)>BUF(I)(Z)_110L1 | QY1: KNY(I)(Z)>KLH(I)(Z)_110L1 | QZ1: KNY(I)(Z)>SAL(I)(Z)_110L1 | RA1: KNY(I)(Z)>SCR(I)(Z)_110L1 | RB1: KNY(I)(Z)>UGL(I)(Z)_110L1 | RC1: KPS(N)(Z)>TAN(N)(Z)_275L1 | RD1: KRA(I)(Z)>BAR(I)(T)_110L1 | RE1: KRA(I)(Z)>LGT(I)(T)_110L1 | RF1: KRA(I)(Z)>MEN(I)(Z)_110L1 | RG1: KRA(I)(Z)>MID(I)(Z)_110L1 | RH1: KRA(I)(Z)>RAF(I)(Z)_220L1 | RI1: KRA(I)(Z)>WHO(I)(Z)_110L1 | RJ1: KTL(I)(Z)>MAY(I)(Z)_110L1 | RK1: KTL(I)(Z)>MON(I)(Z)_110L1 | RL1: KTN(I)(Z)>WAT(I)(Z)_110L1 | RM1: KUD(I)(Z)>CBT(I)(Z)_110L1 | RN1: KUR(I)(Z)>NAV(I)(Z)_110L1 | RO1: KYT(I)(Z)>MAY(I)(Z)_220L1 | RP1: KYT(I)(Z)>WOO(I)(Z)_220L1 | RQ1: LA(I)(Z)>MUL(I)(Z)_110L1 | RR1: LA(I)(Z)>RIC(I)(Z)_110L1 | RS1: LA(I)(Z)>RIC(I)(Z)_110L2 | RT1: LA(I)(Z)>SLB(I)(Z)_110L1 | RU1: LNA(I)(Z)>TIV(I)(Z)_110L1 | RV1: LCK(I)(Z)>MUL(I)(Z)_110L1 | RW1: LET(I)(Z)>GOL(I)(T)_110L1 | RX1: LET(I)(Z)>STR(N)(Z)_110L1 | RY1: LET(I)(Z)>TIV(I)(Z)_110L1 | RZ1: LET(I)(Z)>TLK(I)(Z)_110L1 | SA1: LET(I)(Z)>LNA(I)(Z)_110L1 | SB1: LIB(I)(Z)>MR(I)(Z)_110L1 | SC1: LIB(I)(Z)>MR(I)(Z)_110L2 | SD1: LIM(I)(Z)>MTN(I)(Z)_110L1 | SE1: LIM(I)(Z)>RAT(I)(Z)_110L1 | SF1: LIS(I)(Z)>LOU(I)(Z)_110L1 | SG1: LIS(I)(Z)>LSA(I)(T)_110L1 | SH1: LSA(I)(T)>SKL(I)(Z)_110L1 | SI1: LIS(N)(Z)>TAN(N)(Z)_110L1 | SJ1: LIS(N)(Z)>TAN(N)(Z)_110L2 | SK1: LOU(I)(Z)>MLN(I)(Z)_110L1 | SL1: LOU(I)(Z)>MTH(I)(Z)_110L1 | SM1: LOU(I)(Z)>RRU(I)(Z)_110L1 | SN1: LOU(I)(Z)>TAN(N)(Z)_275L1 | SO1: LOU(I)(Z)>TAN(N)(Z)_275L2 | SP1: LOU(I)(Z)>WOO(I)(Z)_220L1 | SQ1: LSA(I)(Z)>LSA(I)(T)_110L1 | SR1: LSN(I)(Z)>THU(I)(Z)_110L1 | SS1: MAG(N)(Z)>TMN(N)(Z)_275L1 | ST1: MAG(N)(Z)>TMN(N)(Z)_275L2 | SU1: MAY(I)(Z)>BLK(I)(Z)_110L1 | SV1: MAY(I)(Z)>GRI(I)(Z)_110L1 | SW1: MAY(I)(Z)>RNW(I)(Z)_110L1 | SX1: MAY(I)(Z)>RYB(I)(Z)_110L1 | SY1: MAY(I)(Z)>SH(I)(Z)_220L1 | SZ1: MAY(I)(Z)>TH(I)(Z)_220L1 | TA1: MAY(I)(Z)>WOO(I)(Z)_220L1 | TB1: MCD(I)(Z)>NQS(I)(Z)_110L1 | TC1: MCD(I)(Z)>WOL(I)(Z)_110L1 | TD1: MHL(I)(Z)>RE(I)(Z)_110L1 | TE1: MHL(I)(Z)>TRN(I)(Z)_110L1 | TF1: MID(I)(Z)>WHI(I)(Z)_110L1 | TG1: MID(I)(Z)>LGT(I)(Z)_110L1 | TH1: MIL(I)(Z)>RE(I)(Z)_110L1 | TI1: MIL(I)(Z)>RE(I)(Z)_110L2 | TJ1: MKL(N)(Z)>OMA(N)(Z)_110L1 | TK1: MLC(I)(Z)>TSB(I)(Z)_110L1 | TL1: MNH(I)(Z)>MTA(I)(Z)_110L1 | TM1: MOY(I)(Z)>TAW(I)(Z)_110L1 | TN1: MOY(I)(Z)>TAW(I)(Z)_110L2 | TO1: MP(I)(Z)>OST(I)(Z)_380L1 | TP1: MP(I)(Z)>PRO(I)(Z)_220L1 | TQ1: MP(I)(Z)>TBK(I)(T)_110L1 | TR1: MR(I)(Z)>TBG(I)(Z)_110L1 | TS1: MR(I)(Z)>TBG(I)(Z)_110L2 | TT1: MTN(I)(Z)>MUN(I)(Z)_110L1 | TU1: MTN(I)(Z)>MUN(I)(Z)_110L2 | TV1: NEW(I)(Z)>BLK(I)(Z)_110L1 | TW1: NEW(I)(Z)>PLS(I)(Z)_110L1 | TX1: NEW(N)(Z)>TAN(N)(Z)_110L1 | TY1: NEW(N)(Z)>TAN(N)(Z)_110L2 | TZ1: NQS(I)(Z)>RE(I)(Z)_110L1 | UA1: NW(I)(Z)>PB(I)(Z)_220L1 | UB1: OMA(N)(Z)>STR(N)(Z)_110L1 | UC1: OMA(N)(Z)>STR(N)(Z)_110L2 | UD1: OMA(N)(Z)>TRE(N)(Z)_110L1 | UE1: ONH(I)(Z)>MOY(I)(Z)_110L1 | UF1: OST(I)(Z)>TYN(I)(Z)_220L1 | UG1: OST(I)(Z)>WOO(I)(Z)_380L1 | UH1: OUG(I)(Z)>OUG(I)(T)_110L1 | UI1: PA(I)(Z)>STR(I)(T)_110L1 | UJ1: PB(I)(Z)>CKM(I)(Z)_220L1 | UK1: PB(I)(Z)>RE(I)(Z)_110L1 | UL1: PB(I)(Z)>RE(I)(Z)_110L2 | UM1: PB(I)(Z)>SHL(I)(Z)_220L1 | UN1: PLA(I)(Z)>OBE(I)(Z)_220L1 | UO1: PPT(I)(Z)>PLS(I)(Z)_110L1 | UP1: PRO(I)(Z)>TB(I)(Z)_220L1 | UQ1: RAF(I)(Z)>RSY(I)(Z)_110L1 | UR1: RAF(I)(Z)>TBG(I)(Z)_110L1 | US1: RAF(I)(Z)>TBG(I)(Z)_110L2 | UT1: RE(I)(Z)>WBK(I)(Z)_110L1 | UU1: REM(I)(Z)>TRL(I)(Z)_110L1 | UV1: RNW(I)(Z)>DFR(I)(T)_110L1 | UW1: RRU(I)(Z)>SKL(I)(Z)_110L1 | UX1: SBH(I)(Z)>MCE(I)(Z)_110L1 | UY1: SH(I)(Z)>DAL(I)(T)_110L1 | UZ1: SH(I)(Z)>IKE(I)(T)_110L1 | VA1: SH(I)(Z)>SOM(I)(T)_110L1 | VB1: SLI(I)(Z)>SRA(I)(Z)_110L1 | VC1: SLI(I)(Z)>SRA(I)(Z)_110L2 | VD1: SOM(I)(Z)>SOM(I)(T)_110L1 | VE1: SOR(I)(Z)>TLK(I)(Z)_110L1 | VF1: STR(I)(Z)>STR(I)(T)_110L1 | VG1: TAN(N)(Z)>TMN(N)(Z)_275L1 | VH1: TAN(N)(Z)>TMN(N)(Z)_275L2 | VI1: TAN(N)(Z)>WAR(N)(Z)_110L1 | VJ1: TAN(N)(Z)>WAR(N)(Z)_110L2 | VK1: TBK(I)(Z)>TBK(I)(T)_110L1 | VL1: THU(I)(Z)>IKE(I)(T)_110L1 | VM1: TRE(N)(Z)>TMN(N)(Z)_110L1 | VN1: TRL(I)(Z)>OUG(I)(T)_110L1 | VO1: WOO(I)(Z)>PRT(I)(Z)_380L1
A2: t-1 | B2: {=TRANSPOSE(_xlfn._xlws.FILTER(branch!$I$2:$I$591,branch!$D$2:$D$591<>0))} -> 99 | C2: 99 | D2: 178 | E2: 145 | F2: 536 | G2: 393 | H2: 393 | I2: 593 | J2: 434 | K2: 99 | L2: 140 | M2: 103 | N2: 109 | O2: 105 | P2: 99 | Q2: 187 | R2: 187 | S2: 187 | T2: 104 | U2: 112 | V2: 105 | W2: 82 | X2: 82 | Y2: 105 | Z2: 105 | AA2: 99 | AB2: 178 | AC2: 434 | AD2: 434 | AE2: 34 | AF2: 120 | AG2: 120 | AH2: 104 | AI2: 178 | AJ2: 178 | AK2: 178 | AL2: 178 | AM2: 120 | AN2: 178 | AO2: 99 | AP2: 178 | AQ2: 140 | AR2: 140 | AS2: 99 | AT2: 105 | AU2: 99 | AV2: 96 | AW2: 96 | AX2: 178 | AY2: 178 | AZ2: 120 | BA2: 120 | BB2: 178 | BC2: 178 | BD2: 178 | BE2: 105 | BF2: 99 | BG2: 99 | BH2: 99 | BI2: 82 | BJ2: 82 | BK2: 136 | BL2: 140 | BM2: 130 | BN2: 99 | BO2: 122 | BP2: 196 | BQ2: 178 | BR2: 136 | BS2: 178 | BT2: 124 | BU2: 178 | BV2: 178 | BW2: 178 | BX2: 99 | BY2: 136 | BZ2: 195 | CA2: 178 | CB2: 178 | CC2: 192 | CD2: 187 | CE2: 120 | CF2: 187 | CG2: 187 | CH2: 187 | CI2: 119 | CJ2: 119 | CK2: 570 | CL2: 570 | CM2: 140 | CN2: 140 | CO2: 842 | CP2: 105 | CQ2: 109 | CR2: 109 | CS2: 82 | CT2: 82 | CU2: 75 | CV2: 75 | CW2: 178 | CX2: 178 | CY2: 178 | CZ2: 178 | DA2: 82 | DB2: 82 | DC2: 710 | DD2: 69 | DE2: 70 | DF2: 710 | DG2: 710 | DH2: 710 | DI2: 144 | DJ2: 63 | DK2: 99 | DL2: 570 | DM2: 570 | DN2: 178 | DO2: 200 | DP2: 109 | DQ2: 109 | DR2: 79 | DS2: 79 | DT2: 434 | DU2: 740 | DV2: 228 | DW2: 115 | DX2: 195 | DY2: 124 | DZ2: 80 | EA2: 120 | EB2: 105 | EC2: 178 | ED2: 178 | EE2: 178 | EF2: 69 | EG2: 70 | EH2: 69 | EI2: 69 | EJ2: 132 | EK2: 132 | EL2: 710 | EM2: 710 | EN2: 66 | EO2: 66 | EP2: 710 | EQ2: 109 | ER2: 109 | ES2: 82 | ET2: 82 | EU2: 144 | EV2: 144 | EW2: 710 | EX2: 178 | EY2: 124 | EZ2: 99 | FA2: 99 | FB2: 99 | FC2: 761 | FD2: 187 | FE2: 761 | FF2: 761 | FG2: 761 | FH2: 178 | FI2: 178 | FJ2: 115 | FK2: 434 | FL2: 434 | FM2: 555 | FN2: 123 | FO2: 178 | FP2: 130 | FQ2: 178 | FR2: 103 | FS2: 238 | FT2: 434 | FU2: 178 | FV2: 132 | FW2: 178 | FX2: 144 | FY2: 144 | FZ2: 140 | GA2: 140 | GB2: 136 | GC2: 178 | GD2: 178 | GE2: 178 | GF2: 196 | GG2: 178 | GH2: 178 | GI2: 178 | GJ2: 130 | GK2: 99 | GL2: 136 | GM2: 178 | GN2: 105 | GO2: 187 | GP2: 187 | GQ2: 187 | GR2: 105 | GS2: 130 | GT2: 434 | GU2: 105 | GV2: 105 | GW2: 593 | GX2: 119 | GY2: 178 | GZ2: 120 | HA2: 178 | HB2: 178 | HC2: 178 | HD2: 646 | HE2: 161 | HF2: 161 | HG2: 434 | HH2: 434 | HI2: 187 | HJ2: 124 | HK2: 99 | HL2: 105 | HM2: 63 | HN2: 178 | HO2: 187 | HP2: 136 | HQ2: 187 | HR2: 187 | HS2: 99 | HT2: 99 | HU2: 105 | HV2: 178 | HW2: 178 | HX2: 1577 | HY2: 1577 | HZ2: 143 | IA2: 104 | IB2: 82 | IC2: 82 | ID2: 82 | IE2: 82 | IF2: 186 | IG2: 124 | IH2: 136 | II2: 99 | IJ2: 178 | IK2: 178 | IL2: 99 | IM2: 99 | IN2: 105 | IO2: 105 | IP2: 99 | IQ2: 99 | IR2: 100 | IS2: 100 | IT2: 200 | IU2: 143 | IV2: 82 | IW2: 82 | IX2: 82 | IY2: 412 | IZ2: 412 | JA2: 82 | JB2: 82 | JC2: 109 | JD2: 178 | JE2: 99 | JF2: 82 | JG2: 109 | JH2: 140 | JI2: 140 | JJ2: 196 | JK2: 178 | JL2: 178 | JM2: 99 | JN2: 178 | JO2: 350 | JP2: 99 | JQ2: 99 | JR2: 99 | JS2: 392 | JT2: 97 | JU2: 99 | JV2: 761 | JW2: 178 | JX2: 124 | JY2: 103 | JZ2: 178 | KA2: 746 | KB2: 646 | KC2: 178 | KD2: 178 | KE2: 178 | KF2: 178 | KG2: 190 | KH2: 105 | KI2: 136 | KJ2: 134 | KK2: 136 | KL2: 136 | KM2: 99 | KN2: 105 | KO2: 99 | KP2: 105 | KQ2: 99 | KR2: 99 | KS2: 99 | KT2: 74 | KU2: 74 | KV2: 99 | KW2: 178 | KX2: 178 | KY2: 99 | KZ2: 104 | LA2: 178 | LB2: 178 | LC2: 211 | LD2: 196 | LE2: 69 | LF2: 69 | LG2: 144 | LH2: 144 | LI2: 103 | LJ2: 99 | LK2: 99 | LL2: 82 | LM2: 82 | LN2: 82 | LO2: 82 | LP2: 82 | LQ2: 99 | LR2: 79 | LS2: 79 | LT2: 108 | LU2: 109 | LV2: 109 | LW2: 99 | LX2: 99 | LY2: 99 | LZ2: 178 | MA2: 393 | MB2: 350 | MC2: 350 | MD2: 434 | ME2: 1283 | MF2: 351 | MG2: 140 | MH2: 140 | MI2: 140 | MJ2: 186 | MK2: 157 | ML2: 144 | MM2: 186 | MN2: 195 | MO2: 105 | MP2: 119 | MQ2: 593 | MR2: 119 | MS2: 332 | MT2: 120 | MU2: 80 | MV2: 536 | MW2: 105 | MX2: 144 | MY2: 144 | MZ2: 105 | NA2: 384 | NB2: 99 | NC2: 99 | ND2: 434 | NE2: 98 | NF2: 107 | NG2: 140 | NH2: 107 | NI2: 140 | NJ2: 99 | NK2: 99 | NL2: 178 | NM2: 103 | NN2: 103 | NO2: 103 | NP2: 120 | NQ2: 120 | NR2: 570 | NS2: 99 | NT2: 393 | NU2: 434 | NV2: 593 | NW2: 178 | NX2: 178 | NY2: 178 | NZ2: 178 | OA2: 136 | OB2: 122 | OC2: 82 | OD2: 82 | OE2: 105 | OF2: 434 | OG2: 350 | OH2: 99 | OI2: 99 | OJ2: 99 | OK2: 99 | OL2: 99 | OM2: 99 | ON2: 200 | OO2: 200 | OP2: 119 | OQ2: 105 | OR2: 105 | OS2: 195 | OT2: 710 | OU2: 82 | OV2: 80 | OW2: 107 | OX2: 140 | OY2: 136 | OZ2: 136 | PA2: 104 | PB2: 196 | PC2: 80 | PD2: 562 | PE2: 120 | PF2: 267 | PG2: 351 | PH2: 593 | PI2: 178 | PJ2: 99 | PK2: 134 | PL2: 103 | PM2: 103 | PN2: 710 | PO2: 710 | PP2: 710 | PQ2: 185 | PR2: 178 | PS2: 99 | PT2: 178 | PU2: 178 | PV2: 119 | PW2: 120 | PX2: 136 | PY2: 434 | PZ2: 512 | QA2: 99 | QB2: 80 | QC2: 269 | QD2: 178 | QE2: 140 | QF2: 136 | QG2: 731 | QH2: 731 | QI2: 660 | QJ2: 660 | QK2: 136 | QL2: 99 | QM2: 99 | QN2: 350 | QO2: 350 | QP2: 99 | QQ2: 178 | QR2: 99 | QS2: 109 | QT2: 143 | QU2: 434 | QV2: 178 | QW2: 99 | QX2: 140 | QY2: 190 | QZ2: 195 | RA2: 135 | RB2: 195 | RC2: 710 | RD2: 136 | RE2: 105 | RF2: 124 | RG2: 99 | RH2: 353 | RI2: 178 | RJ2: 99 | RK2: 136 | RL2: 99 | RM2: 187 | RN2: 99 | RO2: 761 | RP2: 761 | RQ2: 99 | RR2: 99 | RS2: 99 | RT2: 99 | RU2: 136 | RV2: 124 | RW2: 99 | RX2: 99 | RY2: 136 | RZ2: 105 | SA2: 136 | SB2: 100 | SC2: 99 | SD2: 178 | SE2: 99 | SF2: 99 | SG2: 99 | SH2: 99 | SI2: 82 | SJ2: 80 | SK2: 99 | SL2: 99 | SM2: 95 | SN2: 710 | SO2: 710 | SP2: 350 | SQ2: 120 | SR2: 104 | SS2: 710 | ST2: 710 | SU2: 99 | SV2: 99 | SW2: 80 | SX2: 178 | SY2: 269 | SZ2: 325 | TA2: 350 | TB2: 119 | TC2: 120 | TD2: 140 | TE2: 140 | TF2: 99 | TG2: 105 | TH2: 100 | TI2: 120 | TJ2: 139 | TK2: 135 | TL2: 190 | TM2: 99 | TN2: 99 | TO2: 1283 | TP2: 537 | TQ2: 178 | TR2: 178 | TS2: 178 | TT2: 105 | TU2: 105 | TV2: 136 | TW2: 105 | TX2: 82 | TY2: 82 | TZ2: 119 | UA2: 332 | UB2: 109 | UC2: 82 | UD2: 186 | UE2: 105 | UF2: 434 | UG2: 1577 | UH2: 105 | UI2: 105 | UJ2: 267 | UK2: 269 | UL2: 269 | UM2: 593 | UN2: 178 | UO2: 136 | UP2: 467 | UQ2: 63 | UR2: 195 | US2: 178 | UT2: 125 | UU2: 125 | UV2: 99 | UW2: 95 | UX2: 99 | UY2: 178 | UZ2: 178 | VA2: 105 | VB2: 99 | VC2: 99 | VD2: 105 | VE2: 105 | VF2: 105 | VG2: 710 | VH2: 710 | VI2: 79 | VJ2: 79 | VK2: 105 | VL2: 178 | VM2: 186 | VN2: 178 | VO2: 685

Sheet transformer
A1: name | B1: from_busname | C1: to_busname | D1: type | E1: stat | F1: r | G1: x | H1: b | I1: ShortTermRating | J1: ContinousRating
A2: AD_T2101 | B2: AD_I_Z_220 | C2: AD_I_Z_110 | D2: 1 | E2: 2 | F2: 0.001 | G2: 0.124 | H2: 0 | I2: =J2*1.25 -> 156.25 | J2: 125
A3: ARK_T2101 | B3: ARK_I_Z_220 | C3: ARK_I_Z_110 | D3: 1 | E3: 2 | F3: 0.007 | G3: 0.18 | H3: 0 | I3: =J3*1.25 -> 78.75 | J3: 63
A4: ARK_T2102 | B4: ARK_I_Z_220 | C4: ARK_I_Z_110 | D4: 1 | E4: 2 | F4: 0.0021 | G4: 0.1237 | H4: 0 | I4: =J4*1.25 -> 156.25 | J4: 125
A5: BLC_T2101 | B5: BLC_I_Z_220 | C5: BLC_I_Z_110 | D5: 1 | E5: 2 | F5: 0.001 | G5: 0.0646 | H5: 0 | I5: =J5*1.25 -> 312.5 | J5: 250
A6: BVK_T2101 | B6: BVK_I_Z_220 | C6: BVK_I_Z_110 | D6: 1 | E6: 2 | F6: 0.001 | G6: 0.064 | H6: 0 | I6: =J6*1.25 -> 312.5 | J6: 250
A7: BVK_T2102 | B7: BVK_I_Z_220 | C7: BVK_I_Z_110 | D7: 1 | E7: 2 | F7: 0.001 | G7: 0.064 | H7: 0 | I7: =J7*1.25 -> 312.5 | J7: 250
A8: BYH_T2101 | B8: BYH_I_Z_220 | C8: BYH_I_Z_110 | D8: 1 | E8: 2 | F8: 0.001 | G8: 0.064 | H8: 0 | I8: =J8*1.25 -> 312.5 | J8: 250
A9: BYH_T2102 | B9: BYH_I_Z_220 | C9: BYH_I_Z_110 | D9: 1 | E9: 2 | F9: 0.001 | G9: 0.064 | H9: 0 | I9: =J9*1.25 -> 312.5 | J9: 250
A10: CBT_T2101 | B10: CBT_I_Z_220 | C10: CBT_I_Z_110 | D10: 1 | E10: 2 | F10: 0.001 | G10: 0.0646 | H10: 0 | I10: =J10*1.25 -> 312.5 | J10: 250
A11: CBT_T2102 | B11: CBT_I_Z_220 | C11: CBT_I_Z_110 | D11: 1 | E11: 2 | F11: 0.001 | G11: 0.0646 | H11: 0 | I11: =J11*1.25 -> 312.5 | J11: 250
A12: CBT_T2103 | B12: CBT_I_Z_220 | C12: CBT_I_Z_110 | D12: 1 | E12: 2 | F12: 0.001 | G12: 0.0646 | H12: 0 | I12: =J12*1.25 -> 312.5 | J12: 250
A13: CBT_T2104 | B13: CBT_I_Z_220 | C13: CBT_I_Z_110 | D13: 1 | E13: 2 | F13: 0.001 | G13: 0.0646 | H13: 0 | I13: =J13*1.25 -> 312.5 | J13: 250
... A24: CSH_T2104 | B24: CSH_I_Z_220 | C24: CSH_I_Z_110 | D24: 1 | E24: 2 | F24: 0.0021 | G24: 0.1332 | H24: 0 | I24: =J24*1.25 -> 218.75 | J24: 175
A25: CNB_T4101 | B25: CNB_I_Z_380 | C25: CNB_I_Z_110 | D25: 1 | E25: 2 | F25: 0.00048 | G25: 0.072 | H25: 0 | I25: =J25*1.25 -> 625 | J25: 500
A26: CNB_T4102 | B26: CNB_I_Z_380 | C26: CNB_I_Z_110 | D26: 1 | E26: 2 | F26: 0.00048 | G26: 0.072 | H26: 0 | I26: =J26*1.25 -> 625 | J26: 500
A27: CUL_T2101 | B27: CUL_I_Z_220 | C27: CUL_I_Z_110 | D27: 1 | E27: 2 | F27: 0.0005 | G27: 0.064 | H27: 0 | I27: =J27*1.25 -> 312.5 | J27: 250
A28: DSN_T4201 | B28: DSN_I_Z_380 | C28: DSN_I_Z_220 | D28: 1 | E28: 2 | F28: 0.0002 | G28: 0.0317 | H28: 0 | I28: =J28*1.25 -> 625 | J28: 500
A29: DSN_T4202 | B29: DSN_I_Z_380 | C29: DSN_I_Z_220 | D29: 1 | E29: 2 | F29: 0.0003 | G29: 0.027 | H29: 0 | I29: =J29*1.25 -> 625 | J29: 500
A30: FIN_T2101 | B30: FIN_I_Z_220 | C30: FIN_I_Z_110 | D30: 1 | E30: 2 | F30: 0.0013 | G30: 0.0651 | H30: 0 | I30: =J30*1.25 -> 312.5 | J30: 250
A31: FIN_T2102 | B31: FIN_I_Z_220 | C31: FIN_I_Z_110 | D31: 1 | E31: 2 | F31: 0.0013 | G31: 0.0648 | H31: 0 | I31: =J31*1.25 -> 312.5 | J31: 250
A32: FIN_T2103 | B32: FIN_I_Z_220 | C32: FIN_I_Z_110 | D32: 1 | E32: 2 | F32: 0.001 | G32: 0.064 | H32: 0 | I32: =J32*1.25 -> 312.5 | J32: 250
A33: FIN_T2104 | B33: FIN_I_Z_220 | C33: FIN_I_Z_110 | D33: 1 | E33: 2 | F33: 0.001 | G33: 0.0638 | H33: 0 | I33: =J33*1.25 -> 312.5 | J33: 250
A34: FIN_T2105 | B34: FIN_I_Z_220 | C34: FIN_I_Z_110 | D34: 1 | E34: 2 | F34: 0.001 | G34: 0.064 | H34: 0 | I34: =J34*1.25 -> 312.5 | J34: 250
A35: FLA_T2101 | B35: FLA_I_Z_220 | C35: FLA_I_Z_110 | D35: 1 | E35: 2 | F35: 0.0027 | G35: 0.128 | H35: 0 | I35: =J35*1.25 -> 156.25 | J35: 125
A36: FLA_T2102 | B36: FLA_I_Z_220 | C36: FLA_I_Z_110 | D36: 1 | E36: 2 | F36: 0.0008 | G36: 0.1331 | H36: 0 | I36: =J36*1.25 -> 156.25 | J36: 125
A37: GI_T2101 | B37: GI_I_Z_220 | C37: GI_I_Z_110 | D37: 1 | E37: 2 | F37: 0.0026 | G37: 0.1331 | H37: 0 | I37: =J37*1.25 -> 156.25 | J37: 125
A38: GI_T2102 | B38: GI_I_Z_220 | C38: GI_I_Z_110 | D38: 1 | E38: 2 | F38: 0.0023 | G38: 0.1237 | H38: 0 | I38: =J38*1.25 -> 156.25 | J38: 125
... A86: WOO_WOODLAND | B86: WOO_I_Z_380 | C86: WOO_I_Z_260 | D86: 1 | E86: 2 | F86: 0 | G86: 0.024 | H86: 0 | I86: =J86*1.25 -> 727.5 | J86: 582
A87: AGH_1 | B87: AGH_N_Z_110 | C87: AGH_N_Z_33 | D87: 1 | E87: 2 | F87: 0.00351 | G87: 0.22176 | H87: 0 | I87: =J87*1.25 -> 112.5 | J87: 90
A88: AIR_1 | B88: AIR_N_Z_110 | C88: AIR_N_Z_33 | D88: 1 | E88: 2 | F88: 0.0073 | G88: 0.25 | H88: 0 | I88: =J88*1.25 -> 75 | J88: 60
A89: AIR_2 | B89: AIR_N_Z_110 | C89: AIR_N_Z_33 | D89: 1 | E89: 2 | F89: 0.0073 | G89: 0.25 | H89: 0 | I89: =J89*1.25 -> 75 | J89: 60
A90: ANT_1 | B90: ANT_N_Z_110 | C90: ANT_N_Z_33 | D90: 1 | E90: 2 | F90: 0.00351 | G90: 0.22176 | H90: 0 | I90: =J90*1.25 -> 112.5 | J90: 90
A91: ANT_2 | B91: ANT_N_Z_110 | C91: ANT_N_Z_33 | D91: 1 | E91: 2 | F91: 0.00351 | G91: 0.22257 | H91: 0 | I91: =J91*1.25 -> 112.5 | J91: 90
A92: MKL_1 | B92: MKL_N_Z_110 | C92: MKL_N_Z_33 | D92: 1 | E92: 2 | F92: 0.00351 | G92: 0.22518 | H92: 0 | I92: =J92*1.25 -> 112.5 | J92: 90
A93: MKL_2 | B93: MKL_N_Z_110 | C93: MKL_N_Z_33 | D93: 1 | E93: 2 | F93: 0.00351 | G93: 0.22518 | H93: 0 | I93: =J93*1.25 -> 112.5 | J93: 90
A94: BMA_1 | B94: BMA_N_Z_110 | C94: BMA_N_Z_33 | D94: 1 | E94: 2 | F94: 0.00351 | G94: 0.22023 | H94: 0 | I94: =J94*1.25 -> 112.5 | J94: 90
A95: BMA_2 | B95: BMA_N_Z_110 | C95: BMA_N_Z_33 | D95: 1 | E95: 2 | F95: 0.00351 | G95: 0.22167 | H95: 0 | I95: =J95*1.25 -> 112.5 | J95: 90
A96: BMA_3 | B96: BMA_N_Z_110 | C96: BMA_N_Z_33 | D96: 1 | E96: 2 | F96: 0.00585 | G96: 0.26037 | H96: 0 | I96: =J96*1.25 -> 112.5 | J96: 90
A97: BMA_4 | B97: BMA_N_Z_110 | C97: BMA_N_Z_33 | D97: 1 | E97: 2 | F97: 0.00585 | G97: 0.25803 | H97: 0 | I97: =J97*1.25 -> 112.5 | J97: 90
...

Sheet ts_TLmax
A1: timestep | B1: {=TRANSPOSE(_xlfn._xlws.FILTER(transformer!A2:A181,transformer!$E$2:$E$181<>0))} -> AD_T2101 | C1: ARK_T2101 | D1: ARK_T2102 | E1: BLC_T2101 | F1: BVK_T2101 | G1: BVK_T2102 | H1: BYH_T2101 | I1: BYH_T2102 | J1: CBT_T2101 | K1: CBT_T2102 | L1: CBT_T2103 | M1: CBT_T2104 | N1: CDU_T2101 | O1: CDU_T2102 | P1: CKM_T2101 | Q1: CKM_T2102 | R1: CKM_T2103 | S1: CKM_T2104 | T1: CLA_T2102 | U1: CSH_T2101 | V1: CSH_T2102 | W1: CSH_T2104 | X1: CNB_T4101 | Y1: CNB_T4102 | Z1: CUL_T2101 | AA1: DSN_T4201 | AB1: DSN_T4202 | AC1: FIN_T2101 | AD1: FIN_T2102 | AE1: FIN_T2103 | AF1: FIN_T2104 | AG1: FIN_T2105 | AH1: FLA_T2101 | AI1: FLA_T2102 | AJ1: GI_T2101 | AK1: GI_T2102 | AL1: GOR_T2101 | AM1: INC_T2102 | AN1: INC_T2104 | AO1: INC_T2101 | AP1: INC_T2103 | AQ1: KLN_T2101 | AR1: KLN_T2102 | AS1: KLN_T2103 | AT1: KLN_T2104 | AU1: KLP_T2101 | AV1: KLP_T2102 | AW1: KLS_T2101 | AX1: KLS_T2102 | AY1: KNR_T2101 | AZ1: KNR_T2102 | BA1: BLC_BELCAMP | BB1: CLA_T2101 | BC1: KRA_T2101 | BD1: KRA_T2102 | BE1: LWD_T2101 | BF1: LOU_T2101 | BG1: LOU_T2103 | BH1: LOU_T2102 | BI1: LOU_T2104 | BJ1: LOU_AT1 | BK1: LOU_AT2 | BL1: LOU_AT3 | BM1: MAY_T2101 | BN1: MAY_T2102 | BO1: MAY_T2103 | BP1: MAY_T2104 | BQ1: MP_T4202_01 | BR1: MP_T2101 | BS1: MP_T4202_2 | BT1: OST_T4202 | BU1: PB_T2103 | BV1: PB_T2104 | BW1: RAF_T2101 | BX1: RAF_T2102 | BY1: SH_T2102 | BZ1: SH_T2101 | CA1: SRA_T2102 | CB1: TB_T2101 | CC1: TB_T2102 | CD1: WOO_T4201 | CE1: WOO_T4202 | CF1: WOO_T4204 | CG1: WOO_WOODLAND | CH1: AGH_1 | CI1: AIR_1 | CJ1: AIR_2 | CK1: ANT_1 | CL1: ANT_2 | CM1: MKL_1 | CN1: MKL_2 | CO1: BMA_1 | CP1: BMA_2 | CQ1: BMA_3 | CR1: BMA_4 | CS1: BAN_1 | CT1: BAN_2 | CU1: BAN_3 | CV1: BAN_4 | CW1: BNH_1 | CX1: BNH_2 | CY1: BNM_1 | CZ1: BNM_2 | DA1: BRO | DB1: CAR_1 | DC1: CAR_2 | DD1: CEN_1 | DE1: CEN_2 | DF1: COL (N)_1 | DG1: COL (N)_2 | DH1: CPS_1_110/33 | DI1: CPS_2_110/33 | DJ1: CRG_1 | DK1: CRG_2 | DL1: CRE_1 | DM1: CRE_2 | DN1: DON_1 | DO1: DON_2 | DP1: DON_3 | DQ1: DON_4 | DR1: DRU (N)_1 | DS1: DRU (N)_2 | DT1: CRR | DU1: DUN_1 | DV1: DUN_2 | DW1: EDE_1 | DX1: EDE_2 | DY1: ENN (N)_1 | DZ1: ENN (N)_2 | EA1: ENN (N)_3 | EB1: FIN (N)_1 | EC1: FIN (N)_2 | ED1: GLE (N) | EE1: GOR (N) | EF1: KMT | EG1: KNO_1 | EH1: KNO_2 | EI1: LAR_1 | EJ1: LAR_2 | EK1: LIM (N)_1 | EL1: LIM (N)_2 | EM1: LIS (N)_1 | EN1: LIS (N)_2 | EO1: LMR_1 | EP1: LMR_2 | EQ1: LOG_1 | ER1: LOG_2 | ES1: NAR_1 | ET1: NAR_2 | EU1: NEW (N)_1 | EV1: NEW (N)_2 | EW1: OMA_1 | EX1: OMA_2 | EY1: RSK | EZ1: RAT (N)_1 | FA1: RAT (N)_2 | FB1: ROS_1 | FC1: ROS_2 | FD1: SPR_1 | FE1: SPR_2 | FF1: STR (N)_1 | FG1: STR (N)_2 | FH1: TRE | FI1: TMN | FJ1: WAR_1 | FK1: WAR_2 | FL1: BPS_1 | FM1: BPS_2 | FN1: CAS_1 | FO1: CAS_2 | FP1: CAS_3 | FQ1: CPS_1 | FR1: CPS_2 | FS1: HAN_1 | FT1: HAN_2 | FU1: HAN_3 | FV1: KEL_1 | FW1: KEL_2 | FX1: TAN_1
A2: t-1 | B2: {=TRANSPOSE(_xlfn._xlws.FILTER(transformer!$J$2:$J$181,transformer!$E$2:$E$181<>0))} -> 125 | C2: 63 | D2: 125 | E2: 250 | F2: 250 | G2: 250 | H2: 250 | I2: 250 | J2: 250 | K2: 250 | L2: 250 | M2: 250 | N2: 250 | O2: 250 | P2: 250 | Q2: 250 | R2: 250 | S2: 250 | T2: 250 | U2: 238 | V2: 250 | W2: 175 | X2: 500 | Y2: 500 | Z2: 250 | AA2: 500 | AB2: 500 | AC2: 250 | AD2: 250 | AE2: 250 | AF2: 250 | AG2: 250 | AH2: 125 | AI2: 125 | AJ2: 125 | AK2: 125 | AL2: 250 | AM2: 250 | AN2: 250 | AO2: 250 | AP2: 250 | AQ2: 63 | AR2: 63 | AS2: 250 | AT2: 125 | AU2: 250 | AV2: 250 | AW2: 125 | AX2: 125 | AY2: 250 | AZ2: 250 | BA2: 250 | BB2: 250 | BC2: 250 | BD2: 250 | BE2: 250 | BF2: 125 | BG2: 125 | BH2: 125 | BI2: 250 | BJ2: 300 | BK2: 600 | BL2: 300 | BM2: 125 | BN2: 238 | BO2: 125 | BP2: 250 | BQ2: 500 | BR2: 250 | BS2: 500 | BT2: 500 | BU2: 250 | BV2: 250 | BW2: 238 | BX2: 250 | BY2: 125 | BZ2: 125 | CA2: 250 | CB2: 238 | CC2: 238 | CD2: 500 | CE2: 500 | CF2: 550 | CG2: 582 | CH2: 90 | CI2: 60 | CJ2: 60 | CK2: 90 | CL2: 90 | CM2: 90 | CN2: 90 | CO2: 90 | CP2: 90 | CQ2: 90 | CR2: 90 | CS2: 30 | CT2: 30 | CU2: 30 | CV2: 30 | CW2: 90 | CX2: 90 | CY2: 90 | CZ2: 90 | DA2: 100 | DB2: 90 | DC2: 90 | DD2: 90 | DE2: 90 | DF2: 60 | DG2: 60 | DH2: 90 | DI2: 90 | DJ2: 60 | DK2: 60 | DL2: 75 | DM2: 75 | DN2: 60 | DO2: 60 | DP2: 90 | DQ2: 60 | DR2: 90 | DS2: 90 | DT2: 90 | DU2: 90 | DV2: 90 | DW2: 45 | DX2: 45 | DY2: 45 | DZ2: 45 | EA2: 60 | EB2: 45 | EC2: 45 | ED2: 60 | EE2: 90 | EF2: 90 | EG2: 90 | EH2: 90 | EI2: 45 | EJ2: 45 | EK2: 45 | EL2: 45 | EM2: 90 | EN2: 90 | EO2: 45 | EP2: 45 | EQ2: 45 | ER2: 45 | ES2: 60 | ET2: 60 | EU2: 90 | EV2: 90 | EW2: 90 | EX2: 90 | EY2: 90 | EZ2: 90 | FA2: 90 | FB2: 90 | FC2: 90 | FD2: 90 | FE2: 90 | FF2: 45 | FG2: 45 | FH2: 90 | FI2: 60 | FJ2: 90 | FK2: 90 | FL2: 240 | FM2: 240 | FN2: 240 | FO2: 240 | FP2: 240 | FQ2: 240 | FR2: 240 | FS2: 240 | FT2: 240 | FU2: 240 | FV2: 240 | FW2: 240 | FX2: 240

Sheet generator
A1: busname | B1: name | C1: Market ID | D1: description | E1: export_policy | F1: lifo_group | G1: lifo_position | H1: prorata_groups | I1: MUON_group | J1: stat | K1: PGLB | L1: PGUB | M1: FuelType | N1: synchronous | O1: costc1 | P1: costc0 | Q1: bid | R1: offer
A2: WOO_I_Z_380 | B2: EWIC | C2: EWIC | D2: EWIC | E2: Pro-Rata | H2: ROI/1 | J2: 1 | K2: -504 | L2: 526 | M2: interconnector | N2: No | O2: 70 | P2: 0 | Q2: 10000 | R2: =O2 -> 70
A3: GLE_I_Z_110 | B3: DV1 | C3: GU_401240 | D3: Dromdeeveen Windfarm | E3: Pro-Rata | H3: ROI-W/2,ROI-SW/3a,ROI-SW/3b,ROI-SW/3c,ROI/1,ROI/1 | J3: 1 | K3: 0 | L3: 27 | M3: wind | N3: No | O3: 0 | P3: 0 | Q3: 9000 | R3: =O3 -> 0
A4: LWN_I_Z_220 | B4: GLK | C4: I_ROIGRLK | D4: Greenlink | E4: Pro-Rata | H4: ROI/1 | J4: 0 | K4: -500 | L4: 500 | M4: interconnector | N4: No | O4: 70 | P4: 0 | Q4: 10000 | R4: =O4 -> 70
A5: SLB_I_Z_110 | B5: SB1 | C5: GU_401900 | D5: Sliabh Bawn Windfarm | E5: Pro-Rata | H5: ROI-NW/4,ROI-W/1,ROI-W/2,ROI/1 | J5: 1 | K5: 0 | L5: 58 | M5: wind | N5: No | O5: 0 | P5: 0 | Q5: 9000 | R5: =O5 -> 0
A6: SLC_I_Z_110 | B6: KD1 | C6: GU_403940 | D6: Knockalassa Windfarm | E6: Pro-Rata | H6: ROI-W/1,ROI-W/2,ROI/1 | J6: 1 | K6: 0 | L6: 27 | M6: wind | N6: No | O6: 0 | P6: 0 | Q6: 9000 | R6: =O6 -> 0
A7: SLC_I_Z_110 | B7: RD1 | C7: GU_402270 | D7: Boolinrudda Windfarm | E7: Pro-Rata | H7: ROI-W/1,ROI-W/2,ROI/1 | J7: 1 | K7: 0 | L7: 45 | M7: wind | N7: No | O7: 0 | P7: 0 | Q7: 9000 | R7: =O7 -> 0
A8: SKY_I_Z_110 | B8: OY1 | C8: GU_403760 | D8: Oweninny Wind Farm | E8: Pro-Rata | H8: ROI-NW/4,ROI-W/1,ROI-W/2,ROI-W/6,ROI-W/7,ROI-W/8,ROI/1 | J8: 1 | K8: 0 | L8: 89 | M8: wind | N8: No | O8: 0 | P8: 0 | Q8: 9000 | R8: =O8 -> 0
A9: SKY_I_Z_110 | B9: OY2 | C9: GU_405130 | D9: Oweninny 2 Windfarm | E9: Pro-Rata | H9: ROI-NW/4,ROI-W/1,ROI-W/2,ROI-W/6,ROI-W/7,ROI-W/8,ROI/1 | J9: 1 | K9: 0 | L9: 83 | M9: wind | N9: No | O9: 0 | P9: 0 | Q9: 9000 | R9: =O9 -> 0
A10: TRI_I_Z_110 | B10: KW1 | C10: GU_404200 | D10: Knockawarriga 1 Windfarm | E10: Pro-Rata | H10: ROI-W/2,ROI/1 | J10: 1 | K10: 0 | L10: 22.5 | M10: wind | N10: No | O10: 0 | P10: 0 | Q10: 9000 | R10: =O10 -> 0
A11: TRI_I_Z_110 | B11: TN2 | C11: GU_400600 | D11: Tournafulla Generatot Unit | E11: Pro-Rata | H11: ROI-W/2,ROI/1 | J11: 1 | K11: 0 | L11: 17.2 | M11: wind | N11: No | O11: 0 | P11: 0 | Q11: 9000 | R11: =O11 -> 0
